Workbook

Sheet ap
A1: Wavelength (nm) | B1: E3 | C1: E2 | D1: E1 | E1: E4 | F1: E5 | G1: E24 | H1: E25 | I1: E27 | J1: E31 | K1: E12 | L1: E13 | M1: E14 | N1: E10 | O1: E9 | P1: E7
A2: 800 | B2: 0.0012926528 | C2: 0.0027633328 | D2: 0.00083289857 | E2: 0.011713554 | F2: 0.001850111 | G2: 0.0015318115 | H2: 0.00011334998 | I2: 9.5342121e-05 | J2: 0.00021880886 | K2: 0.00065913966 | L2: 0.00066845384 | M2: 0.0028736723 | N2: 0.0005846514 | O2: 0.0035298973 | P2: 0.0050038583
A3: 799 | B3: 0.0007869255 | C3: 0.0015962479 | D3: 0.0011043723 | E3: 0.0092330957 | F3: 0.00086053085 | G3: 0.00026016655 | H3: 2.8730361e-05 | I3: 0.00026410153 | J3: #NUM! | K3: 0.00063048936 | L3: 0.00022814879 | M3: 0.0021526351 | N3: 0.00068963604 | O3: 0.0032033389 | P3: 0.0035124574
A4: 798 | B4: 0.0010914168 | C4: 0.0014738255 | D4: 0.00030067458 | E4: 0.0089652339 | F4: 0.0023111103 | G4: 0.0005044729 | H4: #NUM! | I4: 0.00010909688 | J4: #NUM! | K4: 3.7935209e-05 | L4: 0.00047912402 | M4: 0.0023604034 | N4: 0.00025427208 | O4: 0.0035704831 | P4: 0.0028435966
A5: 797 | B5: 0.0015237418 | C5: 0.0022824583 | D5: 0.00038178006 | E5: 0.011644355 | F5: 0.00079162483 | G5: 0.0011634305 | H5: #NUM! | I5: #NUM! | J5: #NUM! | K5: #NUM! | L5: 0.00064168036 | M5: 0.0022937557 | N5: 0.00089748527 | O5: 0.0030507615 | P5: 0.0059670444
A6: 796 | B6: 0.0012226619 | C6: 0.0015726285 | D6: 0.00023886329 | E6: 0.012131227 | F6: 0.0019533975 | G6: 0.00027033733 | H6: #NUM! | I6: #NUM! | J6: #NUM! | K6: #NUM! | L6: #NUM! | M6: 0.0024480711 | N6: 1.772258e-06 | O6: 0.0024454894 | P6: 0.0041568834
A7: 795 | B7: 0.00092612788 | C7: 0.0012753653 | D7: 9.4489993e-05 | E7: 0.013217166 | F7: 0.0026349099 | G7: 5.2414684e-05 | H7: #NUM! | I7: #NUM! | J7: #NUM! | K7: #NUM! | L7: 3.8097533e-05 | M7: 0.0020197177 | N7: #NUM! | O7: 0.0026853432 | P7: 0.0030482336
A8: 794 | B8: 0.00022796066 | C8: 0.0012408187 | D8: #NUM! | E8: 0.010538254 | F8: #NUM! | G8: #NUM! | H8: #NUM! | I8: #NUM! | J8: #NUM! | K8: #NUM! | L8: 5.0129864e-05 | M8: 0.0017240083 | N8: #NUM! | O8: 0.0030336578 | P8: 0.00261405
A9: 793 | B9: 0.00013943685 | C9: 0.00013968994 | D9: #NUM! | E9: 0.0072585872 | F9: 4.9461543e-05 | G9: #NUM! | H9: #NUM! | I9: #NUM! | J9: #NUM! | K9: #NUM! | L9: #NUM! | M9: 0.0013516794 | N9: #NUM! | O9: 0.0026038759 | P9: 0.0022363759
A10: 792 | B10: 0.00013211138 | C10: 0.00027662238 | D10: #NUM! | E10: 0.0085169667 | F10: 0.00013305326 | G10: #NUM! | H10: #NUM! | I10: #NUM! | J10: #NUM! | K10: #NUM! | L10: #NUM! | M10: 0.00040005916 | N10: #NUM! | O10: 0.0019544742 | P10: 0.0028079298
A11: 791 | B11: #NUM! | C11: 0.00031653386 | D11: #NUM! | E11: 0.011186765 | F11: #NUM! | G11: #NUM! | H11: #NUM! | I11: #NUM! | J11: #NUM! | K11: #NUM! | L11: #NUM! | M11: 0.0013243648 | N11: #NUM! | O11: 0.0020633321 | P11: 0.0025976989
A12: 790 | B12: #NUM! | C12: #NUM! | D12: #NUM! | E12: 0.0093274291 | F12: #NUM! | G12: #NUM! | H12: #NUM! | I12: #NUM! | J12: #NUM! | K12: #NUM! | L12: #NUM! | M12: 0.00057427612 | N12: #NUM! | O12: 0.0019312188 | P12: 0.0015882634
A13: 789 | B13: 0.0026815944 | C13: 0.0018914192 | D13: 0.0017855682 | E13: 0.013924659 | F13: 0.0031554006 | G13: 0.0018000107 | H13: 0.0016760131 | I13: 0.00052420122 | J13: 0.0014878007 | K13: 0.0019516057 | L13: 0.0012294032 | M13: 0.0029501511 | N13: 0.00078626347 | O13: 0.00423944 | P13: 0.0055852972
A14: 788 | B14: 0.0020409046 | C14: 0.0032171897 | D14: 0.0024033375 | E14: 0.017468929 | F14: 0.0020729829 | G14: 0.0025447913 | H14: 0.0014765561 | I14: 0.0010513169 | J14: 0.0016171604 | K14: 0.0010247518 | L14: 0.0015536585 | M14: 0.0040311714 | N14: 0.0018156627 | O14: 0.0046418807 | P14: 0.0072182772
A15: 787 | B15: 0.0040699869 | C15: 0.0056140093 | D15: 0.0042150754 | E15: 0.019949286 | F15: 0.0066200773 | G15: 0.0043629861 | H15: 0.00078942894 | I15: 0.00091040775 | J15: 0.0024902565 | K15: 0.0031856522 | L15: 0.0042844228 | M15: 0.0056761891 | N15: 0.0035465555 | O15: 0.0066823102 | P15: 0.0086173788
A16: 786 | B16: 0.0039597142 | C16: 0.0056767427 | D16: 0.0033105287 | E16: 0.022208361 | F16: 0.0070163035 | G16: 0.0036321626 | H16: 0.0007226835 | I16: #NUM! | J16: 0.001205368 | K16: 0.00089890163 | L16: 0.0043226853 | M16: 0.0063263798 | N16: 0.0036978542 | O16: 0.0069681001 | P16: 0.0080705666
A17: 785 | B17: 0.0057151947 | C17: 0.0057416935 | D17: 0.0044512382 | E17: 0.023347431 | F17: 0.0089088074 | G17: 0.0022575424 | H17: 0.0008244116 | I17: #NUM! | J17: 0.00021373409 | K17: 0.00054505423 | L17: 0.0045398005 | M17: 0.0050948115 | N17: 0.0035994436 | O17: 0.0061067395 | P17: 0.011030898
A18: 784 | B18: 0.0024061664 | C18: 0.0031181146 | D18: 0.00040815784 | E18: 0.016353327 | F18: 0.0059137944 | G18: 0.00022206448 | H18: #NUM! | I18: #NUM! | J18: #NUM! | K18: #NUM! | L18: 0.0017820449 | M18: 0.0032432704 | N18: 0.00034673865 | O18: 0.005611465 | P18: 0.0055399879
A19: 783 | B19: 0.0029495281 | C19: 0.0055381109 | D19: 0.001250634 | E19: 0.020140905 | F19: 0.0041990191 | G19: 0.00071193051 | H19: 2.4893869e-05 | I19: #NUM! | J19: #NUM! | K19: 8.8856213e-08 | L19: 0.0010126152 | M19: 0.0034502639 | N19: 0.001574086 | O19: 0.0068005712 | P19: 0.0065459041
A20: 782 | B20: 0.0016801091 | C20: 0.0037399696 | D20: 0.00082741028 | E20: 0.020877272 | F20: 0.0031003316 | G20: 0.00097309759 | H20: #NUM! | I20: #NUM! | J20: 0.00041993489 | K20: 0.00013068588 | L20: 0.00097893823 | M20: 0.0051825482 | N20: 0.0009585707 | O20: 0.0064634759 | P20: 0.007211187
A21: 781 | B21: 0.001926024 | C21: 0.002946388 | D21: 0.0010744446 | E21: 0.019804808 | F21: 0.0036631271 | G21: 0.00082334111 | H21: #NUM! | I21: #NUM! | J21: 0.00023289692 | K21: 1.5635225e-05 | L21: 0.00064150181 | M21: 0.0051046682 | N21: 0.00079600089 | O21: 0.0057123239 | P21: 0.0066522485
A22: 780 | B22: 0.0012756958 | C22: 0.0036045629 | D22: 0.00107805 | E22: 0.023332465 | F22: 0.0028421622 | G22: 4.7607177e-05 | H22: #NUM! | I22: #NUM! | J22: #NUM! | K22: 0.00030850967 | L22: 0.0011854392 | M22: 0.0044192519 | N22: 0.0011776621 | O22: 0.0057932912 | P22: 0.0083744351
A23: 779 | B23: 0.0025668508 | C23: 0.0036145101 | D23: 0.00080516093 | E23: 0.026238357 | F23: 0.0050403888 | G23: 0.0011609866 | H23: #NUM! | I23: #NUM! | J23: 0.00065372878 | K23: 0.00032984706 | L23: 0.00097756489 | M23: 0.0050326643 | N23: 0.0006996466 | O23: 0.006274826 | P23: 0.0098685656
A24: 778 | B24: 0.0025974122 | C24: 0.0040159168 | D24: 0.00084522874 | E24: 0.026817338 | F24: 0.0058626663 | G24: 0.0011335611 | H24: 0.00018230877 | I24: #NUM! | J24: #NUM! | K24: 0.0001138928 | L24: 0.0013618694 | M24: 0.0044490255 | N24: 0.0014939851 | O24: 0.0067550092 | P24: 0.0083821934
A25: 777 | B25: 0.0038843612 | C25: 0.0064461083 | D25: 0.0019487372 | E25: 0.028307234 | F25: 0.0067235452 | G25: 0.0011561006 | H25: 0.00066771069 | I25: 0.00072417077 | J25: 0.00036992304 | K25: 0.0011971794 | L25: 0.0014483017 | M25: 0.0062397052 | N25: 0.0022843769 | O25: 0.0075136511 | P25: 0.010226432
A26: 776 | B26: 0.0029327202 | C26: 0.0038995205 | D26: 0.0007477207 | E26: 0.027071049 | F26: 0.0042141986 | G26: 0.0011544724 | H26: 1.8262892e-05 | I26: #NUM! | J26: 0.00028193708 | K26: 0.00010925831 | L26: 0.001160127 | M26: 0.0061618052 | N26: 0.0011754148 | O26: 0.0071165135 | P26: 0.010702874
A27: 775 | B27: 0.0027356378 | C27: 0.0055043367 | D27: 0.0010718415 | E27: 0.027275868 | F27: 0.0046455044 | G27: 0.00064726943 | H27: #NUM! | I27: 1.2967663e-06 | J27: 0.00019466438 | K27: 0.00020034357 | L27: 0.0016456382 | M27: 0.0061066704 | N27: 0.0019098593 | O27: 0.0066945639 | P27: 0.0087241966
A28: 774 | B28: 0.0040906628 | C28: 0.0053297202 | D28: 0.00087804651 | E28: 0.0294046 | F28: 0.0056142397 | G28: 0.0013196643 | H28: 1.9585893e-05 | I28: 8.2009099e-05 | J28: 0.00056096555 | K28: 0.00053540723 | L28: 0.0014843136 | M28: 0.0069312589 | N28: 0.0013277855 | O28: 0.0088076104 | P28: 0.011322388
A29: 773 | B29: 0.002945731 | C29: 0.0041247336 | D29: 0.00037429314 | E29: 0.026567817 | F29: 0.004420534 | G29: 0.00054780022 | H29: #NUM! | I29: #NUM! | J29: #NUM! | K29: 5.201226e-05 | L29: 0.00051106367 | M29: 0.0051280616 | N29: 0.00083085709 | O29: 0.0075286779 | P29: 0.0088339182
A30: 772 | B30: 0.0049364835 | C30: 0.0055514275 | D30: 0.00093030066 | E30: 0.027452964 | F30: 0.0054473502 | G30: 0.00057891836 | H30: #NUM! | I30: #NUM! | J30: 3.5440792e-05 | K30: 0.00024183073 | L30: 0.00060594909 | M30: 0.0051035411 | N30: 0.00078888199 | O30: 0.0084165493 | P30: 0.010287697
A31: 771 | B31: 0.0041061136 | C31: 0.0047344518 | D31: 0.00046336648 | E31: 0.028192804 | F31: 0.0053320667 | G31: 0.00060475157 | H31: #NUM! | I31: #NUM! | J31: 1.3982174e-05 | K31: 0.00025549288 | L31: 0.0011030137 | M31: 0.0062968691 | N31: 0.00056352851 | O31: 0.0072507003 | P31: 0.010145466
A32: 770 | B32: 0.0040316056 | C32: 0.0041500337 | D32: 7.9483098e-05 | E32: 0.026439584 | F32: 0.0047021286 | G32: 0.00079155104 | H32: #NUM! | I32: #NUM! | J32: #NUM! | K32: #NUM! | L32: 0.00036608756 | M32: 0.005597596 | N32: 0.00075943411 | O32: 0.0064878105 | P32: 0.011051043
A33: 769 | B33: 0.0030910329 | C33: 0.0029175793 | D33: 1.3024308e-05 | E33: 0.025928756 | F33: 0.0022213077 | G33: 4.2015889e-05 | H33: #NUM! | I33: #NUM! | J33: #NUM! | K33: #NUM! | L33: 0.00017664124 | M33: 0.0051497843 | N33: 0.00046556858 | O33: 0.0051622725 | P33: 0.0083649563
A34: 768 | B34: 0.0038783119 | C34: 0.0056033972 | D34: 0.00077707078 | E34: 0.033538983 | F34: 0.0051062003 | G34: 0.00089580277 | H34: 0.00047876878 | I34: 0.00057940164 | J34: 0.0007646823 | K34: 0.00052819756 | L34: 0.00074906306 | M34: 0.006498728 | N34: 0.00080257035 | O34: 0.0085330175 | P34: 0.012162241
A35: 767 | B35: 0.0028576218 | C35: 0.0031727025 | D35: 0.00048059124 | E35: 0.029912283 | F35: 0.0024690153 | G35: 0.00079229975 | H35: 6.3144479e-05 | I35: #NUM! | J35: 0.00015893685 | K35: 0.00071048395 | L35: 4.0035512e-05 | M35: 0.0043938826 | N35: 0.00011470689 | O35: 0.0067151977 | P35: 0.0099673912
A36: 766 | B36: 0.0067905146 | C36: 0.008541201 | D36: 0.0046095863 | E36: 0.041306599 | F36: 0.010521073 | G36: 0.0047154882 | H36: 0.0023776031 | I36: 0.0022900523 | J36: 0.0038093217 | K36: 0.0036102388 | L36: 0.0044857833 | M36: 0.0089016103 | N36: 0.0043904255 | O36: 0.01201171 | P36: 0.015165905
A37: 765 | B37: 0.0039892489 | C37: 0.0059839977 | D37: 0.0034275529 | E37: 0.035675179 | F37: 0.0072317213 | G37: 0.0036585919 | H37: 0.00033659822 | I37: 0.0011098619 | J37: 0.0010408124 | K37: 0.0012068257 | L37: 0.0032563738 | M37: 0.0075565286 | N37: 0.0032921477 | O37: 0.0096218703 | P37: 0.012807482
A38: 764 | B38: 0.0071405022 | C38: 0.0087489415 | D38: 0.0051992572 | E38: 0.042751877 | F38: 0.010920125 | G38: 0.0059170526 | H38: #NUM! | I38: 0.0013101958 | J38: 0.0031533961 | K38: 0.0036136333 | L38: 0.0051453675 | M38: 0.0093546324 | N38: 0.0056014233 | O38: 0.012097737 | P38: 0.015083994
A39: 763 | B39: 0.0061042807 | C39: 0.008651332 | D39: 0.0034446008 | E39: 0.042703065 | F39: 0.012891062 | G39: 0.0021613978 | H39: #NUM! | I39: #NUM! | J39: 0.00011744474 | K39: 0.00089447435 | L39: 0.0037375473 | M39: 0.0080296654 | N39: 0.005081668 | O39: 0.010343872 | P39: 0.016034005
A40: 762 | B40: 0.0039556641 | C40: 0.0069277798 | D40: 0.0014024443 | E40: 0.035306486 | F40: 0.0064007858 | G40: 0.00041537588 | H40: #NUM! | I40: #NUM! | J40: #NUM! | K40: #NUM! | L40: 0.0020596638 | M40: 0.0072868478 | N40: 0.0024060162 | O40: 0.010686415 | P40: 0.011970849
...

Sheet ad
A1: Wavelength (nm) | B1: =+ap!B1 -> E3 | C1: =+ap!C1 -> E2 | D1: =+ap!D1 -> E1 | E1: =+ap!E1 -> E4 | F1: =+ap!F1 -> E5 | G1: =+ap!G1 -> E24 | H1: =+ap!H1 -> E25 | I1: =+ap!I1 -> E27 | ... P1: =+ap!P1 -> E7
A2: 800 | B2: 7.5950691e-05 | C2: 0.00066544781 | D2: #NUM! | E2: 0.007646088 | F2: 0.00017222171 | G2: #NUM! | H2: 3.0968926e-07 | I2: 0.00014703131 | J2: #NUM! | K2: #NUM! | L2: #NUM! | M2: 0.0009145754 | N2: 0.00013603146 | O2: 0.0026936003 | P2: 0.0036303863
A3: 799 | B3: 0.00053756033 | C3: 0.0023588583 | D3: 0.00048597145 | E3: 0.0090266752 | F3: 0.0017502888 | G3: #NUM! | H3: 3.0968926e-07 | I3: 0.00014703131 | J3: #NUM! | K3: 4.6778919e-06 | L3: 0.00024763578 | M3: 0.0014565481 | N3: 0.00022992894 | O3: 0.0022392739 | P3: 0.0040764081
A4: 798 | B4: #NUM! | C4: 0.00098788268 | D4: #NUM! | E4: 0.008137252 | F4: 0.0017490753 | G4: #NUM! | H4: 3.0968926e-07 | I4: 0.00014703131 | J4: #NUM! | K4: 3.8796505e-05 | L4: #NUM! | M4: 0.0019036351 | N4: 3.283051e-05 | O4: 0.0018615337 | P4: 0.003617473
A5: 797 | B5: 0.0008740198 | C5: 0.0019045853 | D5: 0.00027516225 | E5: 0.011285275 | F5: 0.0014349415 | G5: 0.00025754123 | H5: 3.0968926e-07 | I5: 0.00013725841 | J5: #NUM! | K5: 0.00071413045 | L5: 0.00054472187 | M5: 0.0029523744 | N5: 0.00093296446 | O5: 0.0033028078 | P5: 0.0050905698
A6: 796 | B6: 2.4480339e-05 | C6: 0.0016822115 | D6: #NUM! | E6: 0.01063849 | F6: 3.3547187e-05 | G6: #NUM! | H6: 3.0968926e-07 | I6: 0.00013725841 | J6: #NUM! | K6: 5.6099358e-06 | L6: #NUM! | M6: 0.00042374211 | N6: 3.1437885e-05 | O6: 0.0026052679 | P6: 0.0038169379
A7: 795 | B7: 0.00033966857 | C7: 0.0023597087 | D7: #NUM! | E7: 0.01032095 | F7: 0.0022475239 | G7: 0.00010780394 | H7: 3.0968926e-07 | I7: 0.00013725841 | J7: #NUM! | K7: 0.00012916308 | L7: 8.0645966e-06 | M7: 0.0016027926 | N7: #NUM! | O7: 0.0024334421 | P7: 0.0040319249
A8: 794 | B8: #NUM! | C8: 0.00094641804 | D8: #NUM! | E8: 0.0094922734 | F8: 4.5082101e-06 | G8: #NUM! | H8: 3.0968926e-07 | I8: 0.00013725841 | J8: #NUM! | K8: #NUM! | L8: #NUM! | M8: 0.00025508856 | N8: #NUM! | O8: 0.0015772749 | P8: 0.0029686226
A9: 793 | B9: #NUM! | C9: 0.00040406495 | D9: 2.3225784e-05 | E9: 0.007051343 | F9: #NUM! | G9: #NUM! | H9: 3.0968926e-07 | I9: 0.00013725841 | J9: #NUM! | K9: #NUM! | L9: 4.2526511e-05 | M9: 0.00059881286 | N9: #NUM! | O9: 0.0018232246 | P9: 0.0018848941
A10: 792 | B10: #NUM! | C10: 0.00086172865 | D10: #NUM! | E10: 0.0075313082 | F10: #NUM! | G10: #NUM! | H10: 3.0968926e-07 | I10: 0.00013725841 | J10: #NUM! | K10: #NUM! | L10: 0.00017588542 | M10: 0.00027186839 | N10: #NUM! | O10: 0.00083381985 | P10: 0.0016314529
A11: 791 | B11: #NUM! | C11: 0.0015544533 | D11: #NUM! | E11: 0.0078038309 | F11: #NUM! | G11: #NUM! | H11: #NUM! | I11: 0.00011965473 | J11: #NUM! | K11: 0.00023893373 | L11: 0.00090122768 | M11: 0.00072556062 | N11: 4.0374269e-05 | O11: 0.0014211228 | P11: 0.0020164322
A12: 790 | B12: 9.6973403e-05 | C12: 0.0013130472 | D12: 0.00033844169 | E12: 0.0090834346 | F12: #NUM! | G12: #NUM! | H12: #NUM! | I12: 0.00011965473 | J12: #NUM! | K12: #NUM! | L12: 0.00080678639 | M12: 0.0008630928 | N12: 0.00020425562 | O12: 0.00085700098 | P12: 0.0017119956
A13: 789 | B13: 0.0034637282 | C13: 0.0037007845 | D13: 0.0014743794 | E13: 0.011948902 | F13: 0.0030420528 | G13: 0.0026695514 | H13: 0.0019473507 | I13: 0.00011965473 | J13: 0.0020137371 | K13: 0.0022960233 | L13: 0.0026798409 | M13: 0.0032399292 | N13: 0.0020498479 | O13: 0.0044834848 | P13: 0.0054170101
A14: 788 | B14: 0.0019188268 | C14: 0.0025981485 | D14: 0.0014892047 | E14: 0.011338789 | F14: 0.0007255065 | G14: 0.00092788949 | H14: 0.0006459164 | I14: 0.00011965473 | J14: 0.00068557958 | K14: 0.0011603787 | L14: 0.001113173 | M14: 0.0014160029 | N14: 0.001646401 | O14: 0.0022559854 | P14: 0.0037214214
A15: 787 | B15: 0.0058758521 | C15: 0.0066460917 | D15: 0.0041325919 | E15: 0.022604047 | F15: 0.010231958 | G15: 0.0046414468 | H15: 0.0010812417 | I15: 0.00011965473 | J15: 0.003735871 | K15: 0.0018976651 | L15: 0.0011289381 | M15: 0.0056076296 | N15: 0.0051181441 | O15: 0.0061744193 | P15: 0.011081192
A16: 786 | B16: 0.0029595309 | C16: 0.0062823804 | D16: 0.003749062 | E16: 0.020650992 | F16: 0.0089992197 | G16: 0.00079213175 | H16: 0.00062059079 | I16: 7.9070547e-05 | J16: 0.0028201236 | K16: 0.0032454609 | L16: 0.00073049793 | M16: 0.0048249363 | N16: 0.0033114831 | O16: 0.0053319542 | P16: 0.0091850122
A17: 785 | B17: 0.0029251004 | C17: 0.0068750361 | D17: 0.0039122772 | E17: 0.019879243 | F17: 0.0096420748 | G17: 0.00072772377 | H17: 0.00070305821 | I17: 1.1621104e-05 | J17: 0.00014052485 | K17: 9.0218474e-05 | L17: 0.00033032241 | M17: 0.0055763055 | N17: 0.0027679947 | O17: 0.0060180273 | P17: 0.0088971073
A18: 784 | B18: 0.0023370861 | C18: 0.0055523723 | D18: 0.0001422096 | E18: 0.01769882 | F18: 0.010286721 | G18: #NUM! | H18: 0.00025627547 | I18: 1.1621104e-05 | J18: 6.0332201e-05 | K18: 0.00016157995 | L18: #NUM! | M18: 0.0055622368 | N18: 0.00026638491 | O18: 0.0059023318 | P18: 0.0088883754
A19: 783 | B19: 0.002791221 | C19: 0.0061360661 | D19: 0.001218636 | E19: 0.017426294 | F19: 0.0029357358 | G19: #NUM! | H19: 1.3171129e-05 | I19: 1.1621104e-05 | J19: #NUM! | K19: 0.0010439993 | L19: #NUM! | M19: 0.0043041005 | N19: 0.00077963175 | O19: 0.0056110985 | P19: 0.0067802812
A20: 782 | B20: 0.0018529168 | C20: 0.0045043958 | D20: 0.00028875645 | E20: 0.016580597 | F20: 0.0023690251 | G20: #NUM! | H20: 1.3171129e-05 | I20: 1.1621104e-05 | J20: #NUM! | K20: 9.4194945e-05 | L20: 0.00060090005 | M20: 0.0035256532 | N20: 0.00065377405 | O20: 0.0054568386 | P20: 0.0050084092
A21: 781 | B21: 0.0023512726 | C21: 0.0053113678 | D21: 0.0010808569 | E21: 0.020014886 | F21: 0.0028221758 | G21: 0.00034211069 | H21: 1.3171129e-05 | I21: 1.1621104e-05 | J21: 0.00026921508 | K21: 0.00036028194 | L21: 0.0011722366 | M21: 0.0029548731 | N21: 0.0010621888 | O21: 0.0054057254 | P21: 0.0099024476
A22: 780 | B22: 0.0030237424 | C22: 0.0051461888 | D22: 0.00062789431 | E22: 0.024553726 | F22: 0.0042472872 | G22: 0.00097115766 | H22: 0.00036540229 | I22: 1.1621104e-05 | J22: 0.00022042304 | K22: 0.00086647019 | L22: 0.0014038548 | M22: 0.0039300398 | N22: 0.0020923895 | O22: 0.0064458968 | P22: 0.010138196
A23: 779 | B23: 0.0015000448 | C23: 0.0054868772 | D23: 0.00090823943 | E23: 0.021974766 | F23: 0.0048413041 | G23: 0.00016384204 | H23: 8.6791553e-05 | I23: 1.1621104e-05 | J23: #NUM! | K23: 0.001424877 | L23: 0.00016107172 | M23: 0.0041188273 | N23: 0.0013550118 | O23: 0.0064127121 | P23: 0.0084653936
A24: 778 | B24: 0.0025631312 | C24: 0.0054746144 | D24: 0.0015103164 | E24: 0.021601317 | F24: 0.0036799937 | G24: 0.00042533747 | H24: 0.00017162183 | I24: 1.1621104e-05 | J24: #NUM! | K24: 0.00055697763 | L24: 0.00094033411 | M24: 0.0043410409 | N24: 0.0010870209 | O24: 0.0064996068 | P24: 0.0094726901
A25: 777 | B25: 0.0017763431 | C25: 0.0063705977 | D25: 0.00097712269 | E25: 0.02292653 | F25: 0.0036505388 | G25: 0.00043632086 | H25: 0.0001306042 | I25: 1.1621104e-05 | J25: 0.00010302442 | K25: 0.0001919164 | L25: 0.001597732 | M25: 0.0045221125 | N25: 0.001582257 | O25: 0.0065995694 | P25: 0.01064826
A26: 776 | B26: 0.0020031616 | C26: 0.0071283831 | D26: 0.0014793169 | E26: 0.024807658 | F26: 0.0064590815 | G26: 0.0007951288 | H26: 0.0004324369 | I26: 1.1621104e-05 | J26: 0.00065901571 | K26: 0.00052989808 | L26: 0.0011170089 | M26: 0.0046790659 | N26: 0.0010384767 | O26: 0.0075460798 | P26: 0.011238591
A27: 775 | B27: 0.0022372899 | C27: 0.0049278588 | D27: 0.00094332112 | E27: 0.022449899 | F27: 0.0035690926 | G27: 0.00017305053 | H27: 0.0004324369 | I27: 1.1621104e-05 | J27: #NUM! | K27: 0.00025139474 | L27: 0.00065429911 | M27: 0.004181016 | N27: 0.0012087068 | O27: 0.0071622107 | P27: 0.0085150989
A28: 774 | B28: 0.0016037297 | C28: 0.0052697964 | D28: 0.00056871197 | E28: 0.022735754 | F28: 0.0057546681 | G28: 0.00067827174 | H28: 0.0004324369 | I28: 1.1621104e-05 | J28: 0.00016534436 | K28: 0.00061785178 | L28: 0.00054334191 | M28: 0.0045078522 | N28: 0.0013613361 | O28: 0.0074110137 | P28: 0.011210564
A29: 773 | B29: 0.0023942043 | C29: 0.0061975799 | D29: 0.00045455658 | E29: 0.027425819 | F29: 0.0038012106 | G29: 0.00045697491 | H29: 0.0004324369 | I29: 1.1621104e-05 | J29: #NUM! | K29: 0.00065301363 | L29: 0.0007753265 | M29: 0.0050843669 | N29: 0.001753118 | O29: 0.0073014578 | P29: 0.010491361
A30: 772 | B30: 0.0020674314 | C30: 0.0048415087 | D30: 0.0010343595 | E30: 0.02106957 | F30: 0.0038741585 | G30: 3.615631e-06 | H30: 0.0004324369 | I30: 1.1621104e-05 | J30: #NUM! | K30: 0.00034038523 | L30: 0.00034352637 | M30: 0.0046857012 | N30: 0.00080492052 | O30: 0.0075111143 | P30: 0.0094917328
A31: 771 | B31: 0.0004291945 | C31: 0.0040783088 | D31: 8.5992858e-05 | E31: 0.02197969 | F31: 0.0024583414 | G31: 0.00013461184 | H31: 0.0004324369 | I31: 1.1621104e-05 | J31: #NUM! | K31: #NUM! | L31: 6.753839e-05 | M31: 0.0032083419 | N31: 0.00024012095 | O31: 0.006457461 | P31: 0.0091788562
A32: 770 | B32: 0.00038195122 | C32: 0.0039919946 | D32: #NUM! | E32: 0.019578393 | F32: 0.0023078842 | G32: #NUM! | H32: 0.0004324369 | I32: 1.1621104e-05 | J32: #NUM! | K32: #NUM! | L32: 0.00012204922 | M32: 0.003302794 | N32: 2.4682312e-05 | O32: 0.0056188657 | P32: 0.0083050446
A33: 769 | B33: 0.0025046234 | C33: 0.0061399073 | D33: 0.00059444646 | E33: 0.025868414 | F33: 0.0029865194 | G33: 0.00049602011 | H33: 0.00039667816 | I33: 1.1621104e-05 | J33: 9.3888656e-05 | K33: 0.0017642197 | L33: 0.0028885206 | M33: 0.0049930741 | N33: 0.0013146924 | O33: 0.0073844303 | P33: 0.010069498
A34: 768 | B34: 0.0015378074 | C34: 0.0050992051 | D34: 0.00084541873 | E34: 0.023695954 | F34: 0.00310697 | G34: 0.00031293546 | H34: 0.00020150237 | I34: 1.1621104e-05 | J34: 2.0738148e-05 | K34: 0.0013577019 | L34: 0.0017830275 | M34: 0.0043783244 | N34: 0.0012439554 | O34: 0.0071546262 | P34: 0.010302947
A35: 767 | B35: 0.0040763508 | C35: 0.0085272274 | D35: 0.0025584717 | E35: 0.032065076 | F35: 0.0059082513 | G35: 0.0022058617 | H35: 0.0014386166 | I35: 1.1621104e-05 | J35: 0.0015568344 | K35: 0.0024859294 | L35: 0.0020293214 | M35: 0.0056234515 | N35: 0.0033998825 | O35: 0.007802344 | P35: 0.013404404
A36: 766 | B36: 0.0066955442 | C36: 0.0097710805 | D36: 0.005065854 | E36: 0.036208005 | F36: 0.0090825945 | G36: 0.0040911011 | H36: 0.0034298572 | I36: 1.1621104e-05 | J36: 0.0031236193 | K36: 0.0042325042 | L36: 0.0040978331 | M36: 0.008111229 | N36: 0.0061350526 | O36: 0.010537854 | P36: 0.01449189
A37: 765 | B37: 0.0069095353 | C37: 0.0091782516 | D37: 0.0033677714 | E37: 0.03423277 | F37: 0.011692589 | G37: 0.0041596606 | H37: 0.00083667279 | I37: 1.1621104e-05 | J37: 0.0020524217 | K37: 0.0015229477 | L37: 0.002432911 | M37: 0.0068376879 | N37: 0.0052218162 | O37: 0.01080536 | P37: 0.015282721
A38: 764 | B38: 0.00602166 | C38: 0.010790436 | D38: 0.0049270639 | E38: 0.034025989 | F38: 0.012071231 | G38: 0.00044885346 | H38: 0.0012726037 | I38: 1.1621104e-05 | J38: 0.0028287839 | K38: 0.00062460038 | L38: 0.0012123907 | M38: 0.0077661746 | N38: 0.0033448294 | O38: 0.011745213 | P38: 0.014839737
A39: 763 | B39: 0.0065198034 | C39: 0.010228374 | D39: 0.0024241371 | E39: 0.036504835 | F39: 0.013544459 | G39: 0.00038027503 | H39: 0.00020247453 | I39: 1.1621104e-05 | J39: 0.00010482526 | K39: 0.00054072923 | L39: 0.001154915 | M39: 0.0084973055 | N39: 0.001773206 | O39: 0.01115015 | P39: 0.01502462
A40: 762 | B40: 0.0056434542 | C40: 0.010683095 | D40: 0.0035238868 | E40: 0.035195132 | F40: 0.014402971 | G40: 0.00038891026 | H40: 5.3082582e-05 | I40: 1.1621104e-05 | J40: 7.07491e-05 | K40: 0.0026314626 | L40: 0.0011267123 | M40: 0.0088402156 | N40: 0.0029969055 | O40: 0.011426331 | P40: 0.014877848
...

Sheet aphy
A1: Wavelength (nm) | B1: =+ap!B1 -> E3 | C1: =+ap!C1 -> E2 | D1: =+ap!D1 -> E1 | E1: =+ap!E1 -> E4 | F1: =+ap!F1 -> E5 | G1: =+ap!G1 -> E24 | H1: =+ap!H1 -> E25 | I1: =+ap!I1 -> E27 | ... P1: =+ap!P1 -> E7 | AI1: B/R | AK1: Si la razón B/R es >3.0 domina el picofitoplancton (< 2 um) | AQ1: =+B1 -> E3 | AR1: =+C1 -> E2 | AS1: =+D1 -> E1 | AT1: =+E1 -> E4 | AU1: =+F1 -> E5 | AV1: =+G1 -> E24 | AW1: =+H1 -> E25 | AX1: =+I1 -> E27 | ... BS1: =+AD1 -> 0
A2: 800 | B2: 0.0012167022 | C2: 0.002097885 | D2: #NUM! | E2: 0.0040674662 | F2: 0.0016778893 | G2: #NUM! | H2: 0.00011304029 | I2: -5.1689191e-05 | J2: #NUM! | K2: #NUM! | L2: #NUM! | M2: 0.0019590969 | N2: 0.00044861994 | O2: 0.00083629705 | P2: 0.001373472 | AI2: B= | AJ2: afito(443) | AK2: Si la razón B/R es <2.5 domina el microfitoplancton (> 20 um) | AP2: B/R = | AQ2: =B$359/B$127 -> 2.8995607 | AR2: =C$359/C$127 -> 1.5295478 | AS2: =D$359/D$127 -> 2.1429958 | AT2: =E$359/E$127 -> 5.8250135 | AU2: =F$359/F$127 -> 4.0034657 | AV2: =G$359/G$127 -> 2.7721744 | AW2: =H$359/H$127 -> 3.4291095 | AX2: =I$359/I$127 -> 5.0501527 | ... BS2: =AD$359/AD$127 -> #DIV/0!
A3: 799 | B3: 0.00024936518 | C3: -0.00076261042 | D3: 0.00061840088 | E3: 0.00020642049 | F3: -0.00088975792 | G3: #NUM! | H3: 2.8420672e-05 | I3: 0.00011707022 | J3: #NUM! | K3: 0.00062581147 | L3: -1.9486988e-05 | M3: 0.00069608697 | N3: 0.00045970709 | O3: 0.00096406508 | P3: -0.0005639507 | AI3: R= | AJ3: afito(675) | AK3: Valores entre 2.5 y 3 domina el nanoplancton | AP3: [ ] Clorofila a =
A4: 798 | B4: #NUM! | C4: 0.00048594279 | D4: #NUM! | E4: 0.0008279819 | F4: 0.00056203497 | G4: #NUM! | H4: #NUM! | I4: -3.7934433e-05 | J4: #NUM! | K4: -8.6129612e-07 | L4: #NUM! | M4: 0.00045676827 | N4: 0.00022144157 | O4: 0.0017089493 | P4: -0.00077387641
A5: 797 | B5: 0.000649722 | C5: 0.00037787307 | D5: 0.00010661782 | E5: 0.00035907967 | F5: -0.00064331667 | G5: 0.00090588924 | H5: #NUM! | I5: #NUM! | J5: #NUM! | K5: #NUM! | L5: 9.6958494e-05 | M5: -0.00065861872 | N5: -3.5479197e-05 | O5: -0.00025204635 | P5: 0.00087647462
A6: 796 | B6: 0.0011981816 | C6: -0.00010958298 | D6: #NUM! | E6: 0.0014927369 | F6: 0.0019198503 | G6: #NUM! | H6: #NUM! | I6: #NUM! | J6: #NUM! | K6: #NUM! | L6: #NUM! | M6: 0.002024329 | N6: -2.9665627e-05 | O6: -0.00015977849 | P6: 0.00033994547
A7: 795 | B7: 0.00058645931 | C7: -0.0010843435 | D7: #NUM! | E7: 0.0028962158 | F7: 0.00038738594 | G7: -5.5389255e-05 | H7: #NUM! | I7: #NUM! | J7: #NUM! | K7: #NUM! | L7: 3.0032936e-05 | M7: 0.00041692509 | N7: #NUM! | O7: 0.00025190111 | P7: -0.00098369125
A8: 794 | B8: #NUM! | C8: 0.00029440069 | D8: #NUM! | E8: 0.001045981 | F8: #NUM! | G8: #NUM! | H8: #NUM! | I8: #NUM! | J8: #NUM! | K8: #NUM! | L8: #NUM! | M8: 0.0014689197 | N8: #NUM! | O8: 0.0014563829 | P8: -0.00035457258
A9: 793 | B9: #NUM! | C9: -0.00026437502 | D9: #NUM! | E9: 0.00020724418 | F9: #NUM! | G9: #NUM! | H9: #NUM! | I9: #NUM! | J9: #NUM! | K9: #NUM! | L9: #NUM! | M9: 0.00075286658 | N9: #NUM! | O9: 0.00078065123 | P9: 0.00035148174
A10: 792 | B10: #NUM! | C10: -0.00058510627 | D10: #NUM! | E10: 0.00098565852 | F10: #NUM! | G10: #NUM! | H10: #NUM! | I10: #NUM! | J10: #NUM! | K10: #NUM! | L10: #NUM! | M10: 0.00012819077 | N10: #NUM! | O10: 0.0011206543 | P10: 0.0011764769
A11: 791 | B11: #NUM! | C11: -0.0012379195 | D11: #NUM! | E11: 0.0033829346 | F11: #NUM! | G11: #NUM! | H11: #NUM! | I11: #NUM! | J11: #NUM! | K11: #NUM! | L11: #NUM! | M11: 0.00059880419 | N11: #NUM! | O11: 0.00064220921 | P11: 0.00058126669
A12: 790 | B12: #NUM! | C12: #NUM! | D12: #NUM! | E12: 0.00024399448 | F12: #NUM! | G12: #NUM! | H12: #NUM! | I12: #NUM! | J12: #NUM! | K12: #NUM! | L12: #NUM! | M12: -0.00028881668 | N12: #NUM! | O12: 0.0010742179 | P12: -0.00012373224
A13: 789 | B13: -0.00078213382 | C13: -0.0018093653 | D13: 0.00031118886 | E13: 0.0019757571 | F13: 0.00011334774 | G13: -0.00086954072 | H13: -0.00027133762 | I13: 0.00040454648 | J13: -0.00052593632 | K13: -0.0003444176 | L13: -0.0014504377 | M13: -0.00028977812 | N13: -0.0012635844 | O13: -0.00024404478 | P13: 0.0001682871
A14: 788 | B14: 0.00012207778 | C14: 0.00061904122 | D14: 0.00091413281 | E14: 0.0061301406 | F14: 0.0013474764 | G14: 0.0016169018 | H14: 0.00083063973 | I14: 0.00093166213 | J14: 0.00093158086 | K14: -0.00013562688 | L14: 0.00044048549 | M14: 0.0026151686 | N14: 0.00016926169 | O14: 0.0023858953 | P14: 0.0034968558
A15: 787 | B15: -0.0018058653 | C15: -0.0010320825 | D15: 8.248354e-05 | E15: -0.0026547615 | F15: -0.0036118806 | G15: -0.00027846069 | H15: -0.00029181271 | I15: 0.00079075302 | J15: -0.0012456145 | K15: 0.0012879871 | L15: 0.0031554846 | M15: 6.8559489e-05 | N15: -0.0015715885 | O15: 0.00050789089 | P15: -0.0024638133
A16: 786 | B16: 0.0010001833 | C16: -0.00060563771 | D16: -0.00043853335 | E16: 0.0015573692 | F16: -0.0019829162 | G16: 0.0028400309 | H16: 0.00010209272 | I16: #NUM! | J16: -0.0016147556 | K16: -0.0023465593 | L16: 0.0035921874 | M16: 0.0015014435 | N16: 0.00038637109 | O16: 0.0016361459 | P16: -0.0011144456
A17: 785 | B17: 0.0027900943 | C17: -0.0011333426 | D17: 0.00053896101 | E17: 0.003468188 | F17: -0.00073326741 | G17: 0.0015298186 | H17: 0.00012135339 | I17: #NUM! | J17: 7.3209249e-05 | K17: 0.00045483575 | L17: 0.0042094781 | M17: -0.00048149398 | N17: 0.00083144887 | O17: 8.8712191e-05 | P17: 0.0021337902
A18: 784 | B18: 6.9080347e-05 | C18: -0.0024342577 | D18: 0.00026594823 | E18: -0.0013454932 | F18: -0.0043729263 | G18: #NUM! | H18: #NUM! | I18: #NUM! | J18: #NUM! | K18: #NUM! | L18: #NUM! | M18: -0.0023189664 | N18: 8.0353741e-05 | O18: -0.00029086687 | P18: -0.0033483875
A19: 783 | B19: 0.00015830711 | C19: -0.00059795516 | D19: 3.1997997e-05 | E19: 0.0027146108 | F19: 0.0012632833 | G19: #NUM! | H19: 1.1722739e-05 | I19: #NUM! | J19: #NUM! | K19: -0.0010439105 | L19: #NUM! | M19: -0.00085383662 | N19: 0.00079445425 | O19: 0.0011894727 | P19: -0.0002343771
A20: 782 | B20: -0.00017280767 | C20: -0.00076442622 | D20: 0.00053865384 | E20: 0.0042966754 | F20: 0.00073130658 | G20: #NUM! | H20: #NUM! | I20: #NUM! | J20: #NUM! | K20: 3.6490936e-05 | L20: 0.00037803818 | M20: 0.001656895 | N20: 0.00030479665 | O20: 0.0010066373 | P20: 0.0022027777
A21: 781 | B21: -0.00042524858 | C21: -0.0023649798 | D21: -6.4122921e-06 | E21: -0.00021007778 | F21: 0.00084095127 | G21: 0.00048123042 | H21: #NUM! | I21: #NUM! | J21: -3.6318157e-05 | K21: -0.00034464671 | L21: -0.00053073475 | M21: 0.0021497951 | N21: -0.00026618787 | O21: 0.00030659853 | P21: -0.0032501991
A22: 780 | B22: -0.0017480467 | C22: -0.0015416259 | D22: 0.00045015572 | E22: -0.0012212605 | F22: -0.001405125 | G22: -0.00092355048 | H22: #NUM! | I22: #NUM! | J22: #NUM! | K22: -0.00055796052 | L22: -0.00021841565 | M22: 0.00048921208 | N22: -0.00091472733 | O22: -0.00065260561 | P22: -0.0017637611
A23: 779 | B23: 0.001066806 | C23: -0.0018723671 | D23: -0.0001030785 | E23: 0.0042635909 | F23: 0.00019908467 | G23: 0.00099714459 | H23: #NUM! | I23: #NUM! | J23: #NUM! | K23: -0.00109503 | L23: 0.00081649317 | M23: 0.00091383695 | N23: -0.00065536519 | O23: -0.00013788607 | P23: 0.001403172
A24: 778 | B24: 3.4280928e-05 | C24: -0.0014586976 | D24: -0.00066508769 | E24: 0.0052160214 | F24: 0.0021826726 | G24: 0.0007082236 | H24: 1.0686939e-05 | I24: #NUM! | J24: #NUM! | K24: -0.00044308483 | L24: 0.00042153529 | M24: 0.00010798461 | N24: 0.0004069642 | O24: 0.00025540242 | P24: -0.0010904967
A25: 777 | B25: 0.0021080181 | C25: 7.5510681e-05 | D25: 0.00097161454 | E25: 0.0053807039 | F25: 0.0030730064 | G25: 0.00071977975 | H25: 0.00053710649 | I25: 0.00071254966 | J25: 0.00026689861 | K25: 0.001005263 | L25: -0.0001494303 | M25: 0.0017175928 | N25: 0.00070211985 | O25: 0.00091408175 | P25: -0.00042182834
A26: 776 | B26: 0.00092955864 | C26: -0.0032288626 | D26: -0.00073159624 | E26: 0.002263391 | F26: -0.0022448829 | G26: 0.00035934357 | H26: -0.00041417401 | I26: #NUM! | J26: -0.00037707862 | K26: -0.00042063977 | L26: 4.3118048e-05 | M26: 0.0014827394 | N26: 0.00013693807 | O26: -0.00042956632 | P26: -0.00053571662
A27: 775 | B27: 0.00049834793 | C27: 0.00057647794 | D27: 0.0001285204 | E27: 0.0048259687 | F27: 0.0010764118 | G27: 0.0004742189 | H27: #NUM! | I27: -1.0324337e-05 | J27: #NUM! | K27: -5.105116e-05 | L27: 0.0009913391 | M27: 0.0019256543 | N27: 0.00070115253 | O27: -0.0004676468 | P27: 0.00020909763
A28: 774 | B28: 0.0024869331 | C28: 5.992374e-05 | D28: 0.00030933454 | E28: 0.0066688456 | F28: -0.0001404284 | G28: 0.00064139256 | H28: -0.00041285101 | I28: 7.0387995e-05 | J28: 0.00039562119 | K28: -8.2444551e-05 | L28: 0.00094097166 | M28: 0.0024234067 | N28: -3.3550654e-05 | O28: 0.0013965967 | P28: 0.00011182421
A29: 773 | B29: 0.00055152676 | C29: -0.0020728463 | D29: -8.0263443e-05 | E29: -0.00085800173 | F29: 0.00061932337 | G29: 9.0825312e-05 | H29: #NUM! | I29: #NUM! | J29: #NUM! | K29: -0.00060100137 | L29: -0.00026426283 | M29: 4.3694712e-05 | N29: -0.00092226091 | O29: 0.00022722007 | P29: -0.0016574431
A30: 772 | B30: 0.0028690521 | C30: 0.0007099188 | D30: -0.00010405885 | E30: 0.0063833936 | F30: 0.0015731916 | G30: 0.00057530273 | H30: #NUM! | I30: #NUM! | J30: #NUM! | K30: -9.8554501e-05 | L30: 0.00026242272 | M30: 0.00041783987 | N30: -1.6038536e-05 | O30: 0.00090543495 | P30: 0.00079596438
A31: 771 | B31: 0.0036769191 | C31: 0.00065614302 | D31: 0.00037737362 | E31: 0.0062131145 | F31: 0.0028737253 | G31: 0.00047013973 | H31: #NUM! | I31: #NUM! | J31: #NUM! | K31: #NUM! | L31: 0.0010354753 | M31: 0.0030885272 | N31: 0.00032340756 | O31: 0.00079323933 | P31: 0.00096660944
A32: 770 | B32: 0.0036496543 | C32: 0.00015803916 | D32: #NUM! | E32: 0.0068611909 | F32: 0.0023942444 | G32: #NUM! | H32: #NUM! | I32: #NUM! | J32: #NUM! | K32: #NUM! | L32: 0.00024403834 | M32: 0.002294802 | N32: 0.0007347518 | O32: 0.00086894475 | P32: 0.002745998
A33: 769 | B33: 0.00058640956 | C33: -0.0032223279 | D33: -0.00058142215 | E33: 6.034203e-05 | F33: -0.00076521167 | G33: -0.00045400422 | H33: #NUM! | I33: #NUM! | J33: #NUM! | K33: #NUM! | L33: -0.0027118794 | M33: 0.0001567102 | N33: -0.00084912386 | O33: -0.0022221578 | P33: -0.0017045415
A34: 768 | B34: 0.0023405045 | C34: 0.00050419213 | D34: -6.8347948e-05 | E34: 0.0098430294 | F34: 0.0019992304 | G34: 0.00058286732 | H34: 0.00027726641 | I34: 0.00056778054 | J34: 0.00074394415 | K34: -0.00082950434 | L34: -0.0010339644 | M34: 0.0021204036 | N34: -0.00044138503 | O34: 0.0013783913 | P34: 0.0018592944
A35: 767 | B35: -0.0012187291 | C35: -0.0053545249 | D35: -0.0020778805 | E35: -0.0021527927 | F35: -0.003439236 | G35: -0.001413562 | H35: -0.0013754721 | I35: #NUM! | J35: -0.0013978975 | K35: -0.0017754455 | L35: -0.0019892859 | M35: -0.0012295689 | N35: -0.0032851756 | O35: -0.0010871463 | P35: -0.0034370131
A36: 766 | B36: 9.4970428e-05 | C36: -0.0012298795 | D36: -0.00045626769 | E36: 0.0050985939 | F36: 0.0014384785 | G36: 0.00062438714 | H36: -0.0010522541 | I36: 0.0022784312 | J36: 0.00068570237 | K36: -0.00062226541 | L36: 0.00038795016 | M36: 0.00079038134 | N36: -0.0017446271 | O36: 0.0014738557 | P36: 0.00067401578
A37: 765 | B37: -0.0029202864 | C37: -0.003194254 | D37: 5.9781503e-05 | E37: 0.0014424086 | F37: -0.0044608673 | G37: -0.00050106866 | H37: -0.00050007457 | I37: 0.0010982408 | J37: -0.0010116094 | K37: -0.00031612197 | L37: 0.00082346276 | M37: 0.00071884071 | N37: -0.0019296685 | O37: -0.0011834897 | P37: -0.0024752387
A38: 764 | B38: 0.0011188422 | C38: -0.0020414941 | D38: 0.00027219334 | E38: 0.0087258873 | F38: -0.0011511056 | G38: 0.0054681991 | H38: #NUM! | I38: 0.0012985747 | J38: 0.00032461211 | K38: 0.0029890329 | L38: 0.0039329768 | M38: 0.0015884578 | N38: 0.0022565939 | O38: 0.00035252329 | P38: 0.00024425676
A39: 763 | B39: -0.00041552269 | C39: -0.0015770422 | D39: 0.0010204637 | E39: 0.0061982302 | F39: -0.00065339694 | G39: 0.0017811228 | H39: #NUM! | I39: #NUM! | J39: 1.2619484e-05 | K39: 0.00035374512 | L39: 0.0025826322 | M39: -0.00046764011 | N39: 0.003308462 | O39: -0.0008062781 | P39: 0.0010093848
A40: 762 | B40: -0.0016877901 | C40: -0.0037553155 | D40: -0.0021214425 | E40: 0.00011135476 | F40: -0.0080021856 | G40: 2.6465626e-05 | H40: #NUM! | I40: #NUM! | J40: #NUM! | K40: #NUM! | L40: 0.00093295151 | M40: -0.0015533678 | N40: -0.00059088933 | O40: -0.00073991608 | P40: -0.0029069983
...

Sheet aCDOM
A1: Wavelength (nm) | B1: E3 | C1: E2 | D1: E1 | E1: E4 | F1: E5 | G1: E24 | H1: E25 | I1: E27 | J1: E31 | K1: E12 | L1: E13 | M1: E14 | N1: E10 | O1: E9 | P1: E7 | AH1: ESPECTROS MODELADOS | AI1: =+A1 -> Wavelength (nm) | AJ1: SC-23-0513 | AK1: SC-23-0516 | AL1: SC-23-0519 | AM1: SC-23-0522 | AN1: SC-23-0523 | AO1: SC-23-0526 | AP1: SC-23-0527 | AQ1: SC-23-0528 | AR1: SC-23-0530 | AS1: SC-23-0532 | AT1: SC-23-0538 | AU1: SC-23-0541 | AV1: SC-23-0544 | AW1: SC-23-0545 | AX1: SC-23-0548 | AY1: =+Q1 -> 0 | AZ1: =+R1 -> 0 | BA1: =+S1 -> 0 | BB1: =+T1 -> 0 | BC1: =+U1 -> 0 | BD1: =+V1 -> 0 | BE1: =+W1 -> 0 | BF1: =+X1 -> 0 | ... BO1: =+AG1 -> 0
A2: 800 | B2: -0.021080647 | C2: -0.0462068 | D2: -0.019724166 | E2: -0.08278526 | F2: -0.057539167 | G2: -0.0015180273 | H2: -0.00015116823 | I2: -0.0051019637 | J2: -0.0070720388 | K2: -0.017377287 | L2: -0.024057079 | M2: -0.058440258 | N2: -0.069398909 | O2: -0.058065855 | P2: -0.069396679 | AI2: 800 | AJ2: 0.00056112708 | AK2: 0.00067007796 | AL2: 0.00042354199 | AM2: 0.0011305665 | AN2: 0.00086196427 | AO2: 0.00033186946 | AP2: 0.00021566458 | AQ2: 0.00021418712 | AR2: 0.00017956334 | AS2: 0.00023531044 | AT2: 0.00036156413 | AU2: 0.00088437764 | AV2: 0.00083042479 | AW2: 0.00085773798 | AX2: 0.0009343342
A3: 799 | B3: -0.021442009 | C3: -0.048970033 | D3: -0.023297292 | E3: -0.091956234 | F3: -0.061240641 | G3: -0.0030410334 | H3: -0.0039096067 | I3: -0.0064715693 | J3: -0.0067216581 | K3: -0.019570856 | L3: -0.030835446 | M3: -0.060251528 | N3: -0.079255889 | O3: -0.069350437 | P3: -0.076049102 | AI3: 799 | AJ3: 0.00057151882 | AK3: 0.00068243963 | AL3: 0.00043149359 | AM3: 0.00115155 | AN3: 0.00087805902 | AO3: 0.00033799858 | AP3: 0.00021959047 | AQ3: 0.00021814283 | AR3: 0.00018289423 | AS3: 0.00023965386 | AT3: 0.00036816435 | AU3: 0.00090089991 | AV3: 0.0008452119 | AW3: 0.00087385868 | AX3: 0.00095194207
A4: 798 | B4: -0.02251786 | C4: -0.048765161 | D4: -0.02140572 | E4: -0.086125372 | F4: -0.057919749 | G4: -0.0064391422 | H4: -0.0029631335 | I4: -0.0079482483 | J4: -0.006445404 | K4: -0.016889641 | L4: -0.028154574 | M4: -0.060764918 | N4: -0.07921368 | O4: -0.064157191 | P4: -0.074137282 | AI4: 798 | AJ4: 0.000582103 | AK4: 0.00069502934 | AL4: 0.00043959448 | AM4: 0.0011729229 | AN4: 0.0008944543 | AO4: 0.0003442409 | AP4: 0.00022358783 | AQ4: 0.00022217159 | AR4: 0.00018628691 | AS4: 0.00024407746 | AT4: 0.00037488504 | AU4: 0.00091773085 | AV4: 0.00086026232 | AW4: 0.00089028236 | AX4: 0.00096988178
A5: 797 | B5: -0.022163704 | C5: -0.046710922 | D5: -0.024925653 | E5: -0.087504929 | F5: -0.060516202 | G5: -0.0083955752 | H5: -0.0012867292 | I5: -0.0074527049 | J5: -0.0081080802 | K5: -0.018051283 | L5: -0.026766093 | M5: -0.061360667 | N5: -0.07493945 | O5: -0.066600586 | P5: -0.075099883 | AI5: 797 | AJ5: 0.0005928832 | AK5: 0.00070785131 | AL5: 0.00044784745 | AM5: 0.0011946925 | AN5: 0.00091115572 | AO5: 0.0003505985 | AP5: 0.00022765796 | AQ5: 0.00022627476 | AR5: 0.00018974252 | AS5: 0.00024858271 | AT5: 0.00038172843 | AU5: 0.00093487624 | AV5: 0.00087558074 | AW5: 0.00090701471 | AX5: 0.00098815956
A6: 796 | B6: -0.02295575 | C6: -0.045993689 | D6: -0.020112298 | E6: -0.083516907 | F6: -0.056555289 | G6: -0.0053838799 | H6: 0.0045300662 | I6: -0.0067745935 | J6: -0.0069488398 | K6: -0.015446936 | L6: -0.025412272 | M6: -0.057443337 | N6: -0.070274002 | O6: -0.058807796 | P6: -0.067717529 | AI6: 796 | AJ6: 0.00060386304 | AK6: 0.00072090983 | AL6: 0.00045625537 | AM6: 0.0012168661 | AN6: 0.00092816899 | AO6: 0.00035707352 | AP6: 0.00023180218 | AQ6: 0.00023045371 | AR6: 0.00019326224 | AS6: 0.00025317113 | AT6: 0.00038869673 | AU6: 0.00095234195 | AV6: 0.00089117193 | AW6: 0.00092406153 | AX6: 0.0010067818
A7: 795 | B7: -0.023097822 | C7: -0.043467929 | D7: -0.020451353 | E7: -0.086651798 | F7: -0.056745408 | G7: -0.0040578586 | H7: 0.0047397451 | I7: -0.0051084835 | J7: -0.0016159186 | K7: -0.01430348 | L7: -0.026527588 | M7: -0.057638604 | N7: -0.069932546 | O7: -0.063690128 | P7: -0.069785838 | AI7: 795 | AJ7: 0.00061504621 | AK7: 0.00073420924 | AL7: 0.00046482113 | AM7: 0.0012394514 | AN7: 0.00094549993 | AO7: 0.00036366812 | AP7: 0.00023602184 | AQ7: 0.00023470984 | AR7: 0.00019684724 | AS7: 0.00025784423 | AT7: 0.00039579224 | AU7: 0.00097013396 | AV7: 0.00090704074 | AW7: 0.00094142875 | AX7: 0.001025755
A8: 794 | B8: -0.017120768 | C8: -0.040762006 | D8: -0.015275952 | E8: -0.078956815 | F8: -0.053413879 | G8: -0.0021803563 | H8: 0.0048358309 | I8: -0.0015264388 | J8: -0.0028335009 | K8: -0.016351886 | L8: -0.022228651 | M8: -0.058910406 | N8: -0.064540258 | O8: -0.061771446 | P8: -0.069369227 | AI8: 794 | AJ8: 0.0006264365 | AK8: 0.00074775401 | AL8: 0.00047354771 | AM8: 0.0012624557 | AN8: 0.00096315448 | AO8: 0.00037038452 | AP8: 0.00024031831 | AQ8: 0.00023904457 | AR8: 0.00020049875 | AS8: 0.00026260359 | AT8: 0.00040301728 | AU8: 0.00098825836 | AV8: 0.00092319213 | AW8: 0.00095912237 | AX8: 0.0010450857
A9: 793 | B9: -0.021368228 | C9: -0.040145322 | D9: -0.018212486 | E9: -0.081581749 | F9: -0.052481816 | G9: -0.00013469349 | H9: 0.0063739378 | I9: -0.0023696131 | J9: -0.0011045904 | K9: -0.014345005 | L9: -0.017831563 | M9: -0.058257344 | N9: -0.067124696 | O9: -0.058470455 | P9: -0.067810529 | AI9: 793 | AJ9: 0.00063803772 | AK9: 0.00076154865 | AL9: 0.00048243812 | AM9: 0.0012858871 | AN9: 0.00098113868 | AO9: 0.00037722495 | AP9: 0.00024469299 | AQ9: 0.00024345936 | AR9: 0.00020421799 | AS9: 0.00026745081 | AT9: 0.0004103742 | AU9: 0.0010067214 | AV9: 0.00093963111 | AW9: 0.00097714853 | AX9: 0.0010647807
A10: 792 | B10: -0.019550781 | C10: -0.040928446 | D10: -0.018864176 | E10: -0.084531671 | F10: -0.051636237 | G10: -0.0020355344 | H10: 0.0059628154 | I10: -0.0017354291 | J10: 0.0015958429 | K10: -0.013848433 | L10: -0.024139784 | M10: -0.061381942 | N10: -0.066896487 | O10: -0.062708995 | P10: -0.07033423 | AI10: 792 | AJ10: 0.0006498538 | AK10: 0.00077559778 | AL10: 0.00049149544 | AM10: 0.0013097533 | AN10: 0.00099945868 | AO10: 0.00038419172 | AP10: 0.00024914731 | AQ10: 0.00024795568 | AR10: 0.00020800622 | AS10: 0.00027238749 | AT10: 0.00041786542 | AU10: 0.0010255293 | AV10: 0.00095636283 | AW10: 0.00099551348 | AX10: 0.0010848469
A11: 791 | B11: -0.019915573 | C11: -0.042210885 | D11: -0.016927304 | E11: -0.081071795 | F11: -0.048673962 | G11: 0.0032699304 | H11: 0.010072664 | I11: 0.00022649429 | J11: -0.0004827597 | K11: -0.012982606 | L11: -0.020080383 | M11: -0.053696225 | N11: -0.064820973 | O11: -0.056690416 | P11: -0.064453264 | AI11: 791 | AJ11: 0.0006618887 | AK11: 0.00078990609 | AL11: 0.00050072281 | AM11: 0.0013340625 | AN11: 0.0010181208 | AO11: 0.00039128716 | AP11: 0.00025368271 | AQ11: 0.00025253504 | AR11: 0.00021186473 | AS11: 0.0002774153 | AT11: 0.0004254934 | AU11: 0.0010446886 | AV11: 0.00097339247 | AW11: 0.0010142236 | AX11: 0.0011052913
A12: 790 | B12: -0.015959123 | C12: -0.040303181 | D12: -0.020007629 | E12: -0.082786975 | F12: -0.049643428 | G12: 0.00084609433 | H12: 0.008531128 | I12: -0.0021626817 | J12: -0.00013958506 | K12: -0.0086229255 | L12: -0.019000414 | M12: -0.059396339 | N12: -0.063946908 | O12: -0.063751556 | P12: -0.066765566 | AI12: 790 | AJ12: 0.00067414647 | AK12: 0.00080447836 | AL12: 0.0005101234 | AM12: 0.0013588229 | AN12: 0.0010371313 | AO12: 0.00039851363 | AP12: 0.00025830068 | AQ12: 0.00025719898 | AR12: 0.00021579481 | AS12: 0.00028253591 | AT12: 0.00043326062 | AU12: 0.0010642059 | AV12: 0.00099072536 | AW12: 0.0010332854 | AX12: 0.0011261209
A13: 789 | B13: -0.017448496 | C13: -0.041837854 | D13: -0.019235145 | E13: -0.081778731 | F13: -0.05276768 | G13: -0.00085364403 | H13: 0.0025321077 | I13: -0.00012491357 | J13: -0.0011272381 | K13: -0.013553646 | L13: -0.021515191 | M13: -0.060200738 | N13: -0.065156596 | O13: -0.06201544 | P13: -0.070842813 | AI13: 789 | AJ13: 0.00068663126 | AK13: 0.00081931945 | AL13: 0.00051970049 | AM13: 0.0013840429 | AN13: 0.0010564968 | AO13: 0.00040587357 | AP13: 0.00026300271 | AQ13: 0.00026194905 | AR13: 0.00021979779 | AS13: 0.00028775104 | AT13: 0.00044116962 | AU13: 0.0010840878 | AV13: 0.0010083669 | AW13: 0.0010527054 | AX13: 0.0011473431
... A552: 250 | B552: 2.7049368 | C552: 3.242931 | D552: 2.4179433 | E552: 4.1724473 | F552: 4.2557251 | G552: 1.9695385 | H552: 1.0706762 | I552: 1.3586454 | J552: 1.5801288 | K552: 1.7416747 | L552: 2.4261355 | M552: 4.2108024 | N552: 2.8306745 | O552: 4.4506424 | P552: 4.6645804 | AI552: 250 | AJ552: 13.557459 | AK552: 15.578371 | AL552: 11.741647 | AM552: 27.923358 | AN552: 22.617032 | AO552: 7.8008378 | AP552: 4.3938848 | AQ552: 5.0346271 | AR552: 4.4106296 | AS552: 5.5008085 | AT552: 7.5717853 | AU552: 23.333115 | AV552: 13.652557 | AW552: 24.041659 | AX552: 26.918765

Sheet ax(443)
B1: =+aCDOM!B1 -> E3 | C1: =+aCDOM!C1 -> E2 | D1: =+aCDOM!D1 -> E1 | E1: =+aCDOM!E1 -> E4 | F1: =+aCDOM!F1 -> E5 | G1: =+aCDOM!G1 -> E24 | H1: =+aCDOM!H1 -> E25 | I1: =+aCDOM!I1 -> E27 | ... AG1: =+aCDOM!AG1 -> 0
A2: ap (443) | B2: =+ap!B359 -> 0.43450072 | C2: =+ap!C359 -> 0.80901301 | D2: =+ap!D359 -> 0.37718041 | E2: =+ap!E359 -> 2.0044174 | F2: =+ap!F359 -> 0.6526502 | G2: =+ap!G359 -> 0.25250739 | H2: =+ap!H359 -> 0.090390764 | I2: =+ap!I359 -> 0.039898015 | ... AG2: =+ap!AG359 -> 0
A3: ad (443) | B3: =+ad!B359 -> 0.22081783 | C3: =+ad!C359 -> 0.51130763 | D3: =+ad!D359 -> 0.14670572 | E3: =+ad!E359 -> 1.6125823 | F3: =+ad!F359 -> 0.37903281 | G3: =+ad!G359 -> 0.058026398 | H3: =+ad!H359 -> 0.023357103 | I3: =+ad!I359 -> 6.6307167e-05 | ... AG3: =+ad!AG359 -> 0
A4: aphy (443) | B4: =+aphy!B359 -> 0.21368289 | C4: =+aphy!C359 -> 0.29770539 | D4: =+aphy!D359 -> 0.23047469 | E4: =+aphy!E359 -> 0.39183507 | F4: =+aphy!F359 -> 0.27361739 | G4: =+aphy!G359 -> 0.19448099 | H4: =+aphy!H359 -> 0.067033661 | I4: =+aphy!I359 -> 0.039831708 | ... AG4: =+aphy!AG359 -> 0
A5: aCDOM (443) | B5: =+aCDOM!B359 -> 0.3959742 | C5: =+aCDOM!C359 -> 0.46405009 | D5: =+aCDOM!D359 -> 0.324961 | E5: =+aCDOM!E359 -> 0.81063146 | F5: =+aCDOM!F359 -> 0.6392263 | G5: =+aCDOM!G359 -> 0.22728671 | H5: =+aCDOM!H359 -> 0.13763412 | I5: =+aCDOM!I359 -> 0.14570668 | ... AG5: =+aCDOM!AG359 -> 0
A6: aCDOM (443)-Modelado | B6: =+aCDOM!AJ359 -> 0.39273777 | C6: =+aCDOM!AK359 -> 0.45741853 | D6: =+aCDOM!AL359 -> 0.32411467 | E6: =+aCDOM!AM359 -> 0.80267414 | F6: =+aCDOM!AN359 -> 0.63648353 | G6: =+aCDOM!AO359 -> 0.22816896 | H6: =+aCDOM!AP359 -> 0.13513159 | I6: =+aCDOM!AQ359 -> 0.14725927 | ... AG6: =+aCDOM!BO359 -> 0
A7: TOTAL-CDOM | B7: =SUM(B3:B5) -> 0.83047491 | C7: =SUM(C3:C5) -> 1.2730631 | D7: =SUM(D3:D5) -> 0.7021414 | E7: =SUM(E3:E5) -> 2.8150489 | F7: =SUM(F3:F5) -> 1.2918765 | G7: =SUM(G3:G5) -> 0.4797941 | H7: =SUM(H3:H5) -> 0.22802488 | I7: =SUM(I3:I5) -> 0.1856047 | ... AG7: =SUM(AG3:AG5) -> 0
A8: TOTAL-CDOM Modelado | B8: =SUM(B3:B4,B6) -> 0.82723848 | C8: =SUM(C3:C4,C6) -> 1.2664315 | D8: =SUM(D3:D4,D6) -> 0.70129508 | E8: =SUM(E3:E4,E6) -> 2.8070915 | F8: =SUM(F3:F4,F6) -> 1.2891337 | G8: =SUM(G3:G4,G6) -> 0.48067635 | H8: =SUM(H3:H4,H6) -> 0.22552235 | I8: =SUM(I3:I4,I6) -> 0.18715728 | ... AG8: =SUM(AG3:AG4,AG6) -> 0
A9: codigo | B9: =+aCDOM!AJ1 -> SC-23-0513 | C9: =+aCDOM!AK1 -> SC-23-0516 | D9: =+aCDOM!AL1 -> SC-23-0519 | E9: =+aCDOM!AM1 -> SC-23-0522 | F9: =+aCDOM!AN1 -> SC-23-0523 | G9: =+aCDOM!AO1 -> SC-23-0526 | H9: =+aCDOM!AP1 -> SC-23-0527 | I9: =+aCDOM!AQ1 -> SC-23-0528 | ... P9: =+aCDOM!AX1 -> SC-23-0548 | Q9: =+ap!Q1 -> 0 | R9: =+ap!R1 -> 0 | S9: =+ap!S1 -> 0 | T9: =+ap!T1 -> 0 | U9: =+ap!U1 -> 0 | V9: =+ap!V1 -> 0 | W9: =+ap!W1 -> 0 | X9: =+ap!X1 -> 0 | ... AG9: =+ap!AG1 -> 0
B10: =+B1 -> E3 | C10: =+C1 -> E2 | D10: =+D1 -> E1 | E10: =+E1 -> E4 | F10: =+F1 -> E5 | G10: =+G1 -> E24 | H10: =+H1 -> E25 | I10: =+I1 -> E27 | ... AG10: =+AG1 -> 0
A11: ad (443) | B11: =(B3*100)/B$7 -> 26.589344 | C11: =(C3*100)/C$7 -> 40.163573 | D11: =(D3*100)/D$7 -> 20.894042 | E11: =(E3*100)/E$7 -> 57.284346 | F11: =(F3*100)/F$7 -> 29.33971 | G11: =(G3*100)/G$7 -> 12.094021 | H11: =(H3*100)/H$7 -> 10.243226 | I11: =(I3*100)/I$7 -> 0.035724941 | ... AG11: =(AG3*100)/AG$7 -> #DIV/0!
A12: aphy (443) | B12: =(B4*100)/B$7 -> 25.730204 | C12: =(C4*100)/C$7 -> 23.384967 | D12: =(D4*100)/D$7 -> 32.82454 | E12: =(E4*100)/E$7 -> 13.919299 | F12: =(F4*100)/F$7 -> 21.179841 | G12: =(G4*100)/G$7 -> 40.53426 | H12: =(H4*100)/H$7 -> 29.39752 | I12: =(I4*100)/I$7 -> 21.460507 | ... AG12: =(AG4*100)/AG$7 -> #DIV/0!
A13: aCDOM (443) | B13: =(B5*100)/B$7 -> 47.680453 | C13: =(C5*100)/C$7 -> 36.45146 | D13: =(D5*100)/D$7 -> 46.281418 | E13: =(E5*100)/E$7 -> 28.796355 | F13: =(F5*100)/F$7 -> 49.480449 | G13: =(G5*100)/G$7 -> 47.371719 | H13: =(H5*100)/H$7 -> 60.359254 | I13: =(I5*100)/I$7 -> 78.503768 | ... AG13: =(AG5*100)/AG$7 -> #DIV/0!
B14: =SUM(B11:B13) -> 100 | C14: =SUM(C11:C13) -> 100 | D14: =SUM(D11:D13) -> 100 | E14: =SUM(E11:E13) -> 100 | F14: =SUM(F11:F13) -> 100 | G14: =SUM(G11:G13) -> 100 | H14: =SUM(H11:H13) -> 100 | I14: =SUM(I11:I13) -> 100 | ... AG14: =SUM(AG11:AG13) -> #DIV/0!
B15: =+B1 -> E3 | C15: =+C1 -> E2 | D15: =+D1 -> E1 | E15: =+E1 -> E4 | F15: =+F1 -> E5 | G15: =+G1 -> E24 | H15: =+H1 -> E25 | I15: =+I1 -> E27 | ... AG15: =+AG1 -> 0
A16: ad (443) | B16: =(B3*100)/B$8 -> 26.69337 | C16: =(C3*100)/C$8 -> 40.373886 | D16: =(D3*100)/D$8 -> 20.919257 | E16: =(E3*100)/E$8 -> 57.446731 | F16: =(F3*100)/F$8 -> 29.402133 | G16: =(G3*100)/G$8 -> 12.071823 | H16: =(H3*100)/H$8 -> 10.356891 | I16: =(I3*100)/I$8 -> 0.03542858 | ... AG16: =(AG3*100)/AG$8 -> #DIV/0!
A17: aphy (443) | B17: =(B4*100)/B$8 -> 25.830869 | C17: =(C4*100)/C$8 -> 23.507421 | D17: =(D4*100)/D$8 -> 32.864153 | E17: =(E4*100)/E$8 -> 13.958756 | F17: =(F4*100)/F$8 -> 21.224903 | G17: =(G4*100)/G$8 -> 40.459862 | H17: =(H4*100)/H$8 -> 29.723732 | I17: =(I4*100)/I$8 -> 21.282478 | ... AG17: =(AG4*100)/AG$8 -> #DIV/0!
A18: =+A6 -> aCDOM (443)-Modelado | B18: =(B6*100)/B$8 -> 47.475761 | C18: =(C6*100)/C$8 -> 36.118693 | D18: =(D6*100)/D$8 -> 46.21659 | E18: =(E6*100)/E$8 -> 28.594512 | F18: =(F6*100)/F$8 -> 49.372964 | G18: =(G6*100)/G$8 -> 47.468315 | H18: =(H6*100)/H$8 -> 59.919377 | I18: =(I6*100)/I$8 -> 78.682093 | ... AG18: =(AG6*100)/AG$8 -> #DIV/0!
B19: =SUM(B16:B18) -> 100 | C19: =SUM(C16:C18) -> 100 | D19: =SUM(D16:D18) -> 100 | E19: =SUM(E16:E18) -> 100 | F19: =SUM(F16:F18) -> 100 | G19: =SUM(G16:G18) -> 100 | H19: =SUM(H16:H18) -> 100 | I19: =SUM(I16:I18) -> 100 | ... AG19: =SUM(AG16:AG18) -> #DIV/0!
W20: CDOM
U21: E2 | V21: SC-23-0516 | W21: BC7
U22: E24 | V22: SC-23-0526 | W22: BC18
U23: E12 | V23: SC-23-0532 | W23: BC77
U24: E1 | V24: SC-23-0519 | W24: BC10
U25: E3 | V25: SC-23-0513 | W25: BC01
U26: E5 | V26: SC-23-0523 | W26: BC05
U27: E27 | V27: SC-23-0528 | W27: BC14
U28: E13 | V28: SC-23-0538 | W28: BC26
U29: E25 | V29: SC-23-0527 | W29: BC12
U30: E10 | V30: SC-23-0544 | W30: BC22
U31: E4 | V31: SC-23-0522 | W31: BC4
U32: E9 | V32: SC-23-0545 | W32: BC37
... U35: E31 | V35: SC-23-0530 | W35: BC24

Sheet aphy-Especifico
A1: Wavelength (nm) | B1: =+'ax(443)'!B1 -> E3 | C1: =+'ax(443)'!C1 -> E2 | D1: =+'ax(443)'!D1 -> E1 | E1: =+'ax(443)'!E1 -> E4 | F1: =+'ax(443)'!F1 -> E5 | G1: =+'ax(443)'!G1 -> E24 | H1: =+'ax(443)'!H1 -> E25 | I1: =+'ax(443)'!I1 -> E27 | ... AC1: =+'ax(443)'!AC1 -> 0 | AD1: =+'ax(443)'!#REF! -> #REF!
A2: 800 | B2: =aphy!$B$2/aphy!AQ$3 -> #DIV/0! | C2: =aphy!$B$2/aphy!AR$3 -> #DIV/0! | D2: =aphy!$B$2/aphy!AS$3 -> #DIV/0! | E2: =aphy!$B$2/aphy!AT$3 -> #DIV/0! | F2: =aphy!$B$2/aphy!AU$3 -> #DIV/0! | G2: =aphy!$B$2/aphy!AV$3 -> #DIV/0! | H2: =aphy!$B$2/aphy!AW$3 -> #DIV/0! | I2: =aphy!$B$2/aphy!AX$3 -> #DIV/0! | ... AD2: =aphy!$B$2/aphy!BS$3 -> #DIV/0!
A3: 799 | B3: =aphy!$B$2/aphy!AQ$3 -> #DIV/0! | C3: =aphy!$B$2/aphy!AR$3 -> #DIV/0! | D3: =aphy!$B$2/aphy!AS$3 -> #DIV/0! | E3: =aphy!$B$2/aphy!AT$3 -> #DIV/0! | F3: =aphy!$B$2/aphy!AU$3 -> #DIV/0! | G3: =aphy!$B$2/aphy!AV$3 -> #DIV/0! | H3: =aphy!$B$2/aphy!AW$3 -> #DIV/0! | I3: =aphy!$B$2/aphy!AX$3 -> #DIV/0! | ... AD3: =aphy!$B$2/aphy!BS$3 -> #DIV/0!
A4: 798 | B4: =aphy!$B$2/aphy!AQ$3 -> #DIV/0! | C4: =aphy!$B$2/aphy!AR$3 -> #DIV/0! | D4: =aphy!$B$2/aphy!AS$3 -> #DIV/0! | E4: =aphy!$B$2/aphy!AT$3 -> #DIV/0! | F4: =aphy!$B$2/aphy!AU$3 -> #DIV/0! | G4: =aphy!$B$2/aphy!AV$3 -> #DIV/0! | H4: =aphy!$B$2/aphy!AW$3 -> #DIV/0! | I4: =aphy!$B$2/aphy!AX$3 -> #DIV/0! | ... AD4: =aphy!$B$2/aphy!BS$3 -> #DIV/0!
A5: 797 | B5: =aphy!$B$2/aphy!AQ$3 -> #DIV/0! | C5: =aphy!$B$2/aphy!AR$3 -> #DIV/0! | D5: =aphy!$B$2/aphy!AS$3 -> #DIV/0! | E5: =aphy!$B$2/aphy!AT$3 -> #DIV/0! | F5: =aphy!$B$2/aphy!AU$3 -> #DIV/0! | G5: =aphy!$B$2/aphy!AV$3 -> #DIV/0! | H5: =aphy!$B$2/aphy!AW$3 -> #DIV/0! | I5: =aphy!$B$2/aphy!AX$3 -> #DIV/0! | ... AD5: =aphy!$B$2/aphy!BS$3 -> #DIV/0!
A6: 796 | B6: =aphy!$B$2/aphy!AQ$3 -> #DIV/0! | C6: =aphy!$B$2/aphy!AR$3 -> #DIV/0! | D6: =aphy!$B$2/aphy!AS$3 -> #DIV/0! | E6: =aphy!$B$2/aphy!AT$3 -> #DIV/0! | F6: =aphy!$B$2/aphy!AU$3 -> #DIV/0! | G6: =aphy!$B$2/aphy!AV$3 -> #DIV/0! | H6: =aphy!$B$2/aphy!AW$3 -> #DIV/0! | I6: =aphy!$B$2/aphy!AX$3 -> #DIV/0! | ... AD6: =aphy!$B$2/aphy!BS$3 -> #DIV/0!
A7: 795 | B7: =aphy!$B$2/aphy!AQ$3 -> #DIV/0! | C7: =aphy!$B$2/aphy!AR$3 -> #DIV/0! | D7: =aphy!$B$2/aphy!AS$3 -> #DIV/0! | E7: =aphy!$B$2/aphy!AT$3 -> #DIV/0! | F7: =aphy!$B$2/aphy!AU$3 -> #DIV/0! | G7: =aphy!$B$2/aphy!AV$3 -> #DIV/0! | H7: =aphy!$B$2/aphy!AW$3 -> #DIV/0! | I7: =aphy!$B$2/aphy!AX$3 -> #DIV/0! | ... AD7: =aphy!$B$2/aphy!BS$3 -> #DIV/0!
A8: 794 | B8: =aphy!$B$2/aphy!AQ$3 -> #DIV/0! | C8: =aphy!$B$2/aphy!AR$3 -> #DIV/0! | D8: =aphy!$B$2/aphy!AS$3 -> #DIV/0! | E8: =aphy!$B$2/aphy!AT$3 -> #DIV/0! | F8: =aphy!$B$2/aphy!AU$3 -> #DIV/0! | G8: =aphy!$B$2/aphy!AV$3 -> #DIV/0! | H8: =aphy!$B$2/aphy!AW$3 -> #DIV/0! | I8: =aphy!$B$2/aphy!AX$3 -> #DIV/0! | ... AD8: =aphy!$B$2/aphy!BS$3 -> #DIV/0!
A9: 793 | B9: =aphy!$B$2/aphy!AQ$3 -> #DIV/0! | C9: =aphy!$B$2/aphy!AR$3 -> #DIV/0! | D9: =aphy!$B$2/aphy!AS$3 -> #DIV/0! | E9: =aphy!$B$2/aphy!AT$3 -> #DIV/0! | F9: =aphy!$B$2/aphy!AU$3 -> #DIV/0! | G9: =aphy!$B$2/aphy!AV$3 -> #DIV/0! | H9: =aphy!$B$2/aphy!AW$3 -> #DIV/0! | I9: =aphy!$B$2/aphy!AX$3 -> #DIV/0! | ... AD9: =aphy!$B$2/aphy!BS$3 -> #DIV/0!
A10: 792 | B10: =aphy!$B$2/aphy!AQ$3 -> #DIV/0! | C10: =aphy!$B$2/aphy!AR$3 -> #DIV/0! | D10: =aphy!$B$2/aphy!AS$3 -> #DIV/0! | E10: =aphy!$B$2/aphy!AT$3 -> #DIV/0! | F10: =aphy!$B$2/aphy!AU$3 -> #DIV/0! | G10: =aphy!$B$2/aphy!AV$3 -> #DIV/0! | H10: =aphy!$B$2/aphy!AW$3 -> #DIV/0! | I10: =aphy!$B$2/aphy!AX$3 -> #DIV/0! | ... AD10: =aphy!$B$2/aphy!BS$3 -> #DIV/0!
A11: 791 | B11: =aphy!$B$2/aphy!AQ$3 -> #DIV/0! | C11: =aphy!$B$2/aphy!AR$3 -> #DIV/0! | D11: =aphy!$B$2/aphy!AS$3 -> #DIV/0! | E11: =aphy!$B$2/aphy!AT$3 -> #DIV/0! | F11: =aphy!$B$2/aphy!AU$3 -> #DIV/0! | G11: =aphy!$B$2/aphy!AV$3 -> #DIV/0! | H11: =aphy!$B$2/aphy!AW$3 -> #DIV/0! | I11: =aphy!$B$2/aphy!AX$3 -> #DIV/0! | ... AD11: =aphy!$B$2/aphy!BS$3 -> #DIV/0!
A12: 790 | B12: =aphy!$B$2/aphy!AQ$3 -> #DIV/0! | C12: =aphy!$B$2/aphy!AR$3 -> #DIV/0! | D12: =aphy!$B$2/aphy!AS$3 -> #DIV/0! | E12: =aphy!$B$2/aphy!AT$3 -> #DIV/0! | F12: =aphy!$B$2/aphy!AU$3 -> #DIV/0! | G12: =aphy!$B$2/aphy!AV$3 -> #DIV/0! | H12: =aphy!$B$2/aphy!AW$3 -> #DIV/0! | I12: =aphy!$B$2/aphy!AX$3 -> #DIV/0! | ... AD12: =aphy!$B$2/aphy!BS$3 -> #DIV/0!
A13: 789 | B13: =aphy!$B$2/aphy!AQ$3 -> #DIV/0! | C13: =aphy!$B$2/aphy!AR$3 -> #DIV/0! | D13: =aphy!$B$2/aphy!AS$3 -> #DIV/0! | E13: =aphy!$B$2/aphy!AT$3 -> #DIV/0! | F13: =aphy!$B$2/aphy!AU$3 -> #DIV/0! | G13: =aphy!$B$2/aphy!AV$3 -> #DIV/0! | H13: =aphy!$B$2/aphy!AW$3 -> #DIV/0! | I13: =aphy!$B$2/aphy!AX$3 -> #DIV/0! | ... AD13: =aphy!$B$2/aphy!BS$3 -> #DIV/0!
... A402: 400 | B402: =aphy!$B$2/aphy!AQ$3 -> #DIV/0! | C402: =aphy!$B$2/aphy!AR$3 -> #DIV/0! | D402: =aphy!$B$2/aphy!AS$3 -> #DIV/0! | E402: =aphy!$B$2/aphy!AT$3 -> #DIV/0! | F402: =aphy!$B$2/aphy!AU$3 -> #DIV/0! | G402: =aphy!$B$2/aphy!AV$3 -> #DIV/0! | H402: =aphy!$B$2/aphy!AW$3 -> #DIV/0! | I402: =aphy!$B$2/aphy!AX$3 -> #DIV/0! | ... AD402: =aphy!$B$2/aphy!BS$3 -> #DIV/0!

Sheet Varias longitudes de onda
C1: SC-23-0513 | D1: SC-23-0516 | E1: SC-23-0519 | F1: SC-23-0522 | G1: SC-23-0523 | H1: SC-23-0526 | I1: SC-23-0527 | J1: SC-23-0528 | K1: SC-23-0530 | L1: SC-23-0532 | M1: SC-23-0538 | N1: SC-23-0541 | O1: SC-23-0544 | P1: SC-23-0545 | Q1: SC-23-0548 | AI1: =+aCDOM!AH1 -> ESPECTROS MODELADOS | AJ1: =+aCDOM!AI1 -> Wavelength (nm) | AK1: =+aCDOM!AJ1 -> SC-23-0513 | AL1: =+aCDOM!AK1 -> SC-23-0516 | AM1: =+aCDOM!AL1 -> SC-23-0519 | AN1: =+aCDOM!AM1 -> SC-23-0522 | AO1: =+aCDOM!AN1 -> SC-23-0523 | AP1: =+aCDOM!AO1 -> SC-23-0526 | ... AY1: =+aCDOM!AX1 -> SC-23-0548
A2: aCDOM | B2: Wavelength (nm) | C2: =+ap!B1 -> E3 | D2: =+ap!C1 -> E2 | E2: =+ap!D1 -> E1 | F2: =+ap!E1 -> E4 | G2: =+ap!F1 -> E5 | H2: =+ap!G1 -> E24 | I2: =+ap!H1 -> E25 | J2: =+ap!I1 -> E27 | ... Q2: =+ap!P1 -> E7
B3: 715 | C3: =+aCDOM!B87 -> -0.040871135 | D3: =+aCDOM!C87 -> -0.056865262 | E3: =+aCDOM!D87 -> -0.042753528 | F3: =+aCDOM!E87 -> -0.074824144 | G3: =+aCDOM!F87 -> -0.063860258 | H3: =+aCDOM!G87 -> -0.024682256 | I3: =+aCDOM!H87 -> -0.012389602 | J3: =+aCDOM!I87 -> -0.014415356 | ... Q3: =+aCDOM!P87 -> -0.065925134 | AJ3: =+aCDOM!AI87 -> 715 | AK3: =+aCDOM!AJ87 -> 0.002669636 | AL3: =+aCDOM!AK87 -> 0.0031690719 | AM3: =+aCDOM!AL87 -> 0.002058335 | AN3: =+aCDOM!AM87 -> 0.0053971381 | AO3: =+aCDOM!AN87 -> 0.0041535298 | AP3: =+aCDOM!AO87 -> 0.0015722165 | AQ3: =+aCDOM!AP87 -> 0.00099936924 | ... AY3: =+aCDOM!AX87 -> 0.0045677873
B4: 676 | C4: =+aCDOM!B126 -> -0.022430865 | D4: =+aCDOM!C126 -> -0.033506969 | E4: =+aCDOM!D126 -> -0.019893439 | F4: =+aCDOM!E126 -> -0.059687094 | G4: =+aCDOM!F126 -> -0.046026033 | H4: =+aCDOM!G126 -> -0.0093324381 | I4: =+aCDOM!H126 -> -0.0055626747 | J4: =+aCDOM!I126 -> -0.016135943 | ... Q4: =+aCDOM!P126 -> -0.057662883 | AJ4: =+aCDOM!AI126 -> 676 | AK4: =+aCDOM!AJ126 -> 0.0054607827 | AL4: =+aCDOM!AK126 -> 0.0064647141 | AM4: =+aCDOM!AL126 -> 0.0042516085 | AN4: =+aCDOM!AM126 -> 0.011057167 | AO4: =+aCDOM!AN126 -> 0.008545959 | AP4: =+aCDOM!AO126 -> 0.0032097287 | AQ4: =+aCDOM!AP126 -> 0.0020196597 | ... AY4: =+aCDOM!AX126 -> 0.0094608186
B5: 650 | C5: =+aCDOM!B152 -> -0.01659674 | D5: =+aCDOM!C152 -> -0.023011343 | E5: =+aCDOM!D152 -> -0.016818602 | F5: =+aCDOM!E152 -> -0.046846133 | G5: =+aCDOM!F152 -> -0.03507004 | H5: =+aCDOM!G152 -> -0.0070885967 | I5: =+aCDOM!H152 -> -0.0057347763 | J5: =+aCDOM!I152 -> -0.011829628 | ... Q5: =+aCDOM!P152 -> -0.047681761 | AJ5: =+aCDOM!AI152 -> 650 | AK5: =+aCDOM!AJ152 -> 0.0087994756 | AL5: =+aCDOM!AK152 -> 0.010398263 | AM5: =+aCDOM!AL152 -> 0.0068956956 | AN5: =+aCDOM!AM152 -> 0.017835999 | AO5: =+aCDOM!AN152 -> 0.013824723 | AP5: =+aCDOM!AO152 -> 0.00516542 | AQ5: =+aCDOM!AP152 -> 0.0032283431 | ... AY5: =+aCDOM!AX152 -> 0.01537248
B6: 630 | C6: =+aCDOM!B172 -> -0.0090268418 | D6: =+aCDOM!C172 -> -0.011720584 | E6: =+aCDOM!D172 -> -0.0079630034 | F6: =+aCDOM!E172 -> -0.026279044 | G6: =+aCDOM!F172 -> -0.019583295 | H6: =+aCDOM!G172 -> 7.704272e-05 | I6: =+aCDOM!H172 -> 0.00020436016 | J6: =+aCDOM!I172 -> -0.0041698182 | ... Q6: =+aCDOM!P172 -> -0.021768025 | AJ6: =+aCDOM!AI172 -> 630 | AK6: =+aCDOM!AJ172 -> 0.012701145 | AL6: =+aCDOM!AK172 -> 0.014987834 | AM6: =+aCDOM!AL172 -> 0.010003123 | AN6: =+aCDOM!AM172 -> 0.025765047 | AO6: =+aCDOM!AN172 -> 0.020014531 | AP6: =+aCDOM!AO172 -> 0.0074483045 | AQ6: =+aCDOM!AP172 -> 0.0046309825 | ... AY6: =+aCDOM!AX172 -> 0.022331068
B7: 555 | C7: =+aCDOM!B247 -> 0.043770524 | D7: =+aCDOM!C247 -> 0.053971363 | E7: =+aCDOM!D247 -> 0.036722164 | F7: =+aCDOM!E247 -> 0.0874894 | G7: =+aCDOM!F247 -> 0.069645996 | H7: =+aCDOM!G247 -> 0.027242676 | I7: =+aCDOM!H247 -> 0.01849921 | J7: =+aCDOM!I247 -> 0.0157171 | ... Q7: =+aCDOM!P247 -> 0.079810544 | AJ7: =+aCDOM!AI247 -> 555 | AK7: =+aCDOM!AJ247 -> 0.050296834 | AL7: =+aCDOM!AK247 -> 0.059041394 | AM7: =+aCDOM!AL247 -> 0.040362349 | AN7: =+aCDOM!AM247 -> 0.10233675 | AO7: =+aCDOM!AN247 -> 0.080154702 | AP7: =+aCDOM!AO247 -> 0.029385061 | AQ7: =+aCDOM!AP247 -> 0.017917342 | ... AY7: =+aCDOM!AX247 -> 0.09057959
