Workbook

Sheet ap
A1: Wavelength (nm) | B1: SC-22-0415 | C1: SC-22-0416 | D1: SC-22-0419 | E1: SC-22-0423 | F1: SC-22-0427 | G1: SC-22-0428 | H1: SC-22-0429 | I1: SC-22-0431 | J1: SC-22-0434 | K1: SC-22-0437 | L1: SC-22-0441 | M1: SC-22-0444 | N1: SC-22-0453 | O1: SC-22-0454 | P1: SC-22-0455 | Q1: SC-22-0456 | R1: SC-22-0459 | S1: SC-22-0463 | T1: SC-22-0464 | U1: SC-22-0465 | V1: SC-22-0466 | W1: SC-22-0468 | X1: SC-22-0469 | Y1: SC-22-0470 | Z1: SC-22-0471 | AA1: SC-22-0473 | AB1: SC-22-0474 | AC1: SC-22-0475 | AD1: SC-22-0479
A2: 800 | B2: 0.0011551786 | C2: 0.0012465232 | D2: 0.0010798209 | E2: 0.0036809331 | F2: 0.0012931161 | G2: 0.0052181697 | H2: 0.0070792285 | I2: 0.0038611364 | J2: 0.0048595251 | K2: 0.0045907657 | L2: 0.0052432202 | M2: 0.014952665 | N2: 0.00052055981 | O2: 0.00036621672 | P2: 0.00016690459 | Q2: 0.00083968951 | R2: 0.0011732033 | S2: 0.0012856455 | T2: 0.0014060929 | U2: 0.00015140433 | V2: 0.00080920814 | W2: 0.00025123661 | X2: 0.00079502737 | Y2: 0.00127588 | Z2: 0.00096103695 | AA2: 0.00033955457 | AB2: 0.00052592175 | AC2: 0.0015248657 | AD2: 0.0018064571
A3: 799 | B3: 0.0011737599 | C3: 0.0014378672 | D3: 0.0017715879 | E3: 0.0053572675 | F3: 0.0023882945 | G3: 0.0052728636 | H3: 0.010413589 | I3: 0.0042559854 | J3: 0.0057565279 | K3: 0.0071904368 | L3: 0.0053389035 | M3: 0.018274188 | N3: 0.001116837 | O3: 0.0010529347 | P3: 0.00019681882 | Q3: 0.001257676 | R3: 0.0019013021 | S3: 0.0015597328 | T3: 0.0021878123 | U3: 0.0014867059 | V3: 0.0014255179 | W3: 0.00085633542 | X3: 0.0011612984 | Y3: 0.0015656164 | Z3: 0.0035784155 | AA3: 0.00098228605 | AB3: 0.0012793124 | AC3: 0.0036031935 | AD3: 0.0023317271
A4: 798 | B4: 0.00090286017 | C4: 0.0013174002 | D4: 0.00090761806 | E4: 0.0032934423 | F4: 0.001128301 | G4: 0.0054954531 | H4: 0.009863931 | I4: 0.0048344765 | J4: 0.0059132909 | K4: 0.0040374557 | L4: 0.0039490681 | M4: 0.013724248 | N4: 0.00085436545 | O4: 0.00041643945 | P4: 0.00012101437 | Q4: 0.00093260206 | R4: 0.0010181598 | S4: 0.00057228719 | T4: 0.0019230364 | U4: 0.00048623693 | V4: 0.00076972385 | W4: 0.00042709531 | X4: 0.00057618635 | Y4: 0.0012441361 | Z4: 0.0012399024 | AA4: 0.00093538287 | AB4: 0.00030397192 | AC4: 0.0018158076 | AD4: 0.0013999424
A5: 797 | B5: 0.00098622409 | C5: 0.00076322524 | D5: 0.0011117814 | E5: 0.0033026292 | F5: 0.00098875422 | G5: 0.0065727548 | H5: 0.0086690836 | I5: 0.0035118244 | J5: 0.0053734623 | K5: 0.0066677853 | L5: 0.0043754623 | M5: 0.015998666 | N5: 0.00063646561 | O5: 0.00041638444 | P5: 0.00015847185 | Q5: 0.00087296522 | R5: 0.00086879962 | S5: 0.00071709331 | T5: 0.00093793219 | U5: 0.0003690391 | V5: 0.00067334021 | W5: 0.00031526478 | X5: 0.000269168 | Y5: 0.0010083886 | Z5: 0.0014491485 | AA5: 0.00082155556 | AB5: 0.00019019951 | AC5: 0.00053581936 | AD5: 0.00078327155
A6: 796 | B6: 0.00121796 | C6: 0.0012436157 | D6: 0.0013374205 | E6: 0.0046234949 | F6: 0.0025869722 | G6: 0.0083238497 | H6: 0.010950361 | I6: 0.0054200028 | J6: 0.0066643346 | K6: 0.0065316151 | L6: 0.0055666831 | M6: 0.019567605 | N6: 0.0011818098 | O6: 0.00031103668 | P6: 0.00039049838 | Q6: 0.001115667 | R6: 0.0016925112 | S6: 0.0015588651 | T6: 0.0023537649 | U6: 0.00033901269 | V6: 0.00092832078 | W6: 0.00045522412 | X6: 0.0012140232 | Y6: 0.00053559253 | Z6: 0.0032635551 | AA6: 0.00071382598 | AB6: 0.0010736397 | AC6: 0.0017782059 | AD6: 0.00090924596
A7: 795 | B7: 0.0011739256 | C7: 0.0007991782 | D7: 0.0019962378 | E7: 0.004370202 | F7: 0.0011335001 | G7: 0.008277161 | H7: 0.01088814 | I7: 0.0048122282 | J7: 0.0060302499 | K7: 0.0062520688 | L7: 0.0053397566 | M7: 0.017757121 | N7: 0.00058962511 | O7: 0.00044352075 | P7: 0.00034196433 | Q7: 0.0011368063 | R7: 0.0013317792 | S7: 0.0010661339 | T7: 0.0014968429 | U7: 0.00071725823 | V7: 0.0011059741 | W7: 0.00066801949 | X7: 0.00083532001 | Y7: 0.00081757649 | Z7: 0.0030133161 | AA7: 0.00095108872 | AB7: 0.00090970214 | AC7: 0.0015415532 | AD7: 0.0013416457
A8: 794 | B8: 0.0012534858 | C8: 0.00092107702 | D8: 0.0027818899 | E8: 0.0055724274 | F8: 0.0014092111 | G8: 0.007753837 | H8: 0.011215755 | I8: 0.0053866662 | J8: 0.0077449421 | K8: 0.0072891123 | L8: 0.0057499299 | M8: 0.022217716 | N8: 0.00063465185 | O8: 0.00028700058 | P8: 0.00078265978 | Q8: 0.0016076142 | R8: 0.0015946645 | S8: 0.0018392528 | T8: 0.0012166395 | U8: 0.0008872488 | V8: 0.0016026094 | W8: 0.00035278334 | X8: 0.0016748074 | Y8: 0.001070769 | Z8: 0.0026443984 | AA8: 0.00081787068 | AB8: 0.0010158142 | AC8: 0.0015782042 | AD8: 0.0010869186
A9: 793 | B9: 0.0012369241 | C9: 0.00089011849 | D9: 0.0030390323 | E9: 0.0042567352 | F9: 0.0027112458 | G9: 0.0088453105 | H9: 0.011991281 | I9: 0.0065636682 | J9: 0.0083032496 | K9: 0.0068178151 | L9: 0.0056644845 | M9: 0.021526678 | N9: 0.00066215771 | O9: 0.00055170443 | P9: 0.00060870573 | Q9: 0.0017291443 | R9: 0.0014041468 | S9: 0.002002002 | T9: 0.001131208 | U9: 0.00053589577 | V9: 0.0010496935 | W9: 0.00061248769 | X9: 0.0019993845 | Y9: 0.0020415016 | Z9: 0.0032800415 | AA9: 0.0016935984 | AB9: 0.0010985578 | AC9: 0.0012112299 | AD9: 0.0030424788
A10: 792 | B10: 0.001239942 | C10: 0.00056603959 | D10: 0.0028521989 | E10: 0.0045349515 | F10: 0.0020767884 | G10: 0.007318213 | H10: 0.011073038 | I10: 0.0051305038 | J10: 0.0080715667 | K10: 0.0080639544 | L10: 0.0056800523 | M10: 0.018978985 | N10: 0.000629037 | O10: 0.00049785533 | P10: 0.00047504796 | Q10: 0.0022369014 | R10: 0.0011369734 | S10: 0.0025404372 | T10: 0.0012210612 | U10: 0.00094059857 | V10: 0.00094911732 | W10: 0.0009084513 | X10: 0.0016676839 | Y10: 0.0024269464 | Z10: 0.0031149676 | AA10: 0.0013180862 | AB10: 0.0011439947 | AC10: 0.0014410698 | AD10: 0.001513385
A11: 791 | B11: 0.001113952 | C11: 0.00068973333 | D11: 0.0030238604 | E11: 0.0044964566 | F11: 0.0033266621 | G11: 0.0094392939 | H11: 0.013048929 | I11: 0.005894938 | J11: 0.0084261763 | K11: 0.0060354788 | L11: 0.0050310898 | M11: 0.023020264 | N11: 0.00059200476 | O11: 0.00061248217 | P11: 0.00017808123 | Q11: 0.0024186216 | R11: 0.0014767161 | S11: 0.0028275419 | T11: 0.0011655885 | U11: 0.00040848088 | V11: 0.0010753589 | W11: 0.00069681423 | X11: 0.0020237606 | Y11: 0.0012887461 | Z11: 0.0040517422 | AA11: 0.0016749039 | AB11: 0.0015824788 | AC11: 0.0013610041 | AD11: 0.0013650255
A12: 790 | B12: 0.001298374 | C12: 0.00083171586 | D12: 0.0032150126 | E12: 0.0056790239 | F12: 0.0037305243 | G12: 0.0085827655 | H12: 0.013191645 | I12: 0.0063497684 | J12: 0.0087557712 | K12: 0.0082180624 | L12: 0.0059816723 | M12: 0.024988319 | N12: 0.00095156641 | O12: 0.00042921208 | P12: 0.00073683341 | Q12: 0.0022467562 | R12: 0.0015271304 | S12: 0.0020448136 | T12: 0.0011308127 | U12: 0.00083932194 | V12: 0.0011109134 | W12: 0.00157677 | X12: 0.0027133046 | Y12: 0.0028630871 | Z12: 0.0047930247 | AA12: 0.0017679534 | AB12: 0.002815952 | AC12: 0.0017786116 | AD12: 0.0024930845
A13: 789 | B13: 0.0012727939 | C13: 0.0011993006 | D13: 0.0028355757 | E13: 0.00588709 | F13: 0.0028182257 | G13: 0.0095347995 | H13: 0.013876942 | I13: 0.0059564823 | J13: 0.0089555298 | K13: 0.0074185201 | L13: 0.0058495841 | M13: 0.021156007 | N13: 0.000519692 | O13: 0.0004129157 | P13: 0.00014828737 | Q13: 0.0027114654 | R13: 0.0017020439 | S13: 0.003203648 | T13: 0.0014680365 | U13: 0.00054922787 | V13: 0.0013064647 | W13: 0.0011278279 | X13: 0.0022833475 | Y13: 0.0026473359 | Z13: 0.0058225031 | AA13: 0.002090055 | AB13: 0.002249614 | AC13: 0.0019195247 | AD13: 0.0023957476
... A402: 400 | B402: 0.35116553 | C402: 0.25852184 | D402: 0.52847477 | E402: 1.4303263 | F402: 1.1259215 | G402: 2.2864149 | H402: 3.2561091 | I402: 1.4217016 | J402: 2.3922959 | K402: 2.1219549 | L402: 1.869618 | M402: 4.0669055 | N402: 0.21036376 | O402: 0.16981757 | P402: 0.10310944 | Q402: 0.57819384 | R402: 0.70311887 | S402: 0.60870852 | T402: 0.52160584 | U402: 0.45175837 | V402: 0.44482903 | W402: 0.37944775 | X402: 0.49342938 | Y402: 0.99968776 | Z402: 2.4915941 | AA402: 0.48155792 | AB402: 0.46717965 | AC402: 0.75217484 | AD402: 0.73459504

Sheet ad
A1: Wavelength (nm) | B1: E51 | C1: E01 | D1: E02 | E1: E03 | F1: E04 | G1: E06 | H1: E07 | I1: E05 | J1: E08 | K1: E09 | L1: E14 | M1: E21 | N1: E43 | O1: E40 | P1: E36 | Q1: E34 | R1: E11 | S1: E12 | T1: E33 | U1: E24 | V1: E25 | W1: E27 | X1: E28 | Y1: E29 | Z1: E30 | AA1: E31 | AB1: E18 | AC1: E10 | AD1: E13
A2: 800 | B2: 6.3108184e-05 | C2: 0.00033239412 | D2: 0.00058887641 | E2: 0.0022865452 | F2: #NUM! | G2: 0.0047602711 | H2: 0.0073971715 | I2: 0.0016206165 | J2: 0.0051668215 | K2: 0.0029671422 | L2: 0.0025795114 | M2: 0.0098011241 | N2: 0.00014930269 | O2: #NUM! | P2: #NUM! | Q2: 7.4645538e-05 | R2: 0.00043896693 | S2: 0.00071500158 | T2: 3.5368859e-07 | U2: #NUM! | V2: 0.00021522552 | W2: 4.0393301e-05 | X2: #NUM! | Y2: 0.00078039728 | Z2: 0.00035529401 | AA2: #NUM! | AB2: #NUM! | AC2: 0.00043935678 | AD2: #NUM!
A3: 799 | B3: 6.5564524e-05 | C3: 0.00056572356 | D3: 0.00024275764 | E3: 0.0026526417 | F3: 0.00032467496 | G3: 0.0039202676 | H3: 0.0077630142 | I3: 0.0020463417 | J3: 0.0075036859 | K3: 0.0038440603 | L3: 0.002076201 | M3: 0.01231946 | N3: 0.00010719901 | O3: 3.2213643e-05 | P3: #NUM! | Q3: 0.0005988813 | R3: 0.0010392116 | S3: 0.00015944911 | T3: 0.0001092766 | U3: 0.00021682387 | V3: 0.00041111618 | W3: 0.00041844554 | X3: 0.00042411901 | Y3: 0.0004443452 | Z3: #NUM! | AA3: #NUM! | AB3: #NUM! | AC3: #NUM! | AD3: #NUM!
A4: 798 | B4: 0.00042946296 | C4: 0.0011281086 | D4: 0.0012300858 | E4: 0.0037478888 | F4: 0.0013463671 | G4: 0.0069117327 | H4: 0.011043865 | I4: 0.0035706252 | J4: 0.0099455284 | K4: 0.0055155666 | L4: 0.0039247206 | M4: 0.01570901 | N4: 0.00078367746 | O4: 0.00044594674 | P4: 0.00031145645 | Q4: 0.0010368401 | R4: 0.0031934132 | S4: 0.0018500036 | T4: 0.0012418149 | U4: 0.00049507514 | V4: 0.0010254586 | W4: 0.00070962339 | X4: 0.00099116507 | Y4: 0.0029643976 | Z4: 0.0013725289 | AA4: 0.000124292 | AB4: 0.001199064 | AC4: 0.0023159496 | AD4: 0.00187496
A5: 797 | B5: 0.00026662561 | C5: 0.0015949834 | D5: 0.000874573 | E5: 0.004304062 | F5: 0.0017056402 | G5: 0.0061040801 | H5: 0.011605325 | I5: 0.004026349 | J5: 0.009690125 | K5: 0.005579195 | L5: 0.0032320261 | M5: 0.017746431 | N5: 0.00059473239 | O5: 0.0004337323 | P5: 0.00018914185 | Q5: 0.0010376423 | R5: 0.0024493425 | S5: 0.0020335316 | T5: 0.00084704364 | U5: 0.001054266 | V5: 0.00079942832 | W5: 0.00074178637 | X5: 0.0015501374 | Y5: 0.002031348 | Z5: 0.0020452863 | AA5: 0.0002559058 | AB5: 0.0003679206 | AC5: 0.001059291 | AD5: 0.0012656112
A6: 796 | B6: #NUM! | C6: 0.00064166631 | D6: 0.00018878272 | E6: 0.0019543 | F6: 0.00054960491 | G6: 0.0046517931 | H6: 0.0077019278 | I6: 0.0032012432 | J6: 0.0077780443 | K6: 0.0022239975 | L6: 0.0022958608 | M6: 0.014087805 | N6: 0.00034873905 | O6: 4.2173817e-05 | P6: #NUM! | Q6: 0.00046467794 | R6: 0.0013696857 | S6: 0.00084560321 | T6: 7.9252692e-05 | U6: #NUM! | V6: 0.00015098588 | W6: #NUM! | X6: 0.00024331529 | Y6: 0.00070714892 | Z6: 0.00016763512 | AA6: #NUM! | AB6: 7.7329115e-05 | AC6: 8.181073e-05 | AD6: #NUM!
A7: 795 | B7: 0.00048343972 | C7: 0.0018651142 | D7: 0.0012595361 | E7: 0.002638996 | F7: 0.0030303584 | G7: 0.0065201657 | H7: 0.010519601 | I7: 0.0052908799 | J7: 0.0091010661 | K7: 0.0053829365 | L7: 0.0047516011 | M7: 0.017454148 | N7: 0.00070075539 | O7: 0.00039351167 | P7: 0.00014474226 | Q7: 0.00085488147 | R7: 0.0025246908 | S7: 0.001503156 | T7: 0.0008135427 | U7: #NUM! | V7: 0.00027519058 | W7: 0.00020149194 | X7: 0.0011522466 | Y7: 0.0018287564 | Z7: 0.0023911767 | AA7: 0.00036961568 | AB7: 0.0008111782 | AC7: 0.0004959555 | AD7: 0.00062793948
A8: 794 | B8: 0.00062803563 | C8: 0.0013829502 | D8: 0.0015452703 | E8: 0.0047397299 | F8: 0.0019275258 | G8: 0.0057756089 | H8: 0.012206886 | I8: 0.0057796393 | J8: 0.0079346739 | K8: 0.0046948583 | L8: 0.0030009361 | M8: 0.016258785 | N8: 0.00097924592 | O8: 0.00070293838 | P8: 0.00037616456 | Q8: 0.00079053628 | R8: 0.0031842434 | S8: 0.0012238733 | T8: 0.00082951699 | U8: 0.00076592105 | V8: 0.0007466549 | W8: 0.00045476907 | X8: 0.00095500364 | Y8: 0.0016713456 | Z8: 0.0012935782 | AA8: 0.00047120584 | AB8: 0.0010916942 | AC8: 0.0012019559 | AD8: 0.0011479224
A9: 793 | B9: 0.0005598183 | C9: 0.00084173662 | D9: 0.0010505117 | E9: 0.00445961 | F9: 0.0021805767 | G9: 0.0073570136 | H9: 0.012817769 | I9: 0.0063037043 | J9: 0.0071498173 | K9: 0.004696563 | L9: 0.004190726 | M9: 0.016871865 | N9: 0.00099589117 | O9: 0.0007076392 | P9: 0.00016957684 | Q9: 0.0010259213 | R9: 0.0027764702 | S9: 0.0017189853 | T9: 0.00071510398 | U9: 7.8566689e-05 | V9: 0.0010450429 | W9: 0.00077607082 | X9: 0.00049154855 | Y9: 0.001649562 | Z9: 0.0031627178 | AA9: 0.00031914384 | AB9: 0.0013046555 | AC9: 0.001607942 | AD9: 0.0018390661
A10: 792 | B10: 0.001086072 | C10: 0.0011183957 | D10: 0.00189502 | E10: 0.0070829462 | F10: 0.0045489696 | G10: 0.010068449 | H10: 0.014009837 | I10: 0.0064985363 | J10: 0.0095587397 | K10: 0.0068935389 | L10: 0.0063703782 | M10: 0.020758119 | N10: 0.0012878557 | O10: 0.0011676416 | P10: 0.00034980266 | Q10: 0.0016784202 | R10: 0.0029668131 | S10: 0.0025934174 | T10: 0.0012502956 | U10: 0.00092413894 | V10: 0.0014593322 | W10: 0.0014657486 | X10: 0.001905176 | Y10: 0.002806723 | Z10: 0.0053584448 | AA10: 0.0013019003 | AB10: 0.0028277621 | AC10: 0.0029241979 | AD10: 0.001776007
A11: 791 | B11: 0.0012098366 | C11: 0.0013884072 | D11: 0.0019413549 | E11: 0.0071568123 | F11: 0.0025490397 | G11: 0.010618546 | H11: 0.015421303 | I11: 0.0076516938 | J11: 0.0077717935 | K11: 0.0074962821 | L11: 0.0068797634 | M11: 0.021274829 | N11: 0.0016545011 | O11: 0.00099104671 | P11: 0.00054749509 | Q11: 0.0015487184 | R11: 0.003733583 | S11: 0.0025012425 | T11: 0.0017715474 | U11: 0.00092397814 | V11: 0.0013847702 | W11: 0.0010409983 | X11: 0.0029273091 | Y11: 0.0023398118 | Z11: 0.0063230587 | AA11: 0.0016897232 | AB11: 0.0034360787 | AC11: 0.0026800328 | AD11: 0.0019741549
A12: 790 | B12: 0.0011998931 | C12: 0.0013084411 | D12: 0.0022543383 | E12: 0.0056761177 | F12: 0.0023490708 | G12: 0.0080060801 | H12: 0.015335944 | I12: 0.0063254895 | J12: 0.0075939239 | K12: 0.0061287813 | L12: 0.0063210373 | M12: 0.02131114 | N12: 0.00092725297 | O12: 0.0011336315 | P12: 0.00040962482 | Q12: 0.0016706228 | R12: 0.0020597643 | S12: 0.0030311029 | T12: 0.0012062802 | U12: 0.0014834925 | V12: 0.0012780454 | W12: 0.00089200003 | X12: 0.0022879174 | Y12: 0.0016906669 | Z12: 0.0047824924 | AA12: 0.0016782191 | AB12: 0.002854198 | AC12: 0.0032190288 | AD12: 0.0014184394
A13: 789 | B13: 0.00083932606 | C13: 0.00057389056 | D13: 0.0019434719 | E13: 0.0063820985 | F13: 0.0013435596 | G13: 0.0076835881 | H13: 0.013000363 | I13: 0.0059775728 | J13: 0.0074176902 | K13: 0.0051322738 | L13: 0.0044714252 | M13: 0.019958321 | N13: 0.00029347037 | O13: 0.00069171018 | P13: 0.00024128207 | Q13: 0.0012588616 | R13: 0.0018814338 | S13: 0.0020726089 | T13: 0.00045988269 | U13: 0.00036785655 | V13: 0.0006204372 | W13: 0.00046609107 | X13: 0.0019186276 | Y13: 0.00055259636 | Z13: 0.0028937412 | AA13: 0.0011643845 | AB13: 0.0020970878 | AC13: 0.0024717717 | AD13: 0.00076761722
A14: 788 | B14: 0.0012089467 | C14: 0.00086277224 | D14: 0.0023191916 | E14: 0.0066027109 | F14: 0.003333397 | G14: 0.0087663387 | H14: 0.015745027 | I14: 0.006370474 | J14: 0.0079058761 | K14: 0.0069071343 | L14: 0.005241098 | M14: 0.022415701 | N14: 0.00064978819 | O14: 0.00076067133 | P14: 0.00021902142 | Q14: 0.0021014985 | R14: 0.0027356463 | S14: 0.003569648 | T14: 0.00085410091 | U14: 0.0012584128 | V14: 0.00085707402 | W14: 0.00073501002 | X14: 0.0022442205 | Y14: 0.0021164497 | Z14: 0.0044785821 | AA14: 0.0018302601 | AB14: 0.0019322522 | AC14: 0.0044882173 | AD14: 0.0027032507
A15: 787 | B15: 0.00084441019 | C15: 0.0012184274 | D15: 0.0027966323 | E15: 0.0067297338 | F15: 0.0028011116 | G15: 0.011633149 | H15: 0.017402238 | I15: 0.006821566 | J15: 0.010540366 | K15: 0.0097638451 | L15: 0.0066284714 | M15: 0.023858833 | N15: 0.00091721742 | O15: 0.00105769 | P15: 0.00047868889 | Q15: 0.0029441098 | R15: 0.0032380092 | S15: 0.0040014245 | T15: 0.0018040367 | U15: 0.0022206787 | V15: 0.0014894715 | W15: 0.00093029366 | X15: 0.0042126855 | Y15: 0.0025594248 | Z15: 0.0074851093 | AA15: 0.0016862703 | AB15: 0.0021446531 | AC15: 0.0048143644 | AD15: 0.00217279
A16: 786 | B16: 0.0010733817 | C16: 0.001539772 | D16: 0.0032810689 | E16: 0.0082483675 | F16: 0.0022581878 | G16: 0.01126232 | H16: 0.017824914 | I16: 0.0078920298 | J16: 0.0099369903 | K16: 0.0095632579 | L16: 0.0086285501 | M16: 0.023251299 | N16: 0.00090380929 | O16: 0.00077522726 | P16: 0.000461091 | Q16: 0.0031574993 | R16: 0.0034678151 | S16: 0.0039094986 | T16: 0.0020092508 | U16: 0.0017735399 | V16: 0.0014736793 | W16: 0.0015286834 | X16: 0.0037759181 | Y16: 0.0018435316 | Z16: 0.004863832 | AA16: 0.0021812548 | AB16: 0.0026987013 | AC16: 0.0053203445 | AD16: 0.0024122395
A17: 785 | B17: 0.00070695019 | C17: 0.0014322309 | D17: 0.0029811314 | E17: 0.0074084309 | F17: 0.0029303453 | G17: 0.011381383 | H17: 0.016443424 | I17: 0.007313956 | J17: 0.01024532 | K17: 0.0088934771 | L17: 0.0073975485 | M17: 0.02521334 | N17: 0.00069952049 | O17: 0.00070127019 | P17: 0.00075261466 | Q17: 0.0028989381 | R17: 0.0037972308 | S17: 0.0031457937 | T17: 0.0011432904 | U17: 0.0020590259 | V17: 0.0014044082 | W17: 0.0016617313 | X17: 0.003293769 | Y17: 0.0029567895 | Z17: 0.0049051872 | AA17: 0.0017665113 | AB17: 0.0018107163 | AC17: 0.0053353009 | AD17: 0.0015077826
A18: 784 | B18: 0.0010110143 | C18: 0.0011560052 | D18: 0.0033499646 | E18: 0.008772717 | F18: 0.0029724219 | G18: 0.010774562 | H18: 0.019035384 | I18: 0.0083900732 | J18: 0.0086122656 | K18: 0.010976479 | L18: 0.0080339904 | M18: 0.030041084 | N18: 0.00089370004 | O18: 0.00081197403 | P18: 0.00076694801 | Q18: 0.0029910776 | R18: 0.0042152334 | S18: 0.002512411 | T18: 0.0024327455 | U18: 0.0027548762 | V18: 0.0022432763 | W18: 0.0021106611 | X18: 0.0032315179 | Y18: 0.0020816131 | Z18: 0.0035821259 | AA18: 0.0014110599 | AB18: 0.0012865959 | AC18: 0.004950472 | AD18: 0.0023431321
A19: 783 | B19: 0.00069924883 | C19: 0.0015029786 | D19: 0.0034423549 | E19: 0.0078773868 | F19: 0.002989392 | G19: 0.011233852 | H19: 0.019781134 | I19: 0.0073289591 | J19: 0.010872042 | K19: 0.010228992 | L19: 0.0091038058 | M19: 0.028957537 | N19: 0.00092554591 | O19: 0.00077333362 | P19: 0.00070045055 | Q19: 0.0032036473 | R19: 0.0042611936 | S19: 0.0033383046 | T19: 0.0024115693 | U19: 0.0027138148 | V19: 0.001991611 | W19: 0.0018361139 | X19: 0.0021730057 | Y19: 0.0013742866 | Z19: 0.0047272922 | AA19: 0.0010271135 | AB19: 0.0013399516 | AC19: 0.0059697561 | AD19: 0.0020638218
... A402: 400 | B402: 0.12166334 | C402: 0.22534456 | D402: 0.47747651 | E402: 1.3427649 | F402: 0.63969085 | G402: 1.8388129 | H402: 2.946773 | I402: 1.2735624 | J402: 1.7155833 | K402: 1.7423993 | L402: 1.4692221 | M402: 4.2130127 | N402: 0.15392703 | O402: 0.13403911 | P402: 0.083615409 | Q402: 0.42905557 | R402: 0.53511532 | S402: 0.47067319 | T402: 0.34643281 | U402: 0.29718555 | V402: 0.32822789 | W402: 0.26925199 | X402: 0.31805134 | Y402: 0.58054294 | Z402: 1.0711517 | AA402: 0.30403669 | AB402: 0.31546186 | AC402: 0.56378039 | AD402: 0.5000926

Sheet aphy
A1: Wavelength (nm) | B1: E51 | C1: E01 | D1: E02 | E1: E03 | F1: E04 | G1: E06 | H1: E07 | I1: E05 | J1: E08 | K1: E09 | L1: E14 | M1: E21 | N1: E43 | O1: E40 | P1: E36 | Q1: E34 | R1: E11 | S1: E12 | T1: E33 | U1: E24 | V1: E25 | W1: E27 | X1: E28 | Y1: E29 | Z1: E30 | AA1: E31 | AB1: E18 | AC1: E10 | AD1: E13 | AI1: B/R | AK1: Si la razón B/R es >3.0 domina el picofitoplancton (< 2 um) | AQ1: =+B1 -> E51 | AR1: =+C1 -> E01 | AS1: =+D1 -> E02 | AT1: =+E1 -> E03 | AU1: =+F1 -> E04 | AV1: =+G1 -> E06 | AW1: =+H1 -> E07 | AX1: =+I1 -> E05 | ... BS1: =+AD1 -> E13
A2: 800 | B2: 0.0010920705 | C2: 0.00091412911 | D2: 0.00049094451 | E2: 0.0013943879 | F2: #NUM! | G2: 0.00045789857 | H2: -0.00031794297 | I2: 0.0022405198 | J2: -0.00030729638 | K2: 0.0016236235 | L2: 0.0026637087 | M2: 0.0051515413 | N2: 0.00037125712 | O2: #NUM! | P2: #NUM! | Q2: 0.00076504397 | R2: 0.00073423642 | S2: 0.00057064394 | T2: 0.0014057392 | U2: #NUM! | V2: 0.00059398262 | W2: 0.00021084331 | X2: #NUM! | Y2: 0.00049548271 | Z2: 0.00060574294 | AA2: #NUM! | AB2: #NUM! | AC2: 0.0010855089 | AD2: #NUM! | AI2: B= | AJ2: afito(443) | AK2: Si la razón B/R es <2.5 domina el microfitoplancton (> 20 um) | AP2: B/R = | AQ2: =B$359/B$127 -> 2.817726 | AR2: =C$359/C$127 -> 2.7349669 | AS2: =D$359/D$127 -> 2.5018018 | AT2: =E$359/E$127 -> 2.6165916 | AU2: =F$359/F$127 -> 1.8179208 | AV2: =G$359/G$127 -> 2.10072 | AW2: =H$359/H$127 -> 2.4753078 | AX2: =I$359/I$127 -> 2.3956485 | ... BS2: =AD$359/AD$127 -> 1.765687
A3: 799 | B3: 0.0011081954 | C3: 0.00087214363 | D3: 0.0015288302 | E3: 0.0027046258 | F3: 0.0020636196 | G3: 0.001352596 | H3: 0.0026505749 | I3: 0.0022096437 | J3: -0.001747158 | K3: 0.0033463765 | L3: 0.0032627025 | M3: 0.005954728 | N3: 0.001009638 | O3: 0.001020721 | P3: #NUM! | Q3: 0.0006587947 | R3: 0.00086209045 | S3: 0.0014002837 | T3: 0.0020785357 | U3: 0.001269882 | V3: 0.0010144017 | W3: 0.00043788988 | X3: 0.00073717936 | Y3: 0.0011212712 | Z3: #NUM! | AA3: #NUM! | AB3: #NUM! | AC3: #NUM! | AD3: #NUM! | AI3: R= | AJ3: afito(675) | AK3: Valores entre 2.5 y 3 domina el nanoplancton | AP3: [ ] Clorofila a =
A4: 798 | B4: 0.00047339721 | C4: 0.00018929167 | D4: -0.00032246774 | E4: -0.00045444648 | F4: -0.00021806608 | G4: -0.0014162796 | H4: -0.0011799337 | I4: 0.0012638513 | J4: -0.0040322375 | K4: -0.001478111 | L4: 2.4347521e-05 | M4: -0.0019847626 | N4: 7.0687993e-05 | O4: -2.950729e-05 | P4: -0.00019044208 | Q4: -0.00010423803 | R4: -0.0021752534 | S4: -0.0012777164 | T4: 0.00068122149 | U4: -8.8382161e-06 | V4: -0.00025573475 | W4: -0.00028252809 | X4: -0.00041497871 | Y4: -0.0017202615 | Z4: -0.00013262651 | AA4: 0.00081109087 | AB4: -0.00089509206 | AC4: -0.00050014202 | AD4: -0.00047501763
A5: 797 | B5: 0.00071959848 | C5: -0.00083175814 | D5: 0.00023720839 | E5: -0.0010014328 | F5: -0.00071688602 | G5: 0.00046867473 | H5: -0.0029362409 | I5: -0.00051452454 | J5: -0.0043166627 | K5: 0.0010885903 | L5: 0.0011434362 | M5: -0.0017477651 | N5: 4.1733218e-05 | O5: -1.7347857e-05 | P5: -3.0669996e-05 | Q5: -0.00016467708 | R5: -0.0015805429 | S5: -0.0013164383 | T5: 9.0888552e-05 | U5: -0.0006852269 | V5: -0.00012608811 | W5: -0.00042652159 | X5: -0.0012809694 | Y5: -0.0010229594 | Z5: -0.00059613776 | AA5: 0.00056564976 | AB5: -0.00017772109 | AC5: -0.0005234716 | AD5: -0.00048233965
A6: 796 | B6: #NUM! | C6: 0.00060194938 | D6: 0.0011486378 | E6: 0.0026691949 | F6: 0.0020373673 | G6: 0.0036720565 | H6: 0.0032484334 | I6: 0.0022187596 | J6: -0.0011137096 | K6: 0.0043076176 | L6: 0.0032708223 | M6: 0.0054798005 | N6: 0.00083307071 | O6: 0.00026886286 | P6: #NUM! | Q6: 0.00065098906 | R6: 0.00032282549 | S6: 0.00071326191 | T6: 0.0022745122 | U6: #NUM! | V6: 0.00077733491 | W6: #NUM! | X6: 0.00097070796 | Y6: -0.00017155639 | Z6: 0.00309592 | AA6: #NUM! | AB6: 0.00099631057 | AC6: 0.0016963952 | AD6: #NUM!
A7: 795 | B7: 0.00069048586 | C7: -0.001065936 | D7: 0.00073670176 | E7: 0.001731206 | F7: -0.0018968582 | G7: 0.0017569953 | H7: 0.00036853941 | I7: -0.00047865177 | J7: -0.0030708162 | K7: 0.00086913227 | L7: 0.00058815553 | M7: 0.00030297274 | N7: -0.00011113028 | O7: 5.0009082e-05 | P7: 0.00019722207 | Q7: 0.00028192485 | R7: -0.0011929117 | S7: -0.00043702207 | T7: 0.00068330021 | U7: #NUM! | V7: 0.00083078347 | W7: 0.00046652755 | X7: -0.00031692661 | Y7: -0.0010111799 | Z7: 0.00062213941 | AA7: 0.00058147304 | AB7: 9.8523932e-05 | AC7: 0.0010455977 | AD7: 0.00071370618
A8: 794 | B8: 0.00062545012 | C8: -0.00046187318 | D8: 0.0012366196 | E8: 0.00083269753 | F8: -0.00051831464 | G8: 0.0019782282 | H8: -0.00099113142 | I8: -0.00039297311 | J8: -0.00018973183 | K8: 0.0025942541 | L8: 0.0027489938 | M8: 0.0059589304 | N8: -0.00034459407 | O8: -0.0004159378 | P8: 0.00040649522 | Q8: 0.00081707793 | R8: -0.0015895789 | S8: 0.00061537956 | T8: 0.00038712256 | U8: 0.00012132775 | V8: 0.00085595453 | W8: -0.00010198573 | X8: 0.00071980378 | Y8: -0.00060057663 | Z8: 0.0013508202 | AA8: 0.00034666484 | AB8: -7.5880066e-05 | AC8: 0.00037624829 | AD8: -6.1003781e-05
A9: 793 | B9: 0.00067710582 | C9: 4.8381869e-05 | D9: 0.0019885207 | E9: -0.00020287474 | F9: 0.00053066911 | G9: 0.0014882969 | H9: -0.00082648819 | I9: 0.00025996394 | J9: 0.0011534323 | K9: 0.0021212521 | L9: 0.0014737585 | M9: 0.0046548126 | N9: -0.00033373346 | O9: -0.00015593477 | P9: 0.0004391289 | Q9: 0.00070322296 | R9: -0.0013723233 | S9: 0.00028301676 | T9: 0.00041610398 | U9: 0.00045732908 | V9: 4.650569e-06 | W9: -0.00016358312 | X9: 0.0015078359 | Y9: 0.00039193958 | Z9: 0.00011732366 | AA9: 0.0013744546 | AB9: -0.00020609764 | AC9: -0.00039671206 | AD9: 0.0012034127
A10: 792 | B10: 0.00015387005 | C10: -0.00055235614 | D10: 0.0009571789 | E10: -0.0025479947 | F10: -0.0024721812 | G10: -0.0027502358 | H10: -0.0029367984 | I10: -0.0013680325 | J10: -0.001487173 | K10: 0.0011704155 | L10: -0.00069032591 | M10: -0.0017791335 | N10: -0.00065881868 | O10: -0.00066978627 | P10: 0.0001252453 | Q10: 0.00055848126 | R10: -0.0018298397 | S10: -5.2980226e-05 | T10: -2.923442e-05 | U10: 1.6459627e-05 | V10: -0.00051021491 | W10: -0.00055729734 | X10: -0.0002374921 | Y10: -0.0003797766 | Z10: -0.0022434772 | AA10: 1.6185847e-05 | AB10: -0.0016837674 | AC10: -0.0014831281 | AD10: -0.00026262195
A11: 791 | B11: -9.588455e-05 | C11: -0.00069867392 | D11: 0.0010825056 | E11: -0.0026603557 | F11: 0.00077762239 | G11: -0.0011792519 | H11: -0.0023723741 | I11: -0.0017567558 | J11: 0.00065438281 | K11: -0.0014608032 | L11: -0.0018486736 | M11: 0.0017454351 | N11: -0.0010624963 | O11: -0.00037856454 | P11: -0.00036941386 | Q11: 0.00086990318 | R11: -0.0022568669 | S11: 0.00032629944 | T11: -0.00060595894 | U11: -0.00051549725 | V11: -0.00030941126 | W11: -0.0003441841 | X11: -0.00090354844 | Y11: -0.0010510658 | Z11: -0.0022713165 | AA11: -1.4819318e-05 | AB11: -0.0018535999 | AC11: -0.0013190286 | AD11: -0.0006091294
A12: 790 | B12: 9.8480978e-05 | C12: -0.00047672522 | D12: 0.00096067433 | E12: 2.9062228e-06 | F12: 0.0013814535 | G12: 0.00057668543 | H12: -0.0021442986 | I12: 2.4278902e-05 | J12: 0.0011618473 | K12: 0.0020892811 | L12: -0.00033936503 | M12: 0.0036771798 | N12: 2.4313438e-05 | O12: -0.00070441946 | P12: 0.00032720859 | Q12: 0.00057613342 | R12: -0.00053263389 | S12: -0.00098628935 | T12: -7.5467464e-05 | U12: -0.00064417057 | V12: -0.00016713199 | W12: 0.00068477 | X12: 0.0004253872 | Y12: 0.0011724202 | Z12: 1.0532289e-05 | AA12: 8.9734223e-05 | AB12: -3.8246046e-05 | AC12: -0.0014404172 | AD12: 0.0010746452
A13: 789 | B13: 0.00043346784 | C13: 0.00062541 | D13: 0.00089210383 | E13: -0.00049500854 | F13: 0.0014746661 | G13: 0.0018512114 | H13: 0.00087657839 | I13: -2.1090474e-05 | J13: 0.0015378397 | K13: 0.0022862463 | L13: 0.0013781589 | M13: 0.001197686 | N13: 0.00022622163 | O13: -0.00027879448 | P13: -9.2994703e-05 | Q13: 0.0014526038 | R13: -0.00017938993 | S13: 0.0011310392 | T13: 0.0010081538 | U13: 0.00018137131 | V13: 0.00068602748 | W13: 0.0006617368 | X13: 0.00036471997 | Y13: 0.0020947395 | Z13: 0.002928762 | AA13: 0.00092567057 | AB13: 0.00015252623 | AC13: -0.00055224698 | AD13: 0.0016281304
A14: 788 | B14: 8.5081007e-05 | C14: -0.00029197144 | D14: 0.00011818652 | E14: -0.0014399574 | F14: -0.00035469629 | G14: -0.00036339489 | H14: -0.0025832013 | I14: 0.00012096039 | J14: -0.00092926411 | K14: 0.00053462524 | L14: 0.00071812632 | M14: 0.0004090725 | N14: -0.00021266891 | O14: -0.00030774228 | P14: -2.6867339e-05 | Q14: 0.00030674549 | R14: -0.0015492391 | S14: -0.0013480784 | T14: -0.00038081865 | U14: -0.0010736393 | V14: 0.00028115545 | W14: 0.00027195599 | X14: -0.00029181592 | Y14: 0.00026620208 | Z14: 0.00020640687 | AA14: -0.0001028987 | AB14: -0.00021442296 | AC14: -0.0035757779 | AD14: -0.0024652206
A15: 787 | B15: 0.00046538125 | C15: -0.00048115216 | D15: -1.6523878e-05 | E15: 0.0012149148 | F15: 0.002951797 | G15: -0.00360288 | H15: -0.003723468 | I15: -0.00022721463 | J15: -0.0016443376 | K15: -0.0011734718 | L15: -0.00058782061 | M15: -0.00061570502 | N15: -0.00043675871 | O15: -0.00071904645 | P15: -0.00033726695 | Q15: -0.00011449361 | R15: -0.0018891053 | S15: -0.0017413361 | T15: -0.0011980332 | U15: -0.00088034739 | V15: -0.00044144457 | W15: 0.00067725113 | X15: -0.0020307216 | Y15: 0.000824996 | Z15: -0.0013475899 | AA15: 0.0004119297 | AB15: -0.00011347299 | AC15: -0.0036689185 | AD15: -0.00068009648
A16: 786 | B16: 0.00016253675 | C16: -0.00061748499 | D16: -0.0011246662 | E16: -0.0025976302 | F16: 0.0014079143 | G16: -0.0016496058 | H16: -0.0031448593 | I16: -0.00061604044 | J16: -0.0006165259 | K16: -0.001002699 | L16: -0.0029692532 | M16: 0.0045621082 | N16: -0.00016077103 | O16: -0.00025288747 | P16: -0.00024384596 | Q16: -0.00075190842 | R16: -0.0019123073 | S16: -0.0015590403 | T16: -0.00098006219 | U16: -0.00010961368 | V16: -0.00014368736 | W16: -0.00022878623 | X16: -0.0021161992 | Y16: 0.0022448206 | Z16: 0.0018486101 | AA16: -9.7680394e-05 | AB16: -0.0001465994 | AC16: -0.0036442938 | AD16: -0.0012163626
A17: 785 | B17: 0.00090629419 | C17: -9.0577991e-05 | D17: 0.00010078108 | E17: 0.00053458018 | F17: 0.00048347632 | G17: -0.00075860842 | H17: -0.0014120474 | I17: 0.00086392334 | J17: 0.0026923392 | K17: -0.00097502859 | L17: 0.00021501415 | M17: 0.0015168621 | N17: 9.0504361e-05 | O17: -0.0003462138 | P17: -0.00057343441 | Q17: -0.00046545687 | R17: -0.001722857 | S17: -0.0008511987 | T17: -0.00013188307 | U17: -0.00036020518 | V17: -3.2265467e-05 | W17: -4.0112051e-05 | X17: -0.0019270249 | Y17: 0.00052019697 | Z17: 0.0017039733 | AA17: -8.586005e-05 | AB17: -0.00027808578 | AC17: -0.0036406102 | AD17: 0.00035902852
A18: 784 | B18: 0.00037890254 | C18: -0.00046279242 | D18: -0.0015290041 | E18: -0.0011255461 | F18: -0.00022283819 | G18: -0.001187403 | H18: -0.0038174727 | I18: -0.0018469959 | J18: 0.0014463068 | K18: -0.0021161147 | L18: -0.0015790698 | M18: -0.00079524491 | N18: -0.00036821616 | O18: -0.00025950766 | P18: -0.00051100507 | Q18: -0.0014234276 | R18: -0.0029124565 | S18: -0.0011487318 | T18: -0.0016377416 | U18: -0.00059782596 | V18: -0.00053146186 | W18: -0.0012395782 | X18: -0.0022865794 | Y18: 0.0016160328 | Z18: 0.0025465386 | AA18: -0.00021208982 | AB18: 0.00018630809 | AC18: -0.0035649397 | AD18: -0.0012908225
A19: 783 | B19: 0.0012306674 | C19: -0.0006119598 | D19: -0.00095194178 | E19: -0.0010408541 | F19: -0.00083413014 | G19: -0.0021057265 | H19: -0.0041343041 | I19: 0.00018830008 | J19: 1.9765575e-05 | K19: 0.0010540758 | L19: 0.00015616657 | M19: -0.0021287847 | N19: -5.8776692e-05 | O19: -0.00018705218 | P19: -0.0003073966 | Q19: -0.0011454041 | R19: -0.0022716347 | S19: -0.0019367609 | T19: -0.001150563 | U19: -0.0022699845 | V19: -0.00029383046 | W19: -0.0011102419 | X19: 7.5529935e-05 | Y19: 0.00089471815 | Z19: 0.0010713428 | AA19: 0.00014349743 | AB19: -0.00047918956 | AC19: -0.0035801153 | AD19: 4.8861791e-05
... A402: 400 | B402: 0.22950218 | C402: 0.033177274 | D402: 0.050998262 | E402: 0.087561349 | F402: 0.4862307 | G402: 0.44760196 | H402: 0.30933601 | I402: 0.14813919 | J402: 0.67671265 | K402: 0.37955567 | L402: 0.40039591 | M402: -0.14610722 | N402: 0.056436733 | O402: 0.035778462 | P402: 0.019494032 | Q402: 0.14913826 | R402: 0.16800355 | S402: 0.13803533 | T402: 0.17517303 | U402: 0.15457282 | V402: 0.11660115 | W402: 0.11019575 | X402: 0.17537803 | Y402: 0.41914482 | Z402: 1.4204425 | AA402: 0.17752123 | AB402: 0.15171779 | AC402: 0.18839445 | AD402: 0.23450243

Sheet aCDOM
A1: Wavelength (nm) | B1: SC-22-0415 | C1: SC-22-0416 | D1: SC-22-0419 | E1: SC-22-0423 | F1: SC-22-0427 | G1: SC-22-0428 | H1: SC-22-0429 | I1: SC-22-0431 | J1: SC-22-0434 | K1: SC-22-0437 | L1: SC-22-0441 | M1: SC-22-0444 | N1: SC-22-0453 | O1: SC-22-0454 | P1: SC-22-0455 | Q1: SC-22-0456 | R1: SC-22-0459 | S1: SC-22-0463 | T1: SC-22-0464 | U1: SC-22-0465 | V1: SC-22-0466 | W1: SC-22-0468 | X1: SC-22-0469 | Y1: SC-22-0470 | Z1: SC-22-0471 | AA1: SC-22-0473 | AB1: SC-22-0474 | AC1: SC-22-0475 | AD1: SC-22-0479 | AI1: ESPECTROS MODELADOS | AJ1: =+A1 -> Wavelength (nm) | AK1: =+B1 -> SC-22-0415 | AL1: =+C1 -> SC-22-0416 | AM1: =+D1 -> SC-22-0419 | AN1: =+E1 -> SC-22-0423 | AO1: =+F1 -> SC-22-0427 | AP1: =+G1 -> SC-22-0428 | AQ1: =+H1 -> SC-22-0429 | ... BQ1: =+AH1 -> 0
A2: 800 | C2: -0.03845725 | D2: -0.04321072 | E2: -0.038180051 | F2: -0.11275582 | G2: -0.069231611 | H2: -0.067752361 | I2: -0.048597691 | J2: -0.069232386 | L2: -0.055844061 | M2: -0.051831246 | N2: 0.0089969014 | O2: 0.016362526 | Q2: -0.052039038 | S2: -0.032646802 | T2: -0.02550347 | U2: -0.030496391 | V2: -0.036055462 | W2: -0.016080348 | X2: -0.029184782 | Y2: -0.039142911 | Z2: -0.15926831 | AA2: -0.032355449 | AB2: -0.030565454 | AC2: -0.023368757 | AD2: -0.01473219 | AJ2: 800 | AK2: 0 | AL2: 0.00054427119 | AM2: 0.00065750178 | AN2: 0.0012192526 | AO2: 0.0016146703 | AP2: 0.0015484839 | AQ2: 0.0013897897 | AR2: 0.00069766204 | AS2: 0.0015141599 | AT2: 0 | AU2: 0.0013711648 | AV2: 0.0010843697 | AW2: 0.0003064757 | AX2: 0.00026741476 | AY2: 0 | AZ2: 0.0011625476 | BA2: 0 | BB2: 0.00095012619 | BC2: 0.00076613021 | BD2: 0.000811905 | BE2: 0.00080331063 | BF2: 0.0007455629 | BG2: 0.00089547055 | BH2: 0.0012799662 | BI2: 0.0032667425 | BJ2: 0.00074762205 | BK2: 0.00085784229 | BL2: 0.0010046632 | BM2: 0.00080500605
A3: 799 | C3: -0.025728593 | D3: -0.041807483 | E3: -0.026831641 | F3: -0.10466619 | G3: -0.066697618 | H3: -0.059587229 | I3: -0.037572892 | J3: -0.057664343 | L3: -0.048456562 | M3: -0.036786852 | N3: 0.020415664 | O3: 0.022547543 | Q3: -0.033065305 | S3: -0.024832051 | T3: -0.012288879 | U3: -0.01784495 | V3: -0.02315213 | W3: -0.012010995 | X3: -0.018346668 | Y3: -0.034926337 | Z3: -0.14956438 | AA3: -0.012086923 | AB3: -0.016159708 | AC3: -0.015015224 | AD3: -0.0036082142 | AJ3: 799 | AK3: 0 | AL3: 0.00055420111 | AM3: 0.00066966492 | AN3: 0.0012414103 | AO3: 0.0016445237 | AP3: 0.0015765774 | AQ3: 0.0014151315 | AR3: 0.00071115812 | AS3: 0.0015415845 | AT3: 0 | AU3: 0.0013959715 | AV3: 0.0011042197 | AW3: 0.00031198605 | AX3: 0.00027227725 | AY3: 0 | AZ3: 0.0011835327 | BA3: 0 | BB3: 0.00096762519 | BC3: 0.00078021704 | BD3: 0.00082667641 | BE3: 0.00081801566 | BF3: 0.00075918045 | BG3: 0.00091156175 | BH3: 0.0013027321 | BI3: 0.0033225525 | BJ3: 0.00076118587 | BK3: 0.00087329225 | BL3: 0.0010229621 | BM3: 0.00081983229
A4: 798 | C4: -0.028860053 | D4: -0.044547383 | E4: -0.035641251 | F4: -0.10689888 | G4: -0.068211014 | H4: -0.059292786 | I4: -0.040943544 | J4: -0.059457767 | L4: -0.052316579 | M4: -0.036561386 | N4: 0.024797649 | O4: 0.023797384 | Q4: -0.035980907 | S4: -0.025274745 | T4: -0.0067318671 | U4: -0.012236459 | V4: -0.030171062 | W4: -0.011566928 | X4: -0.011854164 | Y4: -0.032542651 | Z4: -0.14455851 | AA4: -0.0062649785 | AB4: -0.012825088 | AC4: -0.01721531 | AD4: 0.0015603258 | AJ4: 798 | AK4: 0 | AL4: 0.00056431219 | AM4: 0.00068205307 | AN4: 0.0012639706 | AO4: 0.001674929 | AP4: 0.0016051806 | AQ4: 0.0014409354 | AR4: 0.00072491528 | AS4: 0.0015695058 | AT4: 0 | AU4: 0.001421227 | AV4: 0.001124433 | AW4: 0.00031759547 | AX4: 0.00027722816 | AY4: 0 | AZ4: 0.0012048967 | BA4: 0 | BB4: 0.00098544647 | BC4: 0.00079456289 | BD4: 0.00084171657 | BE4: 0.00083298987 | BF4: 0.00077304673 | BG4: 0.0009279421 | BH4: 0.0013259029 | BI4: 0.003379316 | BJ4: 0.00077499577 | BK4: 0.00088902047 | BL4: 0.0010415942 | BM4: 0.00083493159
A5: 797 | C5: -0.024126315 | D5: -0.041932743 | E5: -0.030752742 | F5: -0.092903567 | G5: -0.062060654 | H5: -0.051475289 | I5: -0.03163427 | J5: -0.0371175 | L5: -0.046109597 | M5: -0.039463265 | N5: 0.032873556 | O5: 0.03943787 | Q5: -0.036078713 | S5: -0.019204689 | T5: -0.011092234 | U5: -0.0062981824 | V5: -0.013831189 | W5: -0.0057017469 | X5: -0.014703193 | Y5: -0.032563586 | Z5: -0.13664767 | AA5: -0.0066613455 | AB5: -0.010241334 | AC5: 0.0016935617 | AD5: -0.0085959019 | AJ5: 797 | AK5: 0 | AL5: 0.00057460775 | AM5: 0.00069467039 | AN5: 0.001286941 | AO5: 0.0017058965 | AP5: 0.0016343028 | AQ5: 0.0014672097 | AR5: 0.00073893857 | AS5: 0.0015979328 | AT5: 0 | AU5: 0.0014469395 | AV5: 0.0011450163 | AW5: 0.00032330575 | AX5: 0.00028226909 | AY5: 0 | AZ5: 0.0012266462 | BA5: 0 | BB5: 0.001003596 | BC5: 0.00080917251 | BD5: 0.00085703036 | BE5: 0.00084823819 | BF5: 0.00078716627 | BG5: 0.00094461679 | BH5: 0.0013494858 | BI5: 0.0034370492 | BJ5: 0.00078905622 | BK5: 0.00090503197 | BL5: 0.0010605657 | BM5: 0.00085030898
A6: 796 | C6: -0.031007635 | D6: -0.04244304 | E6: -0.038615539 | F6: -0.10675509 | G6: -0.076245055 | H6: -0.054329121 | I6: -0.037633976 | J6: -0.058164688 | L6: -0.061143694 | M6: -0.037186992 | N6: 0.024759214 | O6: 0.02622019 | Q6: -0.034511782 | S6: -0.025093207 | T6: -0.0089806844 | U6: -0.011159924 | V6: -0.014056996 | W6: -0.00041103506 | X6: -0.021762618 | Y6: -0.033266404 | Z6: -0.15821373 | AA6: -0.010671329 | AB6: -0.0092231366 | AC6: -0.010480181 | AD6: -0.0052382891 | AJ6: 796 | AK6: 0 | AL6: 0.00058509114 | AM6: 0.00070752111 | AN6: 0.0013103288 | AO6: 0.0017374366 | AP6: 0.0016639533 | AQ6: 0.0014939632 | AR6: 0.00075323314 | AS6: 0.0016268746 | AT6: 0 | AU6: 0.0014731171 | AV6: 0.0011659764 | AW6: 0.0003291187 | AX6: 0.00028740169 | AY6: 0 | AZ6: 0.0012487884 | BA6: 0 | BB6: 0.0010220798 | BC6: 0.00082405077 | BD6: 0.00087262276 | BE6: 0.00086376564 | BF6: 0.00080154371 | BG6: 0.00096159113 | BH6: 0.0013734882 | BI6: 0.0034957688 | BJ6: 0.00080337176 | BK6: 0.00092133183 | BL6: 0.0010798827 | BM6: 0.00086596959
A7: 795 | C7: -0.021963291 | D7: -0.042900837 | E7: -0.035633704 | F7: -0.096863792 | G7: -0.059750066 | H7: -0.05566098 | I7: -0.028549825 | J7: -0.047502968 | L7: -0.051701613 | M7: -0.035390822 | N7: 0.030110322 | O7: 0.022299773 | Q7: -0.02705599 | S7: -0.022589413 | T7: -0.0080675011 | U7: -0.0059200045 | V7: -0.0088455605 | W7: -0.0019669856 | X7: -0.010702475 | Y7: -0.027720717 | Z7: -0.1518887 | AA7: -0.0098199169 | AB7: -0.0059242089 | AC7: -0.011079365 | AD7: -0.01224933 | AJ7: 795 | AK7: 0 | AL7: 0.00059576579 | AM7: 0.00072060956 | AN7: 0.0013341416 | AO7: 0.0017695597 | AP7: 0.0016941418 | AQ7: 0.0015212045 | AR7: 0.00076780424 | AS7: 0.0016563407 | AT7: 0 | AU7: 0.0014997683 | AV7: 0.0011873203 | AW7: 0.00033503616 | AX7: 0.00029262761 | AY7: 0 | AZ7: 0.0012713303 | BA7: 0 | BB7: 0.001040904 | BC7: 0.00083920258 | BD7: 0.00088849884 | BE7: 0.00087957733 | BF7: 0.00081618374 | BG7: 0.00097887048 | BH7: 0.0013979175 | BI7: 0.0035554915 | BJ7: 0.00081794703 | BK7: 0.00093792526 | BL7: 0.0010995515 | BM7: 0.00088191863
A8: 794 | C8: -0.023879574 | D8: -0.042430689 | E8: -0.033922297 | F8: -0.10176809 | G8: -0.061675272 | H8: -0.048605328 | I8: -0.031615397 | J8: -0.050871218 | L8: -0.06047588 | M8: -0.035462544 | N8: 0.034494022 | O8: 0.030021525 | Q8: -0.028099924 | S8: -0.01850942 | T8: -0.014699676 | U8: -0.006994483 | V8: -0.0077800061 | W8: 0.0056573031 | X8: -0.013072775 | Y8: -0.030134259 | Z8: -0.15211245 | AA8: -0.014106843 | AB8: -0.012300034 | AC8: -0.0056867334 | AD8: -0.0071151074 | AJ8: 794 | AK8: 0 | AL8: 0.0006066352 | AM8: 0.00073394014 | AN8: 0.0013583871 | AO8: 0.0018022769 | AP8: 0.001724878 | AQ8: 0.0015489425 | AR8: 0.0007826572 | AS8: 0.0016863405 | AT8: 0 | AU8: 0.0015269016 | AV8: 0.0012090548 | AW8: 0.00034106002 | AX8: 0.00029794856 | AY8: 0 | AZ8: 0.001294279 | BA8: 0 | BB8: 0.0010600749 | BC8: 0.000854633 | BD8: 0.00090466376 | BE8: 0.00089567845 | BF8: 0.00083109117 | BG8: 0.00099646034 | BH8: 0.0014227814 | BI8: 0.0036162346 | BJ8: 0.00083278672 | BK8: 0.00095481754 | BL8: 0.0011195786 | BM8: 0.00089816141
A9: 793 | C9: -0.029136993 | D9: -0.03760738 | E9: -0.037072973 | F9: -0.099141779 | G9: -0.065380859 | H9: -0.06002306 | I9: -0.035313778 | J9: -0.051196888 | L9: -0.051129541 | M9: -0.032169793 | N9: 0.02796171 | O9: 0.023194428 | Q9: -0.030617789 | S9: -0.025524234 | T9: -0.015603594 | U9: -0.011393625 | V9: -0.018325736 | W9: -0.0028245768 | X9: -0.015351792 | Y9: -0.030396099 | Z9: -0.14875243 | AA9: -0.0047282465 | AB9: -0.0097615757 | AC9: -0.0066050639 | AD9: -0.022752162 | AJ9: 793 | AK9: 0 | AL9: 0.00061770292 | AM9: 0.00074751732 | AN9: 0.0013830733 | AO9: 0.0018355989 | AP9: 0.0017561717 | AQ9: 0.0015771863 | AR9: 0.00079779749 | AS9: 0.0017168836 | AT9: 0 | AU9: 0.0015545259 | AV9: 0.0012311872 | AW9: 0.00034719219 | AX9: 0.00030336626 | AY9: 0 | AZ9: 0.001317642 | BA9: 0 | BB9: 0.0010795988 | BC9: 0.00087034713 | BD9: 0.00092112278 | BE9: 0.00091207432 | BF9: 0.00084627088 | BG9: 0.0010143663 | BH9: 0.0014480874 | BI9: 0.0036780154 | BJ9: 0.00084789565 | BK9: 0.00097201406 | BL9: 0.0011399705 | BM9: 0.00091470334
A10: 792 | C10: -0.026068679 | D10: -0.041043924 | E10: -0.03523768 | F10: -0.10405122 | G10: -0.062211994 | H10: -0.061765354 | I10: -0.038606874 | J10: -0.053821483 | L10: -0.055008092 | M10: -0.040883661 | N10: 0.026458609 | O10: 0.024095258 | Q10: -0.028151744 | S10: -0.026855405 | T10: -0.013934055 | U10: -0.012149638 | V10: -0.014145192 | W10: 0.0026013419 | X10: -0.021347724 | Y10: -0.027271847 | Z10: -0.1486989 | AA10: -0.0068854389 | AB10: -0.013436282 | AC10: -0.0072512603 | AD10: -0.0098038738 | AJ10: 792 | AK10: 0 | AL10: 0.00062897256 | AM10: 0.00076134566 | AN10: 0.0014082081 | AO10: 0.001869537 | AP10: 0.0017880333 | AQ10: 0.0016059452 | AR10: 0.00081323067 | AS10: 0.0017479799 | AT10: 0 | AU10: 0.0015826499 | AV10: 0.0012537247 | AW10: 0.0003534346 | AX10: 0.00030888247 | AY10: 0 | AZ10: 0.0013414268 | BA10: 0 | BB10: 0.0010994824 | BC10: 0.0008863502 | BD10: 0.00093788125 | BE10: 0.00092877033 | BF10: 0.00086172785 | BG10: 0.001032594 | BH10: 0.0014738436 | BI10: 0.0037408517 | BJ10: 0.00086327869 | BK10: 0.00098952029 | BL10: 0.0011607338 | BM10: 0.00093154993
A11: 791 | C11: -0.020794443 | D11: -0.039247752 | E11: -0.038568869 | F11: -0.10815764 | G11: -0.059005379 | H11: -0.058230665 | I11: -0.035045075 | J11: -0.049117601 | L11: -0.057814224 | M11: -0.03279883 | N11: 0.027192658 | O11: 0.026296031 | Q11: -0.035706371 | S11: -0.023695117 | T11: -0.012438162 | U11: -0.0091883922 | V11: -0.014371687 | W11: 0.0048165285 | X11: -0.015813018 | Y11: -0.029322309 | Z11: -0.15517905 | AA11: -0.0088078981 | AB11: -0.0086617067 | AC11: -0.0063586659 | AD11: -0.0085114808 | AJ11: 791 | AK11: 0 | AL11: 0.0006404478 | AM11: 0.00077542981 | AN11: 0.0014337997 | AO11: 0.0019041025 | AP11: 0.0018204729 | AQ11: 0.0016352284 | AR11: 0.0008289624 | AS11: 0.0017796394 | AT11: 0 | AU11: 0.0016112828 | AV11: 0.0012766748 | AW11: 0.00035978926 | AX11: 0.00031449898 | AY11: 0 | AZ11: 0.0013656408 | BA11: 0 | BB11: 0.0011197322 | BC11: 0.00090264752 | BD11: 0.00095494461 | BE11: 0.00094577196 | BF11: 0.00087746713 | BG11: 0.0010511492 | BH11: 0.0015000578 | BI11: 0.0038047615 | BJ11: 0.00087894082 | BK11: 0.0010073418 | BL11: 0.0011818753 | BM11: 0.0009487068
A12: 790 | C12: -0.024552536 | D12: -0.036558642 | E12: -0.029691992 | F12: -0.10150007 | G12: -0.062125514 | H12: -0.05239225 | I12: -0.033539226 | J12: -0.054991018 | L12: -0.052525228 | M12: -0.033331093 | N12: 0.036695826 | O12: 0.029957008 | Q12: -0.023664747 | S12: -0.026303237 | T12: -0.0086728585 | U12: -0.0028499719 | V12: -0.015885426 | W12: 0.0013103239 | X12: -0.0073572152 | Y12: -0.026202515 | Z12: -0.14166487 | AA12: -0.0049365528 | AB12: -0.007472951 | AC12: -0.0087547048 | AD12: -0.0092033182 | AJ12: 790 | AK12: 0 | AL12: 0.00065213241 | AM12: 0.00078977451 | AN12: 0.0014598564 | AO12: 0.0019393072 | AP12: 0.001853501 | AQ12: 0.0016650455 | AR12: 0.00084499845 | AS12: 0.0018118724 | AT12: 0 | AU12: 0.0016404336 | AV12: 0.001300045 | AW12: 0.00036625817 | AX12: 0.00032021763 | AY12: 0 | AZ12: 0.001390292 | BA12: 0 | BB12: 0.0011403549 | BC12: 0.0009192445 | BD12: 0.00097231842 | BE12: 0.00096308481 | BF12: 0.00089349389 | BG12: 0.0010700379 | BH12: 0.0015267383 | BI12: 0.0038697632 | BJ12: 0.00089488711 | BK12: 0.0010254843 | BL12: 0.0012034018 | BM12: 0.00096617965
A13: 789 | C13: -0.01507339 | D13: -0.030495104 | E13: -0.033015972 | F13: -0.10099595 | G13: -0.053719474 | H13: -0.046255959 | I13: -0.025118086 | J13: -0.043161131 | L13: -0.049430487 | M13: -0.025766857 | N13: 0.035532468 | O13: 0.037808138 | Q13: -0.025240943 | S13: -0.01729321 | T13: -0.0025942213 | U13: 0.0021119774 | V13: -0.0089210574 | W13: 0.0079332337 | X13: -0.0095936792 | Y13: -0.029313728 | Z13: -0.13952827 | AA13: -0.0023555439 | AB13: -0.0038308464 | AC13: 0.0017467564 | AD13: -0.010301817 | AJ13: 789 | AK13: 0 | AL13: 0.0006640302 | AM13: 0.00080438457 | AN13: 0.0014863866 | AO13: 0.0019751627 | AP13: 0.0018871284 | AQ13: 0.0016954064 | AR13: 0.00086134472 | AS13: 0.0018446891 | AT13: 0 | AU13: 0.0016701119 | AV13: 0.001323843 | AW13: 0.00037284339 | AX13: 0.00032604025 | AY13: 0 | AZ13: 0.0014153881 | BA13: 0 | BB13: 0.0011613574 | BC13: 0.00093614665 | BD13: 0.00099000831 | BE13: 0.00098071459 | BF13: 0.00090981338 | BG13: 0.001089266 | BH13: 0.0015538934 | BI13: 0.0039358754 | BJ13: 0.0009111227 | BK13: 0.0010439535 | BL13: 0.0012253205 | BM13: 0.00098397432
... A452: 350 | C452: 1.4471352 | D452: 1.9356744 | E452: 3.0331987 | F452: 4.5278617 | G452: 3.7527632 | H452: 3.5303579 | I452: 2.9111985 | J452: 3.6123069 | L452: 3.2588256 | M452: 2.8260459 | N452: 0.74832921 | O452: 0.7190329 | Q452: 2.7585603 | S452: 2.6294945 | T452: 2.1007065 | U452: 2.0599192 | V452: 2.1467878 | W452: 1.9476324 | X452: 2.0579404 | Y452: 2.6807895 | Z452: 4.7815401 | AA452: 1.8504582 | AB452: 2.013465 | AC452: 2.5558086 | AD452: 2.2475064 | AJ452: 350 | AK452: 0 | AL452: 1.8588111 | AM452: 2.5128986 | AN452: 4.0349051 | AO452: 6.1433826 | AP452: 5.0557237 | AQ452: 4.72514 | AR452: 3.8737547 | AS452: 4.8773669 | AT452: 0 | AU452: 4.3771829 | AV452: 3.8047246 | AW452: 0.93111537 | AX452: 0.88895407 | AY452: 0 | AZ452: 3.6450079 | BA452: 0 | BB452: 3.5028757 | BC452: 2.786654 | BD452: 2.7111497 | BE452: 2.8185735 | BF452: 2.5692883 | BG452: 2.7083478 | BH452: 3.5700456 | BI452: 6.6794659 | BJ452: 2.4409493 | BK452: 2.6416658 | BL452: 3.3851463 | BM452: 2.9678543
A453: 349 | C453: 1.3901018 | D453: 1.8837093 | E453: 2.89833 | F453: 4.3360386 | G453: 3.5999681 | H453: 3.3695275 | I453: 2.794949 | J453: 3.4453323 | L453: 3.1147788 | M453: 2.7047882 | N453: 0.72884535 | O453: 0.67955848 | Q453: 2.6338935 | S453: 2.5343496 | T453: 2.0258298 | U453: 1.9780091 | V453: 2.054253 | W453: 1.878824 | X453: 1.9774151 | Y453: 2.5594931 | Z453: 4.58708 | AA453: 1.7889419 | AB453: 1.9452812 | AC453: 2.4624392 | AD453: 2.1474263
A454: 348 | C454: 1.9046054 | D454: 2.5432313 | E454: 4.0933102 | F454: 6.3110876 | G454: 5.1398039 | H454: 4.8030419 | I454: 3.9407242 | J454: 4.9528939 | L454: 4.457139 | M454: 3.8041958 | N454: 0.95706078 | O454: 0.90003071 | Q454: 3.6513275 | S454: 3.5817492 | T454: 2.7797386 | U454: 2.7437355 | V454: 2.8595148 | W454: 2.6037676 | X454: 2.7438618 | Y454: 3.5331814 | Z454: 6.6659838 | AA454: 2.4674129 | AB454: 2.6940984 | AC454: 3.4209812 | AD454: 2.9726967
A455: 347 | C455: 1.9060357 | D455: 2.5951274 | E455: 4.1350009 | F455: 6.3547341 | G455: 5.1899817 | H455: 4.8653316 | I455: 4.0413873 | J455: 5.0112872 | L455: 4.4596149 | M455: 3.8644886 | N455: 0.9731087 | O455: 0.92935413 | Q455: 3.6958419 | S455: 3.6249204 | T455: 2.8435623 | U455: 2.7726402 | V455: 2.9218086 | W455: 2.6106547 | X455: 2.7824564 | Y455: 3.5831865 | Z455: 6.7713452 | AA455: 2.494038 | AB455: 2.6838271 | AC455: 3.4287726 | AD455: 3.0338567
A456: 346 | C456: 1.9352829 | D456: 2.6083 | E456: 4.2311564 | F456: 6.4968529 | G456: 5.2592886 | H456: 4.9465494 | I456: 4.1065271 | J456: 5.0991393 | L456: 4.5941757 | M456: 3.9533942 | N456: 0.97800381 | O456: 0.92785129 | Q456: 3.7435522 | S456: 3.6874617 | T456: 2.9165419 | U456: 2.8630232 | V456: 2.9383203 | W456: 2.6874473 | X456: 2.8252309 | Y456: 3.6841217 | Z456: 6.9011276 | AA456: 2.5266597 | AB456: 2.7689118 | AC456: 3.5445391 | AD456: 3.0721895
A457: 345 | C457: 1.9770407 | D457: 2.6494936 | E457: 4.2908718 | F457: 6.5670746 | G457: 5.3992617 | H457: 5.0641675 | I457: 4.1565413 | J457: 5.1980228 | L457: 4.6838333 | M457: 3.9725928 | N457: 1.0179991 | O457: 0.95524762 | Q457: 3.8165035 | S457: 3.726249 | T457: 2.9384643 | U457: 2.880357 | V457: 2.9941489 | W457: 2.7239199 | X457: 2.8399703 | Y457: 3.7006992 | Z457: 7.0377369 | AA457: 2.5541119 | AB457: 2.8381071 | AC457: 3.5695579 | AD457: 3.1171323
A458: 344 | C458: 1.9877787 | D458: 2.6789078 | E458: 4.3852045 | F458: 6.7238632 | G458: 5.4382463 | H458: 5.0957649 | I458: 4.2567821 | J458: 5.2325352 | L458: 4.7435594 | M458: 4.0511337 | N458: 0.99309196 | O458: 0.96004373 | Q458: 3.8845669 | S458: 3.7975159 | T458: 2.9826099 | U458: 2.9282768 | V458: 3.0249118 | W458: 2.7648568 | X458: 2.8836327 | Y458: 3.7473619 | Z458: 7.1986134 | AA458: 2.6045181 | AB458: 2.8300107 | AC458: 3.630576 | AD458: 3.1611856
A459: 343 | C459: 2.0155031 | D459: 2.7289632 | E459: 4.4398906 | F459: 6.8092531 | G459: 5.5524086 | H459: 5.1783147 | I459: 4.3374543 | J459: 5.3088131 | L459: 4.7896991 | M459: 4.146314 | N459: 1.0655059 | O459: 0.96712014 | Q459: 3.9213284 | S459: 3.8417932 | T459: 3.0370609 | U459: 2.948229 | V459: 3.1247139 | W459: 2.808002 | X459: 2.9782148 | Y459: 3.8452866 | Z459: 7.2977886 | AA459: 2.6355451 | AB459: 2.9022724 | AC459: 3.6879004 | AD459: 3.1956464
A460: 342 | C460: 2.0757517 | D460: 2.799262 | E460: 4.5200498 | F460: 6.9457106 | G460: 5.6608316 | H460: 5.2914021 | I460: 4.4549481 | J460: 5.4623092 | L460: 4.8706346 | M460: 4.2196251 | N460: 1.0464683 | O460: 1.008848 | Q460: 3.9980785 | S460: 3.9717288 | T460: 3.1092273 | U460: 3.0416662 | V460: 3.1758523 | W460: 2.8533637 | X460: 3.0147 | Y460: 3.900693 | Z460: 7.473801 | AA460: 2.7304199 | AB460: 2.9634102 | AC460: 3.7535029 | AD460: 3.2860923
A461: 341 | C461: 2.1422949 | D461: 2.8933089 | E461: 4.6007922 | F461: 7.0384037 | G461: 5.7384326 | H461: 5.3703333 | I461: 4.517838 | J461: 5.5192416 | L461: 4.981509 | M461: 4.2596744 | N461: 1.0815987 | O461: 1.0034212 | Q461: 4.0621653 | S461: 3.9959652 | T461: 3.1483002 | U461: 3.0636285 | V461: 3.2122317 | W461: 2.9225498 | X461: 3.054638 | Y461: 3.9912416 | Z461: 7.5883996 | AA461: 2.7736816 | AB461: 3.0153058 | AC461: 3.8421558 | AD461: 3.33612
A462: 340 | C462: 2.1276737 | D462: 2.8778664 | E462: 4.6707914 | F462: 7.1738853 | G462: 5.8155966 | H462: 5.4646539 | I462: 4.5763107 | J462: 5.619985 | L462: 5.0479392 | M462: 4.3485351 | N462: 1.0994779 | O462: 1.0533539 | Q462: 4.1707194 | S462: 4.0644641 | T462: 3.1906712 | U462: 3.1737296 | V462: 3.2479845 | W462: 2.931556 | X462: 3.1218589 | Y462: 4.0408549 | Z462: 7.7496865 | AA462: 2.7734249 | AB462: 3.031136 | AC462: 3.9027016 | AD462: 3.3989671
A463: 339 | C463: 2.1595045 | D463: 2.9502823 | E463: 4.7160956 | F463: 7.2590566 | G463: 5.8942909 | H463: 5.5286411 | I463: 4.6215379 | J463: 5.6465588 | L463: 5.1020087 | M463: 4.4106788 | N463: 1.1131495 | O463: 1.0182337 | Q463: 4.1872471 | S463: 4.0996388 | T463: 3.2219927 | U463: 3.1370863 | V463: 3.2823559 | W463: 3.0000598 | X463: 3.1415833 | Y463: 4.0662787 | Z463: 7.8649404 | AA463: 2.7899728 | AB463: 3.0342477 | AC463: 3.9514993 | AD463: 3.378385
A464: 338 | C464: 2.2227829 | D464: 2.9951577 | E464: 4.8319647 | F464: 7.3831674 | G464: 6.0237366 | H464: 5.6352054 | I464: 4.6940216 | J464: 5.7940445 | L464: 5.1737917 | M464: 4.4724246 | N464: 1.1123265 | O464: 1.0696219 | Q464: 4.2813662 | S464: 4.2226953 | T464: 3.3267021 | U464: 3.2070882 | V464: 3.3521312 | W464: 3.0421729 | X464: 3.1874518 | Y464: 4.1362734 | Z464: 7.9752899 | AA464: 2.8340256 | AB464: 3.0963442 | AC464: 4.0128261 | AD464: 3.4376863
... A552: 250 | C552: 1.6702508 | D552: 3.0008176 | E552: 1.9087482 | F552: 4.539804 | G552: 2.9099791 | H552: 5.4267032 | I552: 1.1815477 | J552: 4.2486109 | L552: 1.7330026 | M552: 2.1828468 | N552: 0.099411509 | O552: 1.757113 | Q552: -5.6153034 | S552: 2.4349512 | T552: 2.4741754 | U552: 2.261096 | V552: 2.5228089 | W552: 2.9962658 | X552: 3.4730038 | Y552: 2.9955881 | Z552: 5.2387586 | AA552: 1.1550823 | AB552: 1.8620315 | AC552: 3.5208898 | AD552: 3.3065489

Sheet ax(443)
B1: =+aCDOM!B1 -> SC-22-0415 | C1: =+aCDOM!C1 -> SC-22-0416 | D1: =+aCDOM!D1 -> SC-22-0419 | E1: =+aCDOM!E1 -> SC-22-0423 | F1: =+aCDOM!F1 -> SC-22-0427 | G1: =+aCDOM!G1 -> SC-22-0428 | H1: =+aCDOM!H1 -> SC-22-0429 | I1: =+aCDOM!I1 -> SC-22-0431 | ... AH1: =+aCDOM!AH1 -> 0
A2: ap (443) | B2: =+ap!B359 -> 0.2774639 | C2: =+ap!C359 -> 0.18744141 | D2: =+ap!D359 -> 0.36089363 | E2: =+ap!E359 -> 0.89105577 | F2: =+ap!F359 -> 1.0461966 | G2: =+ap!G359 -> 1.5854693 | H2: =+ap!H359 -> 1.9135715 | I2: =+ap!I359 -> 0.95279681 | ... AH2: =+ap!AH359 -> 0
A3: ad (443) | B3: =+ad!B359 -> 0.071144151 | C3: =+ad!C359 -> 0.13015051 | D3: =+ad!D359 -> 0.27324427 | E3: =+ad!E359 -> 0.76300389 | F3: =+ad!F359 -> 0.38247646 | G3: =+ad!G359 -> 1.0785221 | H3: =+ad!H359 -> 1.615231 | I3: =+ad!I359 -> 0.72643888 | ... AH3: =+ad!AH359 -> 0
A4: aphy (443) | B4: =+aphy!B359 -> 0.20631975 | C4: =+aphy!C359 -> 0.057290907 | D4: =+aphy!D359 -> 0.087649361 | E4: =+aphy!E359 -> 0.12805188 | F4: =+aphy!F359 -> 0.66372012 | G4: =+aphy!G359 -> 0.50694724 | H4: =+aphy!H359 -> 0.29834048 | I4: =+aphy!I359 -> 0.22635793 | ... AH4: =+aphy!AH359 -> 0
A5: aCDOM (443) | B5: =+aphy!B359 -> 0.20631975 | C5: =+aphy!C359 -> 0.057290907 | D5: =+aphy!D359 -> 0.087649361 | E5: =+aphy!E359 -> 0.12805188 | F5: =+aphy!F359 -> 0.66372012 | G5: =+aphy!G359 -> 0.50694724 | H5: =+aphy!H359 -> 0.29834048 | I5: =+aphy!I359 -> 0.22635793 | ... AH5: =+aphy!AH359 -> 0
A6: aCDOM (443)-Modelado | B6: =+aphy!AK359 -> 0 | C6: =+aphy!AL359 -> 0 | D6: =+aphy!AM359 -> 0 | E6: =+aphy!AN359 -> 0 | F6: =+aphy!AO359 -> 0 | G6: =+aphy!AP359 -> 0 | H6: =+aphy!AQ359 -> 0 | I6: =+aphy!AR359 -> 0 | ... AH6: =+aphy!BQ359 -> 0
A7: TOTAL-CDOM | B7: =SUM(B3:B5) -> 0.48378364 | C7: =SUM(C3:C5) -> 0.24473232 | D7: =SUM(D3:D5) -> 0.44854299 | E7: =SUM(E3:E5) -> 1.0191077 | F7: =SUM(F3:F5) -> 1.7099167 | G7: =SUM(G3:G5) -> 2.0924165 | H7: =SUM(H3:H5) -> 2.211912 | I7: =SUM(I3:I5) -> 1.1791547 | ... AH7: =SUM(AH3:AH5) -> 0
A8: TOTAL-CDOM Modelado | B8: =SUM(B3:B4,B6) -> 0.2774639 | C8: =SUM(C3:C4,C6) -> 0.18744141 | D8: =SUM(D3:D4,D6) -> 0.36089363 | E8: =SUM(E3:E4,E6) -> 0.89105577 | F8: =SUM(F3:F4,F6) -> 1.0461966 | G8: =SUM(G3:G4,G6) -> 1.5854693 | H8: =SUM(H3:H4,H6) -> 1.9135715 | I8: =SUM(I3:I4,I6) -> 0.95279681 | ... AH8: =SUM(AH3:AH4,AH6) -> 0
B10: =+B1 -> SC-22-0415 | C10: =+C1 -> SC-22-0416 | D10: =+D1 -> SC-22-0419 | E10: =+E1 -> SC-22-0423 | F10: =+F1 -> SC-22-0427 | G10: =+G1 -> SC-22-0428 | H10: =+H1 -> SC-22-0429 | I10: =+I1 -> SC-22-0431 | ... AH10: =+AH1 -> 0
A11: ad (443) | B11: =(B3*100)/B$7 -> 14.705779 | C11: =(C3*100)/C$7 -> 53.18076 | D11: =(D3*100)/D$7 -> 60.91819 | E11: =(E3*100)/E$7 -> 74.869803 | F11: =(F3*100)/F$7 -> 22.368134 | G11: =(G3*100)/G$7 -> 51.544329 | H11: =(H3*100)/H$7 -> 73.024199 | I11: =(I3*100)/I$7 -> 61.606747 | J11: =(J3*100)/J$7 -> 37.979458 | L11: =(L3*100)/L$7 -> 41.613112 | M11: =(M3*100)/M$7 -> 93.807777 | N11: =(N3*100)/N$7 -> 34.519569 | O11: =(O3*100)/O$7 -> 38.26554 | Q11: =(Q3*100)/Q$7 -> 37.906939 | S11: =(S3*100)/S$7 -> 38.723362 | T11: =(T3*100)/T$7 -> 29.727032 | U11: =(U3*100)/U$7 -> 27.452166 | V11: =(V3*100)/V$7 -> 34.309244 | W11: =(W3*100)/W$7 -> 32.383966 | X11: =(X3*100)/X$7 -> 28.490846 | Y11: =(Y3*100)/Y$7 -> 24.863058 | Z11: =(Z3*100)/Z$7 -> 15.795728 | ... AH11: =(AH3*100)/AH$7 -> #DIV/0!
A12: aphy (443) | B12: =(B4*100)/B$7 -> 42.647111 | C12: =(C4*100)/C$7 -> 23.40962 | D12: =(D4*100)/D$7 -> 19.540905 | E12: =(E4*100)/E$7 -> 12.565098 | F12: =(F4*100)/F$7 -> 38.815933 | G12: =(G4*100)/G$7 -> 24.227836 | H12: =(H4*100)/H$7 -> 13.4879 | I12: =(I4*100)/I$7 -> 19.196626 | J12: =(J4*100)/J$7 -> 31.010271 | L12: =(L4*100)/L$7 -> 29.193444 | M12: =(M4*100)/M$7 -> 3.0961116 | N12: =(N4*100)/N$7 -> 32.740215 | O12: =(O4*100)/O$7 -> 30.86723 | Q12: =(Q4*100)/Q$7 -> 31.046531 | S12: =(S4*100)/S$7 -> 30.638319 | T12: =(T4*100)/T$7 -> 35.136484 | U12: =(U4*100)/U$7 -> 36.273917 | V12: =(V4*100)/V$7 -> 32.845378 | W12: =(W4*100)/W$7 -> 33.808017 | X12: =(X4*100)/X$7 -> 35.754577 | Y12: =(Y4*100)/Y$7 -> 37.568471 | Z12: =(Z4*100)/Z$7 -> 42.102136 | ... AH12: =(AH4*100)/AH$7 -> #DIV/0!
A13: aCDOM (443) | B13: =(B5*100)/B$7 -> 42.647111 | C13: =(C5*100)/C$7 -> 23.40962 | D13: =(D5*100)/D$7 -> 19.540905 | E13: =(E5*100)/E$7 -> 12.565098 | F13: =(F5*100)/F$7 -> 38.815933 | G13: =(G5*100)/G$7 -> 24.227836 | H13: =(H5*100)/H$7 -> 13.4879 | I13: =(I5*100)/I$7 -> 19.196626 | J13: =(J5*100)/J$7 -> 31.010271 | L13: =(L5*100)/L$7 -> 29.193444 | M13: =(M5*100)/M$7 -> 3.0961116 | N13: =(N5*100)/N$7 -> 32.740215 | O13: =(O5*100)/O$7 -> 30.86723 | Q13: =(Q5*100)/Q$7 -> 31.046531 | S13: =(S5*100)/S$7 -> 30.638319 | T13: =(T5*100)/T$7 -> 35.136484 | U13: =(U5*100)/U$7 -> 36.273917 | V13: =(V5*100)/V$7 -> 32.845378 | W13: =(W5*100)/W$7 -> 33.808017 | X13: =(X5*100)/X$7 -> 35.754577 | Y13: =(Y5*100)/Y$7 -> 37.568471 | Z13: =(Z5*100)/Z$7 -> 42.102136 | ... AH13: =(AH5*100)/AH$7 -> #DIV/0!
B14: =SUM(B11:B13) -> 100 | C14: =SUM(C11:C13) -> 100 | D14: =SUM(D11:D13) -> 100 | E14: =SUM(E11:E13) -> 100 | F14: =SUM(F11:F13) -> 100 | G14: =SUM(G11:G13) -> 100 | H14: =SUM(H11:H13) -> 100 | I14: =SUM(I11:I13) -> 100 | J14: =SUM(J11:J13) -> 100 | L14: =SUM(L11:L13) -> 100 | M14: =SUM(M11:M13) -> 100 | N14: =SUM(N11:N13) -> 100 | O14: =SUM(O11:O13) -> 100 | Q14: =SUM(Q11:Q13) -> 100 | S14: =SUM(S11:S13) -> 100 | T14: =SUM(T11:T13) -> 100 | U14: =SUM(U11:U13) -> 100 | V14: =SUM(V11:V13) -> 100 | W14: =SUM(W11:W13) -> 100 | X14: =SUM(X11:X13) -> 100 | Y14: =SUM(Y11:Y13) -> 100 | Z14: =SUM(Z11:Z13) -> 100 | ... AH14: =SUM(AH11:AH13) -> #DIV/0!
B15: =+B1 -> SC-22-0415 | C15: =+C1 -> SC-22-0416 | D15: =+D1 -> SC-22-0419 | E15: =+E1 -> SC-22-0423 | F15: =+F1 -> SC-22-0427 | G15: =+G1 -> SC-22-0428 | H15: =+H1 -> SC-22-0429 | I15: =+I1 -> SC-22-0431 | ... AH15: =+AH1 -> 0
A16: ad (443) | B16: =(B3*100)/B$8 -> 25.640868 | C16: =(C3*100)/C$8 -> 69.435299 | D16: =(D3*100)/D$8 -> 75.713243 | E16: =(E3*100)/E$8 -> 85.629196 | F16: =(F3*100)/F$8 -> 36.558757 | G16: =(G3*100)/G$8 -> 68.025414 | H16: =(H3*100)/H$8 -> 84.409232 | I16: =(I3*100)/I$8 -> 76.242791 | ... O16: =(O3*100)/O$8 -> 55.350798 | Q16: =(Q3*100)/Q$8 -> 54.974665 | S16: =(S3*100)/S$8 -> 55.828177 | T16: =(T3*100)/T$8 -> 45.830127 | U16: =(U3*100)/U$8 -> 43.078383 | V16: =(V3*100)/V$8 -> 51.089922 | W16: =(W3*100)/W$8 -> 48.924303 | X16: =(X3*100)/X$8 -> 44.346888 | Y16: =(Y3*100)/Y$8 -> 39.824522 | Z16: =(Z3*100)/Z$8 -> 27.282057 | ... AH16: =(AH3*100)/AH$8 -> #DIV/0!
A17: aphy (443) | B17: =(B4*100)/B$8 -> 74.359132 | C17: =(C4*100)/C$8 -> 30.564701 | D17: =(D4*100)/D$8 -> 24.286757 | E17: =(E4*100)/E$8 -> 14.370804 | F17: =(F4*100)/F$8 -> 63.441243 | G17: =(G4*100)/G$8 -> 31.974586 | H17: =(H4*100)/H$8 -> 15.590768 | I17: =(I4*100)/I$8 -> 23.757209 | ... O17: =(O4*100)/O$8 -> 44.649202 | Q17: =(Q4*100)/Q$8 -> 45.025335 | S17: =(S4*100)/S$8 -> 44.171823 | T17: =(T4*100)/T$8 -> 54.169873 | U17: =(U4*100)/U$8 -> 56.921617 | V17: =(V4*100)/V$8 -> 48.910078 | W17: =(W4*100)/W$8 -> 51.075697 | X17: =(X4*100)/X$8 -> 55.653112 | Y17: =(Y4*100)/Y$8 -> 60.175478 | Z17: =(Z4*100)/Z$8 -> 72.717943 | ... AH17: =(AH4*100)/AH$8 -> #DIV/0!
A18: =+A6 -> aCDOM (443)-Modelado | B18: =(B6*100)/B$8 -> 0 | C18: =(C6*100)/C$8 -> 0 | D18: =(D6*100)/D$8 -> 0 | E18: =(E6*100)/E$8 -> 0 | F18: =(F6*100)/F$8 -> 0 | G18: =(G6*100)/G$8 -> 0 | H18: =(H6*100)/H$8 -> 0 | I18: =(I6*100)/I$8 -> 0 | ... O18: =(O6*100)/O$8 -> 0 | Q18: =(Q6*100)/Q$8 -> 0 | S18: =(S6*100)/S$8 -> 0 | T18: =(T6*100)/T$8 -> 0 | U18: =(U6*100)/U$8 -> 0 | V18: =(V6*100)/V$8 -> 0 | W18: =(W6*100)/W$8 -> 0 | X18: =(X6*100)/X$8 -> 0 | Y18: =(Y6*100)/Y$8 -> 0 | Z18: =(Z6*100)/Z$8 -> 0 | ... AH18: =(AH6*100)/AH$8 -> #DIV/0!
