Workbook

Sheet ap
A1: Wavelength (nm) | B1: SC-21-0101 | C1: SC-21-0104 | D1: SC-21-0109 | E1: SC-21-0113 | F1: SC-21-0115 | G1: SC-21-0119 | H1: SC-21-0124 | I1: SC-21-0128 | J1: SC-21-0132 | K1: SC-21-0136 | L1: SC-21-0140 | M1: SC-21-0148 | N1: SC-21-0152 | O1: SC-21-0154 | P1: SC-21-0156 | Q1: SC-21-0158 | R1: SC-21-0159 | S1: SC-21-0160 | T1: SC-21-0161 | U1: SC-21-0163 | V1: SC-21-0164 | W1: SC-21-0165 | X1: SC-21-0166 | Y1: SC-21-0167 | Z1: SC-21-0168 | AA1: SC-21-0169 | AB1: SC-21-0170 | AC1: SC-21-0171 | AD1: SC-21-0172 | AE1: SC-21-0225 | AF1: SC-21-0228 | AG1: SC-21-0231
A2: 800
A3: 799
A4: 798
A5: 797
A6: 796
A7: 795
A8: 794
A9: 793
A10: 792
A11: 791
A12: 790
A13: 789
... A51: 751
A52: 750 | B52: 0 | C52: 0 | D52: 0 | E52: 0 | F52: 0 | G52: 0 | H52: 0 | I52: 0 | J52: 0 | K52: #NUM! | L52: 0 | U52: 0 | V52: 0 | W52: 0 | X52: 0 | Y52: 0 | Z52: 0 | AA52: 0 | AB52: #NUM! | AC52: 0 | AD52: 0 | AE52: 0 | AF52: 0 | AG52: 0
A53: 749 | B53: 0.0010941469 | C53: 0.0051375177 | D53: 0.0027638585 | E53: 0.1856865 | F53: 0.011752924 | G53: 0.0027361185 | H53: 0.0025229638 | I53: 0.0074435868 | J53: 0.0050570452 | K53: 0.0012596892 | L53: 0.0021208667 | U53: 0.0035648585 | V53: 0.002221651 | W53: 0.0017537181 | X53: 0.0054952386 | Y53: 0.0059535589 | Z53: 0.002289719 | AA53: 0.0082517137 | AB53: #NUM! | AC53: 0.0058914923 | AD53: 0.011883618 | AE53: 0.0084496682 | AF53: 0.011746311 | AG53: 0.053122843
A54: 748 | B54: 0.0012563443 | C54: 0.008214736 | D54: 0.00090993597 | E54: 0.15645192 | F54: 0.011486141 | G54: 0.0029059579 | H54: 0.0022811103 | I54: 0.0072612141 | J54: 0.0041003394 | K54: 0.00094746771 | L54: 0.0014941473 | U54: 0.0039381701 | V54: 0.0037186096 | W54: 0.0020665111 | X54: 0.0073695557 | Y54: 0.0045129198 | Z54: 0.0030283881 | AA54: 0.0060314587 | AB54: 0.00020465281 | AC54: 0.0069021803 | AD54: 0.011365751 | AE54: 0.01693609 | AF54: 0.010654089 | AG54: 0.059293995
A55: 747 | B55: 0.00018547853 | C55: 0.0041021733 | D55: 0.0012691515 | E55: 0.14407491 | F55: 0.01044807 | G55: 0.0025454945 | H55: 0.00068780922 | I55: 0.0058782026 | J55: 0.0023487705 | K55: #NUM! | L55: 0.00077963732 | U55: 0.0031012834 | V55: 0.0048156988 | W55: 0.0016973364 | X55: 0.0070161468 | Y55: 0.0053338025 | Z55: 0.0017796249 | AA55: 0.0043265102 | AB55: #NUM! | AC55: 0.0063371104 | AD55: 0.0054134189 | AE55: 0.0122038 | AF55: 0.0057269244 | AG55: 0.054541435
A56: 746 | B56: #NUM! | C56: 0.0036047916 | D56: 0.00062290459 | E56: 0.24211755 | F56: 0.011592115 | G56: 0.0023072433 | H56: 0.00015374455 | I56: 0.0060089458 | J56: 0.0023656923 | K56: 0.00031529917 | L56: 0.001580584 | U56: 0.0065536079 | V56: 0.0055617003 | W56: 0.00049159626 | X56: 0.0043403495 | Y56: 0.0031558609 | Z56: 0.0005584151 | AA56: 0.0040629618 | AB56: #NUM! | AC56: 0.0074849143 | AD56: 0.0071166157 | AE56: 0.0075324308 | AF56: 0.0044633787 | AG56: 0.056368082
A57: 745 | B57: #NUM! | C57: 0.003784393 | D57: 0.0011843936 | E57: 0.13015429 | F57: 0.010639896 | G57: 0.00076277838 | H57: 0.00067099643 | I57: 0.0038483654 | J57: 0.00066094747 | K57: #NUM! | L57: 0.00046559858 | U57: 0.0049475546 | V57: 0.0040727569 | W57: 0.0013997101 | X57: 0.0018314168 | Y57: 0.0027127326 | Z57: 0.00067808532 | AA57: 0.0040629618 | AB57: #NUM! | AC57: 0.0056073683 | AD57: 0.0071301331 | AE57: 0.009111113 | AF57: 0.0054872579 | AG57: 0.050117724
A58: 744 | B58: #NUM! | C58: 0.0040637109 | D58: 0.00047194185 | E58: 0.10444903 | F58: 0.0030721394 | G58: 0.00065169814 | H58: 0.00091155646 | I58: 0.0042905733 | J58: 0.0015587409 | K58: #NUM! | L58: 0.00011015728 | U58: 0.0045625338 | V58: 0.0025575766 | W58: #NUM! | X58: 0.0023143842 | Y58: 0.002490608 | Z58: 5.7950423e-05 | AA58: 0.0024765314 | AB58: #NUM! | AC58: 0.0029289007 | AD58: 0.007535189 | AE58: 0.0051664525 | AF58: 0.0036230616 | AG58: 0.052130821
A59: 743 | B59: #NUM! | C59: 0.0012016537 | D59: 0.0014985343 | E59: 0.028567726 | F59: 0.0053085813 | G59: 0.00050342066 | H59: #NUM! | I59: 0.0002406272 | J59: 0.00036865396 | K59: #NUM! | L59: 5.7777424e-05 | U59: 0.0026489782 | V59: 0.0039145353 | W59: #NUM! | X59: 0.0022070802 | Y59: 0.0010982036 | Z59: 1.6999845e-07 | AA59: 0.0016063862 | AB59: #NUM! | AC59: 0.0037295297 | AD59: 0.0044218402 | AE59: 0.0043677239 | AF59: 0.0010456161 | AG59: 0.048676653
A60: 742 | B60: #NUM! | C60: 0.001567579 | D60: 0.00084896047 | E60: 0.061254304 | F60: 0.00044315543 | G60: 0.0018464862 | H60: #NUM! | I60: 7.4848613e-05 | J60: #NUM! | K60: #NUM! | L60: 5.8962867e-05 | U60: 0.0011037114 | V60: 0.0014093785 | W60: #NUM! | X60: 0.0018353727 | Y60: 0.001052807 | Z60: #NUM! | AA60: 0.00093252375 | AB60: #NUM! | AC60: 0.00099476225 | AD60: 0.0025752625 | AE60: 0.0028715547 | AF60: 0.00028661394 | AG60: 0.043580632
A61: 741 | B61: #NUM! | C61: 0.0009228042 | D61: 2.5309716e-06 | E61: 0.022573885 | F61: 0.0017787315 | G61: 0.0014830384 | H61: #NUM! | I61: 0.00030631453 | J61: 0.00022038625 | K61: #NUM! | L61: 0.00017152696 | U61: 0.0027935175 | V61: 0.0035730247 | W61: #NUM! | X61: 0.0025228625 | Y61: 0.0010479923 | Z61: #NUM! | AA61: 0.00071609522 | AB61: #NUM! | AC61: 0.0016451803 | AD61: 0.0031791844 | AE61: 0.002579317 | AF61: #NUM! | AG61: 0.053210204
A62: 740 | B62: #NUM! | C62: 0.00016824069 | D62: 0.00041827792 | E62: 0.010208644 | F62: 0.0026928359 | G62: 0.0017055621 | H62: #NUM! | I62: 0.00031176306 | J62: #NUM! | K62: #NUM! | L62: 0.00029481686 | U62: 0.0014958387 | V62: 0.0012024734 | W62: #NUM! | X62: 0.002004327 | Y62: #NUM! | Z62: #NUM! | AA62: 0.00030309796 | AB62: #NUM! | AC62: 0.0014101 | AD62: 0.0010964971 | AE62: 0.0039603772 | AF62: 0.00085290275 | AG62: 0.046019405
A63: 739 | B63: #NUM! | C63: #NUM! | D63: #NUM! | E63: #NUM! | F63: 0.0055629897 | G63: 0.00015739535 | H63: #NUM! | I63: #NUM! | J63: #NUM! | K63: #NUM! | L63: 6.3740742e-05 | U63: 0.0016024568 | V63: 0.0010856428 | W63: #NUM! | X63: 0.00043670166 | Y63: #NUM! | Z63: #NUM! | AA63: 0.0001730515 | AB63: #NUM! | AC63: 0.00015132957 | AD63: 0.00019983332 | AE63: 0.0027158793 | AF63: 8.164186e-05 | AG63: 0.038050009
A64: 738 | B64: #NUM! | C64: #NUM! | D64: 0.00071525825 | E64: #NUM! | F64: 0.004185611 | G64: #NUM! | H64: #NUM! | I64: #NUM! | J64: #NUM! | K64: #NUM! | L64: 4.6093967e-05 | U64: 0.0011730421 | V64: 0.0005381231 | W64: #NUM! | X64: #NUM! | Y64: #NUM! | Z64: #NUM! | AA64: #NUM! | AB64: #NUM! | AC64: #NUM! | AD64: 0.00057905266 | AE64: 0.0022669792 | AF64: #NUM! | AG64: 0.040875566
A65: 737 | B65: #NUM! | C65: #NUM! | D65: #NUM! | E65: #NUM! | F65: 0.00041583701 | G65: #NUM! | H65: #NUM! | I65: #NUM! | J65: #NUM! | K65: #NUM! | L65: #NUM! | U65: 0.00023135934 | V65: #NUM! | W65: #NUM! | X65: 1.602894e-05 | Y65: #NUM! | Z65: #NUM! | AA65: #NUM! | AB65: #NUM! | AC65: #NUM! | AD65: #NUM! | AE65: 0.00026258389 | AF65: #NUM! | AG65: 0.038811192
A66: 736 | B66: #NUM! | C66: #NUM! | D66: #NUM! | E66: #NUM! | F66: 0.0045508572 | G66: #NUM! | H66: #NUM! | I66: #NUM! | J66: #NUM! | K66: #NUM! | L66: #NUM! | U66: #NUM! | V66: #NUM! | W66: #NUM! | X66: #NUM! | Y66: #NUM! | Z66: #NUM! | AA66: #NUM! | AB66: #NUM! | AC66: #NUM! | AD66: #NUM! | AE66: #NUM! | AF66: #NUM! | AG66: 0.03031691
A67: 735 | B67: #NUM! | C67: 0.0010103596 | D67: 0.0017753624 | E67: 0.037855447 | F67: 0.011617224 | G67: #NUM! | H67: #NUM! | I67: 0.0015034529 | J67: #NUM! | K67: #NUM! | L67: 0.00058323372 | U67: 0.00037891431 | V67: #NUM! | W67: 5.6414827e-05 | X67: 0.0046157878 | Y67: #NUM! | Z67: #NUM! | AA67: 0.002715329 | AB67: #NUM! | AC67: 0.0021421223 | AD67: 0.0010662892 | AE67: 0.0089860075 | AF67: #NUM! | AG67: 0.045903659
A68: 734 | B68: #NUM! | C68: 9.863484e-05 | D68: 0.0021753623 | E68: 0.020639488 | F68: 0.011763252 | G68: #NUM! | H68: #NUM! | I68: #NUM! | J68: #NUM! | K68: #NUM! | L68: 0.00066737185 | U68: 0.00033912938 | V68: 4.6330061e-05 | W68: #NUM! | X68: 0.0010654837 | Y68: 0.0012152351 | Z68: #NUM! | AA68: 0.0033860437 | AB68: #NUM! | AC68: 0.0033106963 | AD68: 0.0018387264 | AE68: 0.0044234707 | AF68: 0.00093713517 | AG68: 0.035536485
A69: 733 | B69: #NUM! | C69: 0.00044262038 | D69: 0.002662129 | E69: 0.071920061 | F69: 0.0027255668 | G69: #NUM! | H69: #NUM! | I69: 7.4224383e-05 | J69: #NUM! | K69: #NUM! | L69: 0.0016098112 | U69: 0.00090531922 | V69: 0.00098564917 | W69: #NUM! | X69: 0.001325279 | Y69: 0.001176182 | Z69: #NUM! | AA69: 0.0010003098 | AB69: #NUM! | AC69: 0.0011220875 | AD69: 0.0030973305 | AE69: 0.012557598 | AF69: #NUM! | AG69: 0.043968751
A70: 732 | B70: #NUM! | C70: #NUM! | D70: 0.00076912851 | E70: 0.0013682329 | F70: 0.0042119135 | G70: #NUM! | H70: #NUM! | I70: #NUM! | J70: #NUM! | K70: #NUM! | L70: 0.00032156604 | U70: 0.0058474119 | V70: 0.00095986414 | W70: #NUM! | X70: 0.00073889553 | Y70: 3.1393669e-05 | Z70: #NUM! | AA70: 0.0014415836 | AB70: #NUM! | AC70: #NUM! | AD70: 0.00011560559 | AE70: 0.0036106273 | AF70: #NUM! | AG70: 0.04742685
A71: 731 | B71: #NUM! | C71: #NUM! | D71: 0.0011502664 | E71: #NUM! | F71: 0.01122404 | G71: #NUM! | H71: #NUM! | I71: #NUM! | J71: #NUM! | K71: #NUM! | L71: #NUM! | U71: 0.0018246331 | V71: #NUM! | W71: #NUM! | X71: #NUM! | Y71: #NUM! | Z71: #NUM! | AA71: 3.9380695e-05 | AB71: #NUM! | AC71: #NUM! | AD71: #NUM! | AE71: 0.0028791318 | AF71: 2.096117e-05 | AG71: 0.040576247
A72: 730 | B72: #NUM! | C72: #NUM! | D72: #NUM! | E72: #NUM! | F72: 0.0055074964 | G72: #NUM! | H72: #NUM! | I72: #NUM! | J72: #NUM! | K72: #NUM! | L72: #NUM! | U72: #NUM! | V72: #NUM! | W72: #NUM! | X72: #NUM! | Y72: #NUM! | Z72: #NUM! | AA72: #NUM! | AB72: #NUM! | AC72: #NUM! | AD72: #NUM! | AE72: 0.0030617387 | AF72: #NUM! | AG72: 0.028587355
A73: 729 | B73: #NUM! | C73: #NUM! | D73: #NUM! | E73: #NUM! | F73: #NUM! | G73: #NUM! | H73: #NUM! | I73: #NUM! | J73: #NUM! | K73: #NUM! | L73: #NUM! | U73: #NUM! | V73: #NUM! | W73: #NUM! | X73: #NUM! | Y73: #NUM! | Z73: #NUM! | AA73: #NUM! | AB73: #NUM! | AC73: #NUM! | AD73: #NUM! | AE73: #NUM! | AF73: #NUM! | AG73: 0.032833018
A74: 728 | B74: #NUM! | C74: #NUM! | D74: 0.00095638631 | E74: #NUM! | F74: #NUM! | G74: #NUM! | H74: #NUM! | I74: #NUM! | J74: #NUM! | K74: #NUM! | L74: #NUM! | U74: #NUM! | V74: #NUM! | W74: #NUM! | X74: #NUM! | Y74: #NUM! | Z74: #NUM! | AA74: #NUM! | AB74: #NUM! | AC74: #NUM! | AD74: #NUM! | AE74: 7.5842018e-06 | AF74: #NUM! | AG74: 0.032026439
A75: 727 | B75: #NUM! | C75: #NUM! | D75: #NUM! | E75: #NUM! | F75: #NUM! | G75: #NUM! | H75: #NUM! | I75: #NUM! | J75: #NUM! | K75: #NUM! | L75: #NUM! | U75: #NUM! | V75: #NUM! | W75: #NUM! | X75: #NUM! | Y75: #NUM! | Z75: #NUM! | AA75: #NUM! | AB75: #NUM! | AC75: #NUM! | AD75: #NUM! | AE75: #NUM! | AF75: #NUM! | AG75: 0.027461744
A76: 726 | B76: #NUM! | C76: #NUM! | D76: #NUM! | E76: #NUM! | F76: #NUM! | G76: #NUM! | H76: #NUM! | I76: #NUM! | J76: #NUM! | K76: #NUM! | L76: #NUM! | U76: #NUM! | V76: #NUM! | W76: #NUM! | X76: #NUM! | Y76: #NUM! | Z76: #NUM! | AA76: #NUM! | AB76: #NUM! | AC76: #NUM! | AD76: #NUM! | AE76: #NUM! | AF76: #NUM! | AG76: 0.024469755
A77: 725 | B77: #NUM! | C77: #NUM! | D77: #NUM! | E77: #NUM! | F77: #NUM! | G77: #NUM! | H77: #NUM! | I77: #NUM! | J77: #NUM! | K77: #NUM! | L77: #NUM! | U77: #NUM! | V77: #NUM! | W77: #NUM! | X77: #NUM! | Y77: #NUM! | Z77: #NUM! | AA77: #NUM! | AB77: #NUM! | AC77: #NUM! | AD77: #NUM! | AE77: #NUM! | AF77: #NUM! | AG77: 0.021157338
...

Sheet ad
A1: Wavelength (nm) | B1: =+ap!B1 -> SC-21-0101 | C1: =+ap!C1 -> SC-21-0104 | D1: =+ap!D1 -> SC-21-0109 | E1: =+ap!E1 -> SC-21-0113 | F1: =+ap!F1 -> SC-21-0115 | G1: =+ap!G1 -> SC-21-0119 | H1: =+ap!H1 -> SC-21-0124 | I1: =+ap!I1 -> SC-21-0128 | ... AG1: =+ap!AG1 -> SC-21-0231
A2: 800
A3: 799
A4: 798
A5: 797
A6: 796
A7: 795
A8: 794
A9: 793
A10: 792
A11: 791
A12: 790
A13: 789
... A51: 751
A52: 750 | B52: 0 | C52: 0 | D52: 0 | E52: 0 | F52: 0 | G52: 0 | H52: 0 | I52: 0 | J52: 0 | K52: 0 | L52: 0 | U52: 0 | V52: 0 | W52: 0 | X52: 0 | Y52: 0 | Z52: 0 | AA52: 0 | AB52: 0 | AC52: 0 | AD52: 0 | AE52: 0 | AF52: 0 | AG52: 0
A53: 749 | B53: 4.5826954e-06 | C53: 8.9022332e-06 | D53: 3.1947855e-10 | E53: 0.00014709147 | F53: 2.5104702e-11 | G53: 2.5721166e-05 | H53: 1.9479609e-05 | I53: 1.187999e-05 | J53: 8.3892215e-06 | K53: 3.9389098e-06 | L53: 2.0496587e-08 | U53: 1.0471049e-09 | V53: 2.548978e-05 | W53: 4.6800147e-10 | X53: 1.3136528e-05 | Y53: 2.4886353e-05 | Z53: 7.6759374e-05 | AA53: 2.1113439e-05 | AB53: 3.8346011e-09 | AC53: 1.3537473e-05 | AD53: 6.7411531e-05 | AE53: 1.3462389e-09 | AF53: 3.0540445e-05 | AG53: 8.7104272e-06
A54: 748 | B54: 1.1239909e-05 | C54: 2.1743603e-05 | D54: 7.9905283e-10 | E54: 0.00035965743 | F54: 6.3200682e-11 | G54: 6.2847937e-05 | H54: 4.7575236e-05 | I54: 2.9044168e-05 | J54: 2.0507202e-05 | K54: 9.6710719e-06 | L54: 5.0916381e-08 | U54: 2.61477e-09 | V54: 6.2312736e-05 | W54: 1.1698365e-09 | X54: 3.2079693e-05 | Y54: 6.081861e-05 | Z54: 0.00018739786 | AA54: 5.1635023e-05 | AB54: 9.5166335e-09 | AC54: 3.3038398e-05 | AD54: 0.00016469446 | AE54: 3.3664821e-09 | AF54: 7.4673369e-05 | AG54: 2.1284095e-05
A55: 747 | B55: 1.9074076e-05 | C55: 3.6744801e-05 | D55: 1.3830317e-09 | E55: 0.00060844865 | F55: 1.1011778e-10 | G55: 0.00010624873 | H55: 8.0392111e-05 | I55: 4.9128664e-05 | J55: 3.4683596e-05 | K55: 1.6429129e-05 | L55: 8.7522113e-08 | U55: 4.5184532e-09 | V55: 0.00010539514 | W55: 2.0235889e-09 | X55: 5.4201518e-05 | Y55: 0.0001028358 | Z55: 0.0003165404 | AA55: 8.7370215e-05 | AB55: 1.6342789e-08 | AC55: 5.5786779e-05 | AD55: 0.00027839151 | AE55: 5.8257546e-09 | AF55: 0.00012632503 | AG55: 3.5983495e-05
A56: 746 | B56: 2.7838066e-05 | C56: 5.3403292e-05 | D56: 2.0591476e-09 | E56: 0.00088525424 | F56: 1.650585e-10 | G56: 0.00015447732 | H56: 0.00011682978 | I56: 7.1469371e-05 | J56: 5.0448774e-05 | K56: 2.400334e-05 | L56: 1.2940117e-07 | U56: 6.7163744e-09 | V56: 0.00015331098 | W56: 3.0110249e-09 | X56: 7.8758999e-05 | Y56: 0.00014954111 | Z56: 0.00045983376 | AA56: 0.00012714284 | AB56: 2.4139295e-08 | AC56: 8.1012195e-05 | AD56: 0.00040470729 | AE56: 8.6721261e-09 | AF56: 0.00018379016 | AG56: 5.231904e-05
A57: 745 | B57: 3.7407368e-05 | C57: 7.1458781e-05 | D57: 2.8232487e-09 | E57: 0.001185848 | F57: 2.2786134e-10 | G57: 0.00020678623 | H57: 0.00015631801 | I57: 9.5724185e-05 | J57: 6.7560622e-05 | K57: 3.2288937e-05 | L57: 1.7616776e-07 | U57: 9.1934067e-09 | V57: 0.00020532532 | W57: 4.1258081e-09 | X57: 0.00010536688 | Y57: 0.00020021337 | Z57: 0.00061501747 | AA57: 0.00017034823 | AB57: 3.2831158e-08 | AC57: 0.00010831386 | AD57: 0.00054167881 | AE57: 1.1887873e-08 | AF57: 0.00024619088 | AG57: 7.0037747e-05
A58: 744 | B58: 4.7707409e-05 | C58: 9.0750011e-05 | D58: 3.6745581e-09 | E58: 0.0015076307 | F58: 2.9863698e-10 | G58: 0.00026271358 | H58: 0.00019850338 | I58: 0.00012168251 | J58: 8.5869958e-05 | K58: 4.1223875e-05 | L58: 2.2765151e-07 | U58: 1.194545e-08 | V58: 0.00026098554 | W58: 5.3665392e-09 | X58: 0.00013378621 | Y58: 0.00025440741 | Z58: 0.00078068713 | AA58: 0.00021661504 | AB58: 4.2383723e-08 | AC58: 0.00013744224 | AD58: 0.00068809198 | AE58: 1.5469485e-08 | AF58: 0.00031298721 | AG58: 8.8983323e-05
A59: 743 | B59: 5.8689446e-05 | C59: 0.00011116708 | D59: 4.6141341e-09 | E59: 0.0018488464 | F59: 3.7765165e-10 | G59: 0.00032194549 | H59: 0.00024314488 | I59: 0.0001492019 | J59: 0.00010527575 | K59: 5.0768202e-05 | L59: 2.8379542e-07 | U59: 1.4974345e-08 | V59: 0.00031998526 | W59: 6.7344944e-09 | X59: 0.0001638539 | Y59: 0.00031182117 | Z59: 0.00095588239 | AA59: 0.00026569278 | AB59: 5.2783498e-08 | AC59: 0.00016822631 | AD59: 0.00084312097 | AE59: 1.9421177e-08 | AF59: 0.00038381424 | AG59: 0.00010904959
A60: 742 | B60: 7.0320009e-05 | C60: 0.00013263047 | D60: 5.6442146e-09 | E60: 0.0022082376 | F60: 4.6527852e-10 | G60: 0.00038425568 | H60: 0.00029006805 | I60: 0.0001781802 | J60: 0.00012570547 | K60: 6.0895032e-05 | L60: 3.446118e-07 | U60: 1.8285699e-08 | V60: 0.00038210462 | W60: 8.2326606e-09 | X60: 0.00019545176 | Y60: 0.00037223722 | Z60: 0.0011399059 | AA60: 0.00031740247 | AB60: 6.4029863e-08 | AC60: 0.00020054154 | AD60: 0.0010061698 | AE60: 2.3752114e-08 | AF60: 0.00045841059 | AG60: 0.00013016003
A61: 741 | B61: 8.2575485e-05 | C61: 0.00015508032 | D61: 6.7678928e-09 | E61: 0.0025848685 | F61: 5.6197461e-10 | G61: 0.0004494744 | H61: 0.00033914138 | I61: 0.00020854128 | J61: 0.00014710495 | K61: 7.1585925e-05 | L61: 4.1016004e-07 | U61: 2.1887804e-08 | V61: 0.00044717961 | W61: 9.8652568e-09 | X61: 0.00022849063 | Y61: 0.00043549276 | Z61: 0.00133223 | AA61: 0.00037161122 | AB61: 7.6130882e-08 | AC61: 0.00023429339 | AD61: 0.0011767906 | AE61: 2.847505e-08 | AF61: 0.00053658169 | AG61: 0.00015225725
A62: 740 | B62: 9.5439036e-05 | C62: 0.00017847018 | D62: 7.9889428e-09 | E62: 0.002978024 | F62: 6.6826931e-10 | G62: 0.00051747068 | H62: 0.00039026285 | I62: 0.00024022683 | J62: 0.00016943266 | K62: 8.2828256e-05 | L62: 4.8053424e-07 | U62: 2.5791046e-08 | V62: 0.00051508449 | W62: 1.1637476e-08 | X62: 0.00026290122 | Y62: 0.00050146247 | Z62: 0.0015324436 | AA62: 0.00042821781 | AB62: 8.910096e-08 | AC62: 0.00026940797 | AD62: 0.0013546373 | AE62: 3.3605585e-08 | AF62: 0.0006181788 | AG62: 0.00017529701
A63: 739 | B63: 0.00010889872 | C63: 0.00020276331 | D63: 9.3117212e-09 | E63: 0.0033871476 | F63: 7.8475873e-10 | G63: 0.00058814139 | H63: 0.00044335159 | I63: 0.00027319137 | J63: 0.00019265609 | K63: 9.4613604e-05 | L63: 5.5585583e-07 | U63: 3.0007569e-08 | V63: 0.00058572107 | W63: 1.3555338e-08 | X63: 0.00029862852 | Y63: 0.00057004794 | Z63: 0.0017402192 | AA63: 0.00048714371 | AB63: 1.0295944e-07 | AC63: 0.00030582616 | AD63: 0.0015394371 | AE63: 3.9161749e-08 | AF63: 0.0007030861 | AG63: 0.00019924448
... A402: 400 | B402: 0.82837148 | C402: 0.1722586 | D402: 10.039772 | E402: 4.9433262 | F402: 52.260617 | G402: 0.60483169 | H402: 0.36337601 | I402: 0.37215519 | J402: 0.24521241 | K402: 1.298271 | L402: 8.4724618 | U402: 11.906339 | V402: 0.7684599 | W402: 10.088244 | X402: 0.23111492 | Y402: 0.63897426 | Z402: 1.183112 | AA402: 0.78495985 | AB402: 0.87134765 | AC402: 0.17601055 | AD402: 1.4855839 | AE402: 37.622443 | AF402: 1.0127023 | AG402: 0.20854387

Sheet aphy
A1: Wavelength (nm) | B1: =+ap!B1 -> SC-21-0101 | C1: =+ap!C1 -> SC-21-0104 | D1: =+ap!D1 -> SC-21-0109 | E1: =+ap!E1 -> SC-21-0113 | F1: =+ap!F1 -> SC-21-0115 | G1: =+ap!G1 -> SC-21-0119 | H1: =+ap!H1 -> SC-21-0124 | I1: =+ap!I1 -> SC-21-0128 | ... AG1: =+ap!AG1 -> SC-21-0231 | AI1: B/R | AK1: Si la razón B/R es >3.0 domina el picofitoplancton (< 2 um) | AQ1: =+B1 -> SC-21-0101 | AR1: =+C1 -> SC-21-0104 | AS1: =+D1 -> SC-21-0109 | AT1: =+E1 -> SC-21-0113 | AU1: =+F1 -> SC-21-0115 | AV1: =+G1 -> SC-21-0119 | AW1: =+H1 -> SC-21-0124 | AX1: =+I1 -> SC-21-0128 | ... BV1: =+AG1 -> SC-21-0231
A2: 800 | AI2: B= | AJ2: afito(443) | AK2: Si la razón B/R es <2.5 domina el microfitoplancton (> 20 um) | AP2: B/R = | AQ2: =B$359/B$127 -> 1.9519775 | AR2: =C$359/C$127 -> 2.2014279 | AS2: =D$359/D$127 -> 3.0722802 | AT2: =E$359/E$127 -> 7.8643718 | AU2: =F$359/F$127 -> 4.2821312 | AV2: =G$359/G$127 -> 3.2566001 | AW2: =H$359/H$127 -> 1.6918457 | AX2: =I$359/I$127 -> 1.9483405 | ... BA2: =L$359/L$127 -> 1.3762803 | BJ2: =U$359/U$127 -> 0.91253619 | BK2: =V$359/V$127 -> 2.2614735 | BL2: =W$359/W$127 -> 1.0734607 | BM2: =X$359/X$127 -> 4.1807015 | BN2: =Y$359/Y$127 -> 1.9085866 | BO2: =Z$359/Z$127 -> 1.2020199 | BP2: =AA$359/AA$127 -> 2.6039908 | BQ2: =AB$359/AB$127 -> 1.8301599 | ... BV2: =AG$359/AG$127 -> 9.2424693
A3: 799 | AI3: R= | AJ3: afito(675) | AK3: Valores entre 2.5 y 3 domina el nanoplancton | AP3: [ ] Clorofila a = | AQ3: 2.3361 | AS3: 2.1261 | AT3: 0.3827 | AU3: 3.0243 | AV3: 5.5122 | AW3: 4.9193 | AX3: 3.3152 | AY3: 2.803 | AZ3: 3.5209 | BA3: 16.373 | BB3: 2.651 | BC3: 4.7536 | BD3: 0.2861 | BE3: 0.6087 | BF3: 1.2024 | BG3: 8.9747 | BH3: 8.7417 | BI3: 8.0399 | BJ3: 11.152 | BK3: 6.5181 | BL3: 7.4729 | BM3: 1.4715 | BN3: 6.5523 | BO3: 18.4549 | BP3: 8.461541 | BQ3: 0.986503 | BR3: 1.920167 | BS3: 15.24317 | BT3: 3.782756 | BU3: 12.55027 | BV3: 1.937818
A4: 798 | AQ4: E01 | AR4: E02 | AS4: E03 | AT4: E04 | AU4: E05 | AV4: E06 | AW4: E11 | AX4: E12 | AY4: E13 | AZ4: E14 | BA4: E08 | BB4: E43 | BC4: E41 | BD4: E39 | BE4: E37 | BF4: E35 | BG4: E34 | BH4: E33 | BI4: E32 | BJ4: E27 | BK4: E24 | BL4: E25 | BM4: E27_5m | BN4: E28 | BO4: E29 | BP4: E31_sup | BQ4: E31_10m | BR4: E31_5m | BS4: E30 | BT4: E07_sup | BU4: E09_sup | BV4: E10_sup
A5: 797 | AQ5: E01 | AR5: E02 | AS5: E03 | AT5: E04 | AU5: E05 | AV5: E06 | AW5: E11 | AX5: E12 | AY5: E13 | AZ5: E14 | BA5: E08 | BJ5: E27 | BK5: E24 | BL5: E25 | BN5: E28 | BO5: E29 | BP5: E31 | BS5: E30 | BT5: E07 | BU5: E09 | BV5: E10
A6: 796
A7: 795
A8: 794
A9: 793
A10: 792
A11: 791
A12: 790
A13: 789
A14: 788
A15: 787
A16: 786
A17: 785
... A51: 751
A52: 750 | B52: 0 | C52: 0 | D52: 0 | E52: 0 | F52: 0 | G52: 0 | H52: 0 | I52: 0 | J52: 0 | K52: #NUM! | L52: 0 | U52: 0 | V52: 0 | W52: 0 | X52: 0 | Y52: 0 | Z52: 0 | AA52: 0 | AB52: #NUM! | AC52: 0 | AD52: 0 | AE52: 0 | AF52: 0 | AG52: 0
A53: 749 | B53: 0.0010895643 | C53: 0.0051286155 | D53: 0.0027638582 | E53: 0.18553941 | F53: 0.011752924 | G53: 0.0027103974 | H53: 0.0025034842 | I53: 0.0074317068 | J53: 0.005048656 | K53: 0.0012557503 | L53: 0.0021208462 | U53: 0.0035648575 | V53: 0.0021961612 | W53: 0.0017537177 | X53: 0.005482102 | Y53: 0.0059286726 | Z53: 0.0022129597 | AA53: 0.0082306003 | AB53: #NUM! | AC53: 0.0058779549 | AD53: 0.011816206 | AE53: 0.0084496669 | AF53: 0.01171577 | AG53: 0.053114132
A54: 748 | B54: 0.0012451044 | C54: 0.0081929924 | D54: 0.00090993517 | E54: 0.15609226 | F54: 0.011486141 | G54: 0.00284311 | H54: 0.0022335351 | I54: 0.0072321699 | J54: 0.0040798322 | K54: 0.00093779664 | L54: 0.0014940963 | U54: 0.0039381675 | V54: 0.0036562968 | W54: 0.00206651 | X54: 0.007337476 | Y54: 0.0044521012 | Z54: 0.0028409903 | AA54: 0.0059798237 | AB54: 0.00020464329 | AC54: 0.0068691419 | AD54: 0.011201057 | AE54: 0.016936086 | AF54: 0.010579416 | AG54: 0.059272711
A55: 747 | B55: 0.00016640445 | C55: 0.0040654285 | D55: 0.0012691501 | E55: 0.14346646 | F55: 0.01044807 | G55: 0.0024392458 | H55: 0.00060741711 | I55: 0.0058290739 | J55: 0.0023140869 | K55: #NUM! | L55: 0.0007795498 | U55: 0.0031012788 | V55: 0.0047103037 | W55: 0.0016973344 | X55: 0.0069619453 | Y55: 0.0052309667 | Z55: 0.0014630845 | AA55: 0.00423914 | AB55: #NUM! | AC55: 0.0062813236 | AD55: 0.0051350274 | AE55: 0.012203794 | AF55: 0.0056005994 | AG55: 0.054505451
A56: 746 | B56: #NUM! | C56: 0.0035513883 | D56: 0.00062290253 | E56: 0.2412323 | F56: 0.011592115 | G56: 0.002152766 | H56: 3.6914769e-05 | I56: 0.0059374764 | J56: 0.0023152436 | K56: 0.00029129583 | L56: 0.0015804546 | U56: 0.0065536012 | V56: 0.0054083893 | W56: 0.00049159325 | X56: 0.0042615905 | Y56: 0.0030063198 | Z56: 9.858134e-05 | AA56: 0.003935819 | AB56: #NUM! | AC56: 0.0074039021 | AD56: 0.0067119084 | AE56: 0.0075324222 | AF56: 0.0042795885 | AG56: 0.056315763
A57: 745 | B57: #NUM! | C57: 0.0037129342 | D57: 0.0011843908 | E57: 0.12896844 | F57: 0.010639895 | G57: 0.00055599214 | H57: 0.00051467842 | I57: 0.0037526412 | J57: 0.00059338685 | K57: #NUM! | L57: 0.00046542242 | U57: 0.0049475454 | V57: 0.0038674316 | W57: 0.0013997059 | X57: 0.0017260499 | Y57: 0.0025125192 | Z57: 6.3067848e-05 | AA57: 0.0038926136 | AB57: #NUM! | AC57: 0.0054990544 | AD57: 0.0065884543 | AE57: 0.0091111011 | AF57: 0.0052410671 | AG57: 0.050047687
A58: 744 | B58: #NUM! | C58: 0.0039729609 | D58: 0.00047193818 | E58: 0.1029414 | F58: 0.0030721391 | G58: 0.00038898455 | H58: 0.00071305308 | I58: 0.0041688908 | J58: 0.001472871 | K58: #NUM! | L58: 0.00010992962 | U58: 0.0045625219 | V58: 0.002296591 | W58: #NUM! | X58: 0.002180598 | Y58: 0.0022362006 | Z58: -0.00072273671 | AA58: 0.0022599164 | AB58: #NUM! | AC58: 0.0027914585 | AD58: 0.006847097 | AE58: 0.005166437 | AF58: 0.0033100744 | AG58: 0.052041838
A59: 743 | B59: #NUM! | C59: 0.0010904866 | D59: 0.0014985296 | E59: 0.02671888 | F59: 0.0053085809 | G59: 0.00018147517 | H59: #NUM! | I59: 9.1425298e-05 | J59: 0.00026337821 | K59: #NUM! | L59: 5.7493628e-05 | U59: 0.0026489632 | V59: 0.00359455 | W59: #NUM! | X59: 0.0020432263 | Y59: 0.00078638246 | Z59: -0.00095571239 | AA59: 0.0013406934 | AB59: #NUM! | AC59: 0.0035613034 | AD59: 0.0035787192 | AE59: 0.0043677045 | AF59: 0.00066180185 | AG59: 0.048567603
A60: 742 | B60: #NUM! | C60: 0.0014349485 | D60: 0.00084895483 | E60: 0.059046066 | F60: 0.00044315497 | G60: 0.0014622306 | H60: #NUM! | I60: -0.00010333159 | J60: #NUM! | K60: #NUM! | L60: 5.8618255e-05 | U60: 0.0011036932 | V60: 0.0010272739 | W60: #NUM! | X60: 0.0016399209 | Y60: 0.00068056977 | Z60: #NUM! | AA60: 0.00061512128 | AB60: #NUM! | AC60: 0.00079422071 | AD60: 0.0015690927 | AE60: 0.002871531 | AF60: -0.00017179665 | AG60: 0.043450472
A61: 741 | B61: #NUM! | C61: 0.00076772388 | D61: 2.5242037e-06 | E61: 0.019989016 | F61: 0.0017787309 | G61: 0.001033564 | H61: #NUM! | I61: 9.7773245e-05 | J61: 7.3281299e-05 | K61: #NUM! | L61: 0.0001711168 | U61: 0.0027934956 | V61: 0.0031258451 | W61: #NUM! | X61: 0.0022943718 | Y61: 0.00061249951 | Z61: #NUM! | AA61: 0.000344484 | AB61: #NUM! | AC61: 0.0014108869 | AD61: 0.0020023938 | AE61: 0.0025792885 | AF61: #NUM! | AG61: 0.053057947
A62: 740 | B62: #NUM! | C62: -1.0229488e-05 | D62: 0.00041826994 | E62: 0.0072306198 | F62: 0.0026928352 | G62: 0.0011880914 | H62: #NUM! | I62: 7.1536227e-05 | J62: #NUM! | K62: #NUM! | L62: 0.00029433633 | U62: 0.0014958129 | V62: 0.00068738887 | W62: #NUM! | X62: 0.0017414258 | Y62: #NUM! | Z62: #NUM! | AA62: -0.00012511985 | AB62: #NUM! | AC62: 0.001140692 | AD62: -0.00025814017 | AE62: 0.0039603436 | AF62: 0.00023472396 | AG62: 0.045844108
A63: 739 | B63: #NUM! | C63: #NUM! | D63: #NUM! | E63: #NUM! | F63: 0.0055629889 | G63: -0.00043074604 | H63: #NUM! | I63: #NUM! | J63: #NUM! | K63: #NUM! | L63: 6.3184886e-05 | U63: 0.0016024268 | V63: 0.00049992169 | W63: #NUM! | X63: 0.00013807313 | Y63: #NUM! | Z63: #NUM! | AA63: -0.00031409221 | AB63: #NUM! | AC63: -0.00015449658 | AD63: -0.0013396038 | AE63: 0.0027158401 | AF63: -0.00062144424 | AG63: 0.037850765
A64: 738 | B64: #NUM! | C64: #NUM! | D64: 0.00071524751 | E64: #NUM! | F64: 0.0041856101 | G64: #NUM! | H64: #NUM! | I64: #NUM! | J64: #NUM! | K64: #NUM! | L64: 4.5457698e-05 | U64: 0.0011730076 | V64: -0.00012088852 | W64: #NUM! | X64: #NUM! | Y64: #NUM! | Z64: #NUM! | AA64: #NUM! | AB64: #NUM! | AC64: #NUM! | AD64: -0.0011519187 | AE64: 0.002266934 | AF64: #NUM! | AG64: 0.040651494
A65: 737 | B65: #NUM! | C65: #NUM! | D65: #NUM! | E65: #NUM! | F65: 0.00041583596 | G65: #NUM! | H65: #NUM! | I65: #NUM! | J65: #NUM! | K65: #NUM! | L65: #NUM! | U65: 0.00023131991 | V65: #NUM! | W65: #NUM! | X65: -0.00035783511 | Y65: #NUM! | Z65: #NUM! | AA65: #NUM! | AB65: #NUM! | AC65: #NUM! | AD65: #NUM! | AE65: 0.00026253226 | AF65: #NUM! | AG65: 0.038561435
A66: 736 | B66: #NUM! | C66: #NUM! | D66: #NUM! | E66: #NUM! | F66: 0.004550856 | G66: #NUM! | H66: #NUM! | I66: #NUM! | J66: #NUM! | K66: #NUM! | L66: #NUM! | U66: #NUM! | V66: #NUM! | W66: #NUM! | X66: #NUM! | Y66: #NUM! | Z66: #NUM! | AA66: #NUM! | AB66: #NUM! | AC66: #NUM! | AD66: #NUM! | AE66: #NUM! | AF66: #NUM! | AG66: 0.030040629
A67: 735 | B67: #NUM! | C67: 0.00070190611 | D67: 0.0017753467 | E67: 0.032679642 | F67: 0.011617223 | G67: #NUM! | H67: #NUM! | I67: 0.0010862311 | J67: #NUM! | K67: #NUM! | L67: 0.00058232394 | U67: 0.00037886401 | V67: #NUM! | W67: 5.6391998e-05 | X67: 0.0041618575 | Y67: #NUM! | Z67: #NUM! | AA67: 0.0019703404 | AB67: #NUM! | AC67: 0.0016784325 | AD67: -0.0012780817 | AE67: 0.0089859414 | AF67: #NUM! | AG67: 0.045600029
A68: 734 | B68: #NUM! | C68: -0.00023827927 | D68: 0.0021753447 | E68: 0.014979741 | F68: 0.011763251 | G68: #NUM! | H68: #NUM! | I68: #NUM! | J68: #NUM! | K68: #NUM! | L68: 0.00066635948 | U68: 0.00033907306 | V68: -0.00093131553 | W68: #NUM! | X68: 0.00056976809 | Y68: 0.00026529044 | Z68: #NUM! | AA68: 0.0025712331 | AB68: #NUM! | AC68: 0.0028046468 | AD68: -0.00072264604 | AE68: 0.0044233966 | AF68: -0.00023752781 | AG68: 0.035204694
A69: 733 | B69: #NUM! | C69: 7.6456259e-05 | D69: 0.0026621093 | E69: 0.065761991 | F69: 0.0027255651 | G69: #NUM! | H69: #NUM! | I69: -0.00042203712 | J69: #NUM! | K69: #NUM! | L69: 0.0016086901 | U69: 0.00090525647 | V69: -7.7841461e-05 | W69: #NUM! | X69: 0.00078663387 | Y69: 0.00014316255 | Z69: #NUM! | AA69: 0.00011357769 | AB69: #NUM! | AC69: 0.00057256621 | AD69: 0.00031283518 | AE69: 0.012557515 | AF69: #NUM! | AG69: 0.043607996
A70: 732 | B70: #NUM! | C70: #NUM! | D70: 0.00076910662 | E70: -0.0053024408 | F70: 0.0042119115 | G70: #NUM! | H70: #NUM! | I70: #NUM! | J70: #NUM! | K70: #NUM! | L70: 0.00032033 | U70: 0.0058473423 | V70: -0.00019189856 | W70: #NUM! | X70: 0.00015619066 | Y70: -0.0010870018 | Z70: #NUM! | AA70: 0.00048084343 | AB70: #NUM! | AC70: #NUM! | AD70: -0.0028980703 | AE70: 0.0036105354 | AF70: #NUM! | AG70: 0.047036335
A71: 731 | B71: #NUM! | C71: #NUM! | D71: 0.0011502422 | E71: #NUM! | F71: 0.011224038 | G71: #NUM! | H71: #NUM! | I71: #NUM! | J71: #NUM! | K71: #NUM! | L71: #NUM! | U71: 0.0018245562 | V71: #NUM! | W71: #NUM! | X71: #NUM! | Y71: #NUM! | Z71: #NUM! | AA71: -0.00099744482 | AB71: #NUM! | AC71: #NUM! | AD71: #NUM! | AE71: 0.00287903 | AF71: -0.0014727325 | AG71: 0.040155185
A72: 730 | B72: #NUM! | C72: #NUM! | D72: #NUM! | E72: #NUM! | F72: 0.005507494 | G72: #NUM! | H72: #NUM! | I72: #NUM! | J72: #NUM! | K72: #NUM! | L72: #NUM! | U72: #NUM! | V72: #NUM! | W72: #NUM! | X72: #NUM! | Y72: #NUM! | Z72: #NUM! | AA72: #NUM! | AB72: #NUM! | AC72: #NUM! | AD72: #NUM! | AE72: 0.0030616264 | AF72: #NUM! | AG72: 0.02813496
A73: 729 | B73: #NUM! | C73: #NUM! | D73: #NUM! | E73: #NUM! | F73: #NUM! | G73: #NUM! | H73: #NUM! | I73: #NUM! | J73: #NUM! | K73: #NUM! | L73: #NUM! | U73: #NUM! | V73: #NUM! | W73: #NUM! | X73: #NUM! | Y73: #NUM! | Z73: #NUM! | AA73: #NUM! | AB73: #NUM! | AC73: #NUM! | AD73: #NUM! | AE73: #NUM! | AF73: #NUM! | AG73: 0.032348511
...

Sheet aCDOM
A1: Wavelength (nm) | B1: SC-21-0101 | C1: SC-21-0104 | D1: SC-21-0109 | E1: SC-21-0113 | F1: SC-21-0115 | G1: SC-21-0119 | H1: SC-21-0124 | I1: SC-21-0128 | J1: SC-21-0132 | K1: SC-21-0136 | L1: SC-21-0140 | M1: SC-21-0148 | N1: SC-21-0152 | O1: SC-21-0154 | P1: SC-21-0156 | Q1: SC-21-0158 | R1: SC-21-0159 | S1: SC-21-0160 | T1: SC-21-0161 | U1: SC-21-0163 | V1: SC-21-0164 | W1: SC-21-0165 | X1: SC-21-0166 | Y1: SC-21-0167 | Z1: SC-21-0168 | AA1: SC-21-0169 | AB1: SC-21-0170 | AC1: SC-21-0171 | AD1: SC-21-0172 | AE1: SC-21-0225 | AF1: SC-21-0228 | AG1: SC-21-0231 | AJ1: =+B1 -> SC-21-0101 | AK1: =+C1 -> SC-21-0104 | AL1: =+D1 -> SC-21-0109 | AM1: =+E1 -> SC-21-0113 | AN1: =+F1 -> SC-21-0115 | AO1: =+G1 -> SC-21-0119 | AP1: =+H1 -> SC-21-0124 | AQ1: =+I1 -> SC-21-0128 | ... BO1: =+AG1 -> SC-21-0231 | BQ1: Wavelength (nm) | BR1: =+B1 -> SC-21-0101 | BS1: =+C1 -> SC-21-0104 | BT1: =+D1 -> SC-21-0109 | BU1: =+E1 -> SC-21-0113 | BV1: =+F1 -> SC-21-0115 | BW1: =+G1 -> SC-21-0119 | BX1: =+H1 -> SC-21-0124 | BY1: =+I1 -> SC-21-0128 | ... CW1: =+AG1 -> SC-21-0231
A2: 800 | B2: -0.042600894 | C2: -0.05243931 | D2: -0.0640234 | E2: -0.09334059 | F2: -0.088437503 | G2: -0.044659776 | H2: -0.025358333 | I2: -0.011017552 | J2: -0.026316381 | K2: -0.022060437 | L2: -0.052526824 | M2: -0.019332073 | N2: -0.019762043 | O2: 0.006980393 | P2: -0.056283017 | Q2: -0.035380989 | R2: -0.043646456 | S2: -0.043821484 | T2: -0.028964831 | U2: -0.04249035 | V2: -0.032113032 | W2: -0.042978586 | X2: -0.020678637 | Y2: -0.030332813 | Z2: -0.04580667 | AA2: -0.037179632 | AB2: 0.004048674 | AC2: -0.00819868 | AD2: -0.068189527 | AE2: -0.096507215 | AF2: -0.074582655 | AG2: -0.066975846 | AI2: a | AJ2: 1195 | AK2: 1291 | AL2: 1669 | AM2: 3853 | AN2: 2556 | AO2: 1086 | AP2: 647.1 | AQ2: 563 | AR2: 279 | AS2: 421.2 | AT2: 1028 | AU2: 171.3 | AV2: 210 | AW2: 86.05 | AX2: 56.77 | AY2: 1168 | AZ2: 1429 | BA2: 1590 | BB2: 1313 | BC2: 1510 | BD2: 1172 | BE2: 1199 | BF2: 257.5 | BG2: 1168 | BH2: 843.1 | BI2: 1581 | BJ2: 165.6 | BK2: 237.4 | BL2: 842 | BM2: 2959 | BN2: 2131 | BO2: 2256 | BQ2: =+A2 -> 800 | BR2: =AJ$2*EXP(AJ$3*$BQ2) -> 0.00079426092 | BS2: =AK$2*EXP(AK$3*$BQ2) -> 0.00075497373 | BT2: =AL$2*EXP(AL$3*$BQ2) -> 0.0010743708 | BU2: =AM$2*EXP(AM$3*$BQ2) -> 0.0012267429 | BV2: =AN$2*EXP(AN$3*$BQ2) -> 0.0012839665 | BW2: =AO$2*EXP(AO$3*$BQ2) -> 0.00072761136 | BX2: =AP$2*EXP(AP$3*$BQ2) -> 0.00044408296 | BY2: =AQ$2*EXP(AQ$3*$BQ2) -> 0.00018656696 | ... CW2: =BO$2*EXP(BO$3*$BQ2) -> 0.0010630093
A3: 799 | B3: -0.032119941 | C3: -0.041831692 | D3: -0.059778971 | E3: -0.08808975 | F3: -0.080162824 | G3: -0.032244303 | H3: -0.013666002 | I3: -0.003864434 | J3: -0.012348686 | K3: -0.009292605 | L3: -0.044364992 | M3: -0.019942138 | N3: -0.011574878 | O3: 0.008148014 | P3: -0.051050601 | Q3: -0.025503422 | R3: -0.041313517 | S3: -0.03793041 | T3: -0.022461159 | U3: -0.04368791 | V3: -0.028052843 | W3: -0.038020227 | X3: -0.018962902 | Y3: -0.026406198 | Z3: -0.038890761 | AA3: -0.034323912 | AB3: 0.011070521 | AC3: -0.013117888 | AD3: -0.063507528 | AE3: -0.094849055 | AF3: -0.069702598 | AG3: -0.069886838 | AI3: b | AJ3: -0.01778 | AK3: -0.01794 | AL3: -0.01782 | AM3: -0.0187 | AN3: -0.01813 | AO3: -0.01777 | AP3: -0.01774 | AQ3: -0.01865 | AR3: -0.01684 | AS3: -0.01748 | AT3: -0.01759 | AU3: -0.01653 | AV3: -0.0165 | AW3: -0.01654 | AX3: -0.01383 | AY3: -0.01811 | AZ3: -0.01833 | BA3: -0.01854 | BB3: -0.01824 | BC3: -0.01824 | BD3: -0.01803 | BE3: -0.01791 | BF3: -0.01743 | BG3: -0.01842 | BH3: -0.01721 | BI3: -0.01865 | BJ3: -0.01757 | BK3: -0.01698 | BL3: -0.01698 | BM3: -0.01824 | BN3: -0.01808 | BO3: -0.01821 | BQ3: =+A3 -> 799 | BR3: =AJ$2*EXP(AJ$3*$BQ3) -> 0.00080850917 | BS3: =AK$2*EXP(AK$3*$BQ3) -> 0.00076864018 | BT3: =AL$2*EXP(AL$3*$BQ3) -> 0.0010936877 | BU3: =AM$2*EXP(AM$3*$BQ3) -> 0.0012498988 | BV3: =AN$2*EXP(AN$3*$BQ3) -> 0.0013074571 | BW3: =AO$2*EXP(AO$3*$BQ3) -> 0.00074065658 | BX3: =AP$2*EXP(AP$3*$BQ3) -> 0.00045203129 | BY3: =AQ$2*EXP(AQ$3*$BQ3) -> 0.00019007908 | ... CW3: =BO$2*EXP(BO$3*$BQ3) -> 0.0010825441
A4: 798 | B4: -0.039830385 | C4: -0.046000122 | D4: -0.06296402 | E4: -0.094752329 | F4: -0.086378621 | G4: -0.040339348 | H4: -0.017631768 | I4: -0.007206087 | J4: -0.019930162 | K4: -0.020862877 | L4: -0.051865863 | M4: -0.017850092 | N4: -0.018258184 | O4: 0.011890389 | P4: -0.055129214 | Q4: -0.030058756 | R4: -0.041631331 | S4: -0.040134381 | T4: -0.023322481 | U4: -0.0449085 | V4: -0.028849681 | W4: -0.039240817 | X4: -0.018230548 | Y4: -0.030685172 | Z4: -0.039300695 | AA4: -0.034954934 | AB4: 0.012007842 | AC4: -0.012581289 | AD4: -0.05992406 | AE4: -0.095256686 | AF4: -0.070391195 | AG4: -0.070522466 | AI4: f(x)=a*exp(b*x) | BQ4: =+A4 -> 798 | BR4: =AJ$2*EXP(AJ$3*$BQ4) -> 0.00082301302 | BS4: =AK$2*EXP(AK$3*$BQ4) -> 0.00078255402 | BT4: =AL$2*EXP(AL$3*$BQ4) -> 0.0011133519 | BU4: =AM$2*EXP(AM$3*$BQ4) -> 0.0012734919 | BV4: =AN$2*EXP(AN$3*$BQ4) -> 0.0013313775 | BW4: =AO$2*EXP(AO$3*$BQ4) -> 0.00075393568 | BX4: =AP$2*EXP(AP$3*$BQ4) -> 0.00046012187 | BY4: =AQ$2*EXP(AQ$3*$BQ4) -> 0.00019365732 | ... CW4: =BO$2*EXP(BO$3*$BQ4) -> 0.0011024378
A5: 797 | B5: -0.036638427 | C5: -0.042340655 | D5: -0.062878809 | E5: -0.091258678 | F5: -0.085130395 | G5: -0.039187848 | H5: -0.016828021 | I5: -0.004150006 | J5: -0.015010954 | K5: -0.014421386 | L5: -0.049141414 | M5: -0.015758968 | N5: -0.015356404 | O5: 0.007017241 | P5: -0.050820301 | Q5: -0.030150876 | R5: -0.042554834 | S5: -0.032939809 | T5: -0.020807605 | U5: -0.04143097 | V5: -0.026279533 | W5: -0.036806546 | X5: -0.014246358 | Y5: -0.024598343 | Z5: -0.038301193 | AA5: -0.031495828 | AB5: 0.011402153 | AC5: -0.009080729 | AD5: -0.066333309 | AE5: -0.098298949 | AF5: -0.074538898 | AG5: -0.063509831 | BQ5: =+A5 -> 797 | BR5: =AJ$2*EXP(AJ$3*$BQ5) -> 0.00083777706 | BS5: =AK$2*EXP(AK$3*$BQ5) -> 0.00079671972 | BT5: =AL$2*EXP(AL$3*$BQ5) -> 0.0011333697 | BU5: =AM$2*EXP(AM$3*$BQ5) -> 0.0012975302 | BV5: =AN$2*EXP(AN$3*$BQ5) -> 0.0013557355 | BW5: =AO$2*EXP(AO$3*$BQ5) -> 0.00076745286 | BX5: =AP$2*EXP(AP$3*$BQ5) -> 0.00046835727 | BY5: =AQ$2*EXP(AQ$3*$BQ5) -> 0.00019730291 | ... CW5: =BO$2*EXP(BO$3*$BQ5) -> 0.0011226971
A6: 796 | B6: -0.03666376 | C6: -0.042405139 | D6: -0.06123677 | E6: -0.091136619 | F6: -0.082385219 | G6: -0.037050664 | H6: -0.016471056 | I6: -0.004711938 | J6: -0.017544254 | K6: -0.014679322 | L6: -0.051911923 | M6: -0.014880374 | N6: -0.011381426 | O6: 0.005626229 | P6: -0.050633758 | Q6: -0.027447154 | R6: -0.045371403 | S6: -0.03717042 | T6: -0.022659217 | U6: -0.0455994 | V6: -0.02217789 | W6: -0.040974976 | X6: -0.018691148 | Y6: -0.023322481 | Z6: -0.036523277 | AA6: -0.032697994 | AB6: 0.015393252 | AC6: -0.00734657 | AD6: -0.066559003 | AE6: -0.09711751 | AF6: -0.072532985 | AG6: -0.068627097 | AJ6: b = Scdom | BQ6: =+A6 -> 796 | BR6: =AJ$2*EXP(AJ$3*$BQ6) -> 0.00085280594 | BS6: =AK$2*EXP(AK$3*$BQ6) -> 0.00081114185 | BT6: =AL$2*EXP(AL$3*$BQ6) -> 0.0011537473 | BU6: =AM$2*EXP(AM$3*$BQ6) -> 0.0013220223 | BV6: =AN$2*EXP(AN$3*$BQ6) -> 0.0013805391 | BW6: =AO$2*EXP(AO$3*$BQ6) -> 0.00078121239 | BX6: =AP$2*EXP(AP$3*$BQ6) -> 0.00047674006 | BY6: =AQ$2*EXP(AQ$3*$BQ6) -> 0.00020101714 | ... CW6: =BO$2*EXP(BO$3*$BQ6) -> 0.0011433287
A7: 795 | B7: -0.030155482 | C7: -0.038526887 | D7: -0.059205524 | E7: -0.087327457 | F7: -0.084372708 | G7: -0.036463399 | H7: -0.013857151 | I7: -0.004000311 | J7: -0.016648387 | K7: -0.015333374 | L7: -0.044804865 | M7: -0.010137806 | N7: -0.011365305 | O7: 0.019720589 | P7: -0.046506782 | Q7: -0.023907443 | R7: -0.046315633 | S7: -0.0375389 | T7: -0.018730299 | U7: -0.04018735 | V7: -0.019978525 | W7: -0.039063486 | X7: -0.021544565 | Y7: -0.025406696 | Z7: -0.036108737 | AA7: -0.028306173 | AB7: 0.014045997 | AC7: -0.01628221 | AD7: -0.065663136 | AE7: -0.10041541 | AF7: -0.074736956 | AG7: -0.068164194 | AJ7: 1 | AK7: 2 | AL7: 3 | AM7: 4 | AN7: 5 | AO7: 6 | AP7: 7 | AQ7: 8 | AR7: 9 | AS7: 10 | AT7: 11 | AU7: 12 | AV7: 13 | AW7: 14 | AX7: 15 | AY7: 16 | AZ7: 17 | BA7: 18 | BB7: 19 | BC7: 20 | BD7: 21 | BE7: 22 | BF7: 23 | BG7: 24 | BH7: 25 | BI7: 26 | BJ7: 27 | BK7: 28 | BL7: 29 | BM7: 30 | BN7: 31 | BO7: 32 | BQ7: =+A7 -> 795 | BR7: =AJ$2*EXP(AJ$3*$BQ7) -> 0.00086810443 | BS7: =AK$2*EXP(AK$3*$BQ7) -> 0.00082582505 | BT7: =AL$2*EXP(AL$3*$BQ7) -> 0.0011744914 | BU7: =AM$2*EXP(AM$3*$BQ7) -> 0.0013469767 | BV7: =AN$2*EXP(AN$3*$BQ7) -> 0.0014057966 | BW7: =AO$2*EXP(AO$3*$BQ7) -> 0.00079521861 | BX7: =AP$2*EXP(AP$3*$BQ7) -> 0.00048527289 | BY7: =AQ$2*EXP(AQ$3*$BQ7) -> 0.00020480129 | ... CW7: =BO$2*EXP(BO$3*$BQ7) -> 0.0011643394
A8: 794 | B8: -0.035984375 | C8: -0.044358083 | D8: -0.058001055 | E8: -0.093474164 | F8: -0.082074314 | G8: -0.038893064 | H8: -0.017095169 | I8: -0.005886468 | J8: -0.016272998 | K8: -0.014596414 | L8: -0.04748786 | M8: -0.017500727 | N8: -0.016314452 | O8: 0.008822793 | P8: -0.053864867 | Q8: -0.031300073 | R8: -0.041741875 | S8: -0.040608799 | T8: -0.020701667 | U8: -0.04645151 | V8: -0.026387774 | W8: -0.039024335 | X8: -0.017484376 | Y8: -0.026843768 | Z8: -0.035104629 | AA8: -0.036405824 | AB8: 0.014195692 | AC8: -0.010206896 | AD8: -0.061315072 | AE8: -0.092645084 | AF8: -0.072645832 | AG8: -0.068592552 | AJ8: =AJ3*-1 -> 0.01778 | AK8: =AK3*-1 -> 0.01794 | AL8: =AL3*-1 -> 0.01782 | AM8: =AM3*-1 -> 0.0187 | AN8: =AN3*-1 -> 0.01813 | AO8: =AO3*-1 -> 0.01777 | AP8: =AP3*-1 -> 0.01774 | AQ8: =AQ3*-1 -> 0.01865 | ... BO8: =BO3*-1 -> 0.01821 | BQ8: =+A8 -> 794 | BR8: =AJ$2*EXP(AJ$3*$BQ8) -> 0.00088367736 | BS8: =AK$2*EXP(AK$3*$BQ8) -> 0.00084077404 | BT8: =AL$2*EXP(AL$3*$BQ8) -> 0.0011956084 | BU8: =AM$2*EXP(AM$3*$BQ8) -> 0.0013724022 | BV8: =AN$2*EXP(AN$3*$BQ8) -> 0.0014315161 | BW8: =AO$2*EXP(AO$3*$BQ8) -> 0.00080947595 | BX8: =AP$2*EXP(AP$3*$BQ8) -> 0.00049395845 | BY8: =AQ$2*EXP(AQ$3*$BQ8) -> 0.00020865667 | ... CW8: =BO$2*EXP(BO$3*$BQ8) -> 0.0011857363
A9: 793 | B9: -0.035433958 | C9: -0.041237518 | D9: -0.060306358 | E9: -0.091251769 | F9: -0.082300008 | G9: -0.036760486 | H9: -0.017482073 | I9: -0.00481327 | J9: -0.015911427 | K9: -0.016263786 | L9: -0.050456427 | M9: -0.013403921 | N9: -0.014591808 | O9: 0.011945661 | P9: -0.050260672 | Q9: -0.028181811 | R9: -0.04564546 | S9: -0.040493649 | T9: -0.02005913 | U9: -0.0409934 | V9: -0.027576122 | W9: -0.038407131 | X9: -0.012063114 | Y9: -0.029773184 | Z9: -0.039077304 | AA9: -0.034105127 | AB9: 0.012986617 | AC9: -0.009829204 | AD9: -0.062736023 | AE9: -0.096746727 | AF9: -0.077760795 | AG9: -0.065762165 | BQ9: =+A9 -> 793 | BR9: =AJ$2*EXP(AJ$3*$BQ9) -> 0.00089952966 | BS9: =AK$2*EXP(AK$3*$BQ9) -> 0.00085599364 | BT9: =AL$2*EXP(AL$3*$BQ9) -> 0.0012171051 | BU9: =AM$2*EXP(AM$3*$BQ9) -> 0.0013983076 | BV9: =AN$2*EXP(AN$3*$BQ9) -> 0.0014577062 | BW9: =AO$2*EXP(AO$3*$BQ9) -> 0.0008239889 | BX9: =AP$2*EXP(AP$3*$BQ9) -> 0.00050279946 | BY9: =AQ$2*EXP(AQ$3*$BQ9) -> 0.00021258463 | ... CW9: =BO$2*EXP(BO$3*$BQ9) -> 0.0012075263
A10: 792 | B10: -0.034443668 | C10: -0.042932526 | D10: -0.051672411 | E10: -0.090385841 | F10: -0.085105062 | G10: -0.038840095 | H10: -0.018969811 | I10: -0.003737769 | J10: -0.010702041 | K10: -0.012754014 | L10: -0.04504668 | M10: -0.012770135 | N10: -0.015043196 | O10: 0.012429291 | P10: -0.048814388 | Q10: -0.032582844 | R10: -0.04516183 | S10: -0.038349556 | T10: -0.024602949 | U10: -0.041866237 | V10: -0.029257312 | W10: -0.038727248 | X10: -0.011082036 | Y10: -0.031085894 | Z10: -0.03187352 | AA10: -0.032847689 | AB10: 0.009951263 | AC10: 0.003935827 | AD10: -0.057623363 | AE10: -0.095461653 | AF10: -0.068373767 | AG10: -0.062821234 | BQ10: =+A10 -> 792 | BR10: =AJ$2*EXP(AJ$3*$BQ10) -> 0.00091566632 | BS10: =AK$2*EXP(AK$3*$BQ10) -> 0.00087148874 | BT10: =AL$2*EXP(AL$3*$BQ10) -> 0.0012389884 | BU10: =AM$2*EXP(AM$3*$BQ10) -> 0.0014247019 | BV10: =AN$2*EXP(AN$3*$BQ10) -> 0.0014843754 | BW10: =AO$2*EXP(AO$3*$BQ10) -> 0.00083876205 | BX10: =AP$2*EXP(AP$3*$BQ10) -> 0.00051179871 | BY10: =AQ$2*EXP(AQ$3*$BQ10) -> 0.00021658654 | ... CW10: =BO$2*EXP(BO$3*$BQ10) -> 0.0012297168
A11: 791 | B11: -0.042584773 | C11: -0.047338165 | D11: -0.060992652 | E11: -0.10325961 | F11: -0.086205896 | G11: -0.042780528 | H11: -0.020632577 | I11: -0.011761421 | J11: -0.020264097 | K11: -0.018230548 | L11: -0.054820612 | M11: -0.008926428 | N11: -0.004562243 | O11: 0.023619568 | P11: -0.042683802 | Q11: -0.025231668 | R11: -0.043379308 | S11: -0.035187537 | T11: -0.015872276 | U11: -0.03659467 | V11: -0.018790177 | W11: -0.036845697 | X11: -0.00819868 | Y11: -0.017680131 | Z11: -0.027256005 | AA11: -0.025284637 | AB11: 0.020388459 | AC11: -0.00333935 | AD11: -0.056727496 | AE11: -0.094572695 | AF11: -0.067931591 | AG11: -0.066093797 | AJ11: 0.01778 | AK11: 0.01794 | AL11: 0.01782 | AM11: 0.0187 | AN11: 0.01813 | AO11: 0.01777 | AP11: 0.01774 | AQ11: 0.01865 | AR11: 0.01684 | AS11: 0.01748 | AT11: 0.01759 | AU11: 0.01653 | AV11: 0.0165 | AW11: 0.01654 | AX11: 0.01383 | AY11: 0.01811 | AZ11: 0.01833 | BA11: 0.01854 | BB11: 0.01824 | BC11: 0.01824 | BD11: 0.01803 | BE11: 0.01791 | BF11: 0.01743 | BG11: 0.01842 | BH11: 0.01721 | BI11: 0.01865 | BJ11: 0.01757 | BK11: 0.01698 | BL11: 0.01698 | BM11: 0.01824 | BN11: 0.01808 | BO11: 0.01821 | BQ11: =+A11 -> 791 | BR11: =AJ$2*EXP(AJ$3*$BQ11) -> 0.00093209247 | BS11: =AK$2*EXP(AK$3*$BQ11) -> 0.00088726434 | BT11: =AL$2*EXP(AL$3*$BQ11) -> 0.001261265 | BU11: =AM$2*EXP(AM$3*$BQ11) -> 0.0014515945 | BV11: =AN$2*EXP(AN$3*$BQ11) -> 0.0015115326 | BW11: =AO$2*EXP(AO$3*$BQ11) -> 0.00085380007 | BX11: =AP$2*EXP(AP$3*$BQ11) -> 0.00052095903 | BY11: =AQ$2*EXP(AQ$3*$BQ11) -> 0.00022066378 | ... CW11: =BO$2*EXP(BO$3*$BQ11) -> 0.0012523151
A12: 790 | B12: -0.031783703 | C12: -0.03922009 | D12: -0.051617139 | E12: -0.09267272 | F12: -0.080602697 | G12: -0.032822356 | H12: -0.013953877 | I12: 0.002139487 | J12: -0.007620627 | K12: -0.008627038 | L12: -0.044277478 | M12: -0.010449863 | N12: -0.005025146 | O12: 0.016745113 | P12: -0.046315633 | Q12: -0.021553777 | R12: -0.044351174 | S12: -0.033202351 | T12: -0.01531495 | U12: -0.0343147 | V12: -0.01883854 | W12: -0.030141664 | X12: -0.00665567 | Y12: -0.016662205 | Z12: -0.026288745 | AA12: -0.022719095 | AB12: 0.02169426 | AC12: -0.001800946 | AD12: -0.056174776 | AE12: -0.09370907 | AF12: -0.073168613 | AG12: -0.064866298 | BQ12: =+A12 -> 790 | BR12: =AJ$2*EXP(AJ$3*$BQ12) -> 0.00094881328 | BS12: =AK$2*EXP(AK$3*$BQ12) -> 0.0009033255 | BT12: =AL$2*EXP(AL$3*$BQ12) -> 0.0012839422 | BU12: =AM$2*EXP(AM$3*$BQ12) -> 0.0014789947 | BV12: =AN$2*EXP(AN$3*$BQ12) -> 0.0015391866 | BW12: =AO$2*EXP(AO$3*$BQ12) -> 0.0008691077 | BX12: =AP$2*EXP(AP$3*$BQ12) -> 0.0005302833 | BY12: =AQ$2*EXP(AQ$3*$BQ12) -> 0.00022481778 | ... CW12: =BO$2*EXP(BO$3*$BQ12) -> 0.0012753286
A13: 789 | B13: -0.024973732 | C13: -0.035965951 | D13: -0.050748908 | E13: -0.088267081 | F13: -0.081021843 | G13: -0.031348436 | H13: -0.008127287 | I13: 0.000545811 | J13: -0.007880866 | K13: -0.004495456 | L13: -0.040247228 | M13: -0.010127442 | N13: -0.011006037 | O13: 0.007873957 | P13: -0.046919019 | Q13: -0.03240321 | R13: -0.045067407 | S13: -0.042342958 | T13: -0.021542262 | U13: -0.04557637 | V13: -0.025351424 | W13: -0.037660959 | X13: -0.006075314 | Y13: -0.031157287 | Z13: -0.032361756 | AA13: -0.030259117 | AB13: 0.011544939 | AC13: -0.005621623 | AD13: -0.060472174 | AE13: -0.099777475 | AF13: -0.073085705 | AG13: -0.066390884 | BQ13: =+A13 -> 789 | BR13: =AJ$2*EXP(AJ$3*$BQ13) -> 0.00096583404 | BS13: =AK$2*EXP(AK$3*$BQ13) -> 0.00091967739 | BT13: =AL$2*EXP(AL$3*$BQ13) -> 0.0013070271 | BU13: =AM$2*EXP(AM$3*$BQ13) -> 0.0015069122 | BV13: =AN$2*EXP(AN$3*$BQ13) -> 0.0015673466 | BW13: =AO$2*EXP(AO$3*$BQ13) -> 0.00088468979 | BX13: =AP$2*EXP(AP$3*$BQ13) -> 0.00053977447 | BY13: =AQ$2*EXP(AQ$3*$BQ13) -> 0.00022904997 | ... CW13: =BO$2*EXP(BO$3*$BQ13) -> 0.0012987651
A14: 788 | B14: -0.028822045 | C14: -0.037718534 | D14: -0.053196997 | E14: -0.0907382 | F14: -0.07827897 | G14: -0.033257623 | H14: -0.011556454 | I14: -0.0009212 | J14: -0.005838105 | K14: -0.006289493 | L14: -0.044457112 | M14: -0.0064378062 | N14: -0.00640234 | O14: 0.013751213 | P14: -0.041046369 | Q14: -0.0218785 | R14: -0.044641352 | S14: -0.032843083 | T14: -0.014683928 | U14: -0.03802253 | V14: -0.013362006 | W14: -0.037345448 | X14: -0.005400535 | Y14: -0.024842461 | Z14: -0.026249594 | AA14: -0.027265217 | AB14: 0.021272811 | AC14: -0.002890265 | AD14: -0.065278535 | AE14: -0.095673529 | AF14: -0.070577738 | AG14: -0.065142658 | BQ14: =+A14 -> 788 | BR14: =AJ$2*EXP(AJ$3*$BQ14) -> 0.00098316015 | BS14: =AK$2*EXP(AK$3*$BQ14) -> 0.00093632529 | BT14: =AL$2*EXP(AL$3*$BQ14) -> 0.0013305271 | BU14: =AM$2*EXP(AM$3*$BQ14) -> 0.0015353565 | BV14: =AN$2*EXP(AN$3*$BQ14) -> 0.0015960217 | BW14: =AO$2*EXP(AO$3*$BQ14) -> 0.00090055123 | BX14: =AP$2*EXP(AP$3*$BQ14) -> 0.00054943551 | BY14: =AQ$2*EXP(AQ$3*$BQ14) -> 0.00023336183 | ... CW14: =BO$2*EXP(BO$3*$BQ14) -> 0.0013226323
A15: 787 | B15: -0.029699488 | C15: -0.036553216 | D15: -0.049659589 | E15: -0.093517921 | F15: -0.08300012 | G15: -0.034155793 | H15: -0.011738391 | I15: 0.001853915 | J15: -0.010015747 | K15: -0.006167434 | L15: -0.041688906 | M15: -0.015955184 | N15: -0.009018548 | O15: 0.014174965 | P15: -0.043167432 | Q15: -0.025501119 | R15: -0.043777727 | S15: -0.040548921 | T15: -0.019494895 | U15: -0.043404641 | V15: -0.02489543 | W15: -0.037251025 | X15: -0.013085646 | Y15: -0.030171603 | Z15: -0.035171416 | AA15: -0.035157598 | AB15: 0.013200796 | AC15: -0.004025644 | AD15: -0.055329575 | AE15: -0.092836233 | AF15: -0.067717412 | AG15: -0.068643218 | BQ15: =+A15 -> 787 | BR15: =AJ$2*EXP(AJ$3*$BQ15) -> 0.0010007971 | BS15: =AK$2*EXP(AK$3*$BQ15) -> 0.00095327455 | BT15: =AL$2*EXP(AL$3*$BQ15) -> 0.0013544496 | BU15: =AM$2*EXP(AM$3*$BQ15) -> 0.0015643378 | BV15: =AN$2*EXP(AN$3*$BQ15) -> 0.0016252215 | BW15: =AO$2*EXP(AO$3*$BQ15) -> 0.00091669706 | BX15: =AP$2*EXP(AP$3*$BQ15) -> 0.00055926946 | BY15: =AQ$2*EXP(AQ$3*$BQ15) -> 0.00023775487 | ... CW15: =BO$2*EXP(BO$3*$BQ15) -> 0.001346938
A16: 786 | B16: -0.030689778 | C16: -0.040016928 | D16: -0.05271567 | E16: -0.09336362 | F16: -0.083631142 | G16: -0.034510455 | H16: -0.012963587 | I16: 8.2908e-05 | J16: -0.006713245 | K16: -0.008686916 | L16: -0.042865739 | M16: -0.00188846 | N16: -0.006220403 | O16: 0.016685235 | P16: -0.034178823 | Q16: -0.022164072 | R16: -0.042117264 | S16: -0.03770011 | T16: -0.016042698 | U16: -0.039151 | V16: -0.0255633 | W16: -0.030609173 | X16: -0.007044877 | Y16: -0.025312273 | Z16: -0.029768578 | AA16: -0.030093301 | AB16: 0.016528631 | AC16: -0.005292294 | AD16: -0.060389266 | AE16: -0.097124419 | AF16: -0.071872024 | AG16: -0.065142658 | BQ16: =+A16 -> 786 | BR16: =AJ$2*EXP(AJ$3*$BQ16) -> 0.0010187504 | BS16: =AK$2*EXP(AK$3*$BQ16) -> 0.00097053062 | BT16: =AL$2*EXP(AL$3*$BQ16) -> 0.0013788023 | BU16: =AM$2*EXP(AM$3*$BQ16) -> 0.0015938662 | BV16: =AN$2*EXP(AN$3*$BQ16) -> 0.0016549555 | BW16: =AO$2*EXP(AO$3*$BQ16) -> 0.00093313236 | BX16: =AP$2*EXP(AP$3*$BQ16) -> 0.00056927943 | BY16: =AQ$2*EXP(AQ$3*$BQ16) -> 0.00024223061 | ... CW16: =BO$2*EXP(BO$3*$BQ16) -> 0.0013716905
A17: 785 | B17: -0.032769387 | C17: -0.042211687 | D17: -0.053056514 | E17: -0.09301817 | F17: -0.085296211 | G17: -0.033510953 | H17: -0.012876073 | I17: -0.001453193 | J17: -0.006671791 | K17: -0.004622121 | L17: -0.044528505 | M17: -0.0020722394 | N17: -0.003279472 | O17: 0.019008962 | P17: -0.029920576 | Q17: -0.024082471 | R17: -0.042407442 | S17: -0.034540394 | T17: -0.013085646 | U17: -0.03544317 | V17: -0.022175587 | W17: -0.037237207 | X17: -0.003968069 | Y17: -0.023667931 | Z17: -0.029796214 | AA17: -0.032534481 | AB17: 0.02005913 | AC17: -0.00407631 | AD17: -0.05831196 | AE17: -0.094462151 | AF17: -0.074785319 | AG17: -0.063196623 | BQ17: =+A17 -> 785 | BR17: =AJ$2*EXP(AJ$3*$BQ17) -> 0.0010370257 | BS17: =AK$2*EXP(AK$3*$BQ17) -> 0.00098809905 | BT17: =AL$2*EXP(AL$3*$BQ17) -> 0.0014035928 | BU17: =AM$2*EXP(AM$3*$BQ17) -> 0.0016239519 | BV17: =AN$2*EXP(AN$3*$BQ17) -> 0.0016852334 | BW17: =AO$2*EXP(AO$3*$BQ17) -> 0.00094986233 | BX17: =AP$2*EXP(AP$3*$BQ17) -> 0.00057946856 | BY17: =AQ$2*EXP(AQ$3*$BQ17) -> 0.0002467906 | ... CW17: =BO$2*EXP(BO$3*$BQ17) -> 0.0013968978
A18: 784 | B18: -0.029416219 | C18: -0.040366984 | D18: -0.052319554 | E18: -0.090510203 | F18: -0.082281584 | G18: -0.029234282 | H18: -0.007314328 | I18: 0.006549732 | J18: -0.006029254 | K18: -0.00573447 | L18: -0.038674279 | M18: -0.005064297 | N18: -0.007917714 | O18: 0.015494584 | P18: -0.03429167 | Q18: -0.027963026 | R18: -0.04345761 | S18: -0.037642535 | T18: -0.012841528 | U18: -0.03710133 | V18: -0.019333685 | W18: -0.035569835 | X18: -0.010335864 | Y18: -0.021562989 | Z18: -0.02828084 | AA18: -0.030510144 | AB18: 0.017776857 | AC18: 0.002339848 | AD18: -0.059313765 | AE18: -0.10104182 | AF18: -0.071128155 | AG18: -0.066443853 | BQ18: =+A18 -> 784 | BR18: =AJ$2*EXP(AJ$3*$BQ18) -> 0.0010556289 | BS18: =AK$2*EXP(AK$3*$BQ18) -> 0.0010059855 | BT18: =AL$2*EXP(AL$3*$BQ18) -> 0.001428829 | BU18: =AM$2*EXP(AM$3*$BQ18) -> 0.0016546055 | BV18: =AN$2*EXP(AN$3*$BQ18) -> 0.0017160654 | BW18: =AO$2*EXP(AO$3*$BQ18) -> 0.00096689225 | BX18: =AP$2*EXP(AP$3*$BQ18) -> 0.00058984005 | BY18: =AQ$2*EXP(AQ$3*$BQ18) -> 0.00025143643 | ... CW18: =BO$2*EXP(BO$3*$BQ18) -> 0.0014225683
A19: 783 | B19: -0.033338228 | C19: -0.040406135 | D19: -0.054277104 | E19: -0.091622552 | F19: -0.084400344 | G19: -0.033170109 | H19: -0.009262666 | I19: 6.4484e-05 | J19: -0.004935329 | K19: -0.004884663 | L19: -0.041099338 | M19: -0.0073470306 | N19: -0.005315324 | O19: 0.01315013 | P19: -0.03528196 | Q19: -0.026532863 | R19: -0.042087325 | S19: -0.039876445 | T19: -0.022311464 | U19: -0.03926615 | V19: -0.023803808 | W19: -0.034082097 | X19: -0.004827088 | Y19: -0.02337545 | Z19: -0.03456803 | AA19: -0.033557013 | AB19: 0.017267894 | AC19: 0.000776111 | AD19: -0.053980017 | AE19: -0.092866172 | AF19: -0.072876132 | AG19: -0.067438749 | BQ19: =+A19 -> 783 | BR19: =AJ$2*EXP(AJ$3*$BQ19) -> 0.0010745659 | BS19: =AK$2*EXP(AK$3*$BQ19) -> 0.0010241957 | BT19: =AL$2*EXP(AL$3*$BQ19) -> 0.0014545189 | BU19: =AM$2*EXP(AM$3*$BQ19) -> 0.0016858378 | BV19: =AN$2*EXP(AN$3*$BQ19) -> 0.0017474614 | BW19: =AO$2*EXP(AO$3*$BQ19) -> 0.00098422749 | BX19: =AP$2*EXP(AP$3*$BQ19) -> 0.00060039718 | BY19: =AQ$2*EXP(AQ$3*$BQ19) -> 0.00025616972 | ... CW19: =BO$2*EXP(BO$3*$BQ19) -> 0.0014487106
A20: 782 | B20: -0.034072885 | C20: -0.04108552 | D20: -0.05006722 | E20: -0.094528938 | F20: -0.087025764 | G20: -0.034001492 | H20: -0.00992593 | I20: 0.001395618 | J20: -0.009799265 | K20: -0.006089132 | L20: -0.04456305 | M20: -0.0093163259 | N20: -0.011920328 | O20: 0.01487738 | P20: -0.034934207 | Q20: -0.030447963 | R20: -0.038681188 | S20: -0.038494645 | T20: -0.017567284 | U20: -0.03940433 | V20: -0.027223763 | W20: -0.03558135 | X20: -0.009893688 | Y20: -0.025151063 | Z20: -0.032062366 | AA20: -0.03102141 | AB20: 0.016745113 | AC20: 0.001577555 | AD20: -0.054730795 | AE20: -0.097552777 | AF20: -0.070538587 | AG20: -0.066181311 | BQ20: =+A20 -> 782 | BR20: =AJ$2*EXP(AJ$3*$BQ20) -> 0.0010938425 | BS20: =AK$2*EXP(AK$3*$BQ20) -> 0.0010427356 | BT20: =AL$2*EXP(AL$3*$BQ20) -> 0.0014806708 | BU20: =AM$2*EXP(AM$3*$BQ20) -> 0.0017176595 | BV20: =AN$2*EXP(AN$3*$BQ20) -> 0.0017794318 | BW20: =AO$2*EXP(AO$3*$BQ20) -> 0.0010018735 | BX20: =AP$2*EXP(AP$3*$BQ20) -> 0.00061114326 | BY20: =AQ$2*EXP(AQ$3*$BQ20) -> 0.00026099211 | ... CW20: =BO$2*EXP(BO$3*$BQ20) -> 0.0014753332
A21: 781 | B21: -0.030749656 | C21: -0.038349556 | D21: -0.050173158 | E21: -0.094581907 | F21: -0.080699423 | G21: -0.02876447 | H21: -0.007429478 | I21: 0.005331445 | J21: -0.004184551 | K21: -0.005036661 | L21: -0.041426364 | M21: -0.0039282271 | N21: -0.005437383 | O21: 0.018025581 | P21: -0.028453565 | Q21: -0.034102824 | R21: -0.043791545 | S21: -0.041060187 | T21: -0.019934768 | U21: -0.03691709 | V21: -0.021484687 | W21: -0.03744678 | X21: -0.014610232 | Y21: -0.023039212 | Z21: -0.031309285 | AA21: -0.031175711 | AB21: 0.020413792 | AC21: -0.004430972 | AD21: -0.058079357 | AE21: -0.092709568 | AF21: -0.072968252 | AG21: -0.070989975 | BQ21: =+A21 -> 781 | BR21: =AJ$2*EXP(AJ$3*$BQ21) -> 0.001113465 | BS21: =AK$2*EXP(AK$3*$BQ21) -> 0.0010616111 | BT21: =AL$2*EXP(AL$3*$BQ21) -> 0.0015072928 | BU21: =AM$2*EXP(AM$3*$BQ21) -> 0.001750082 | BV21: =AN$2*EXP(AN$3*$BQ21) -> 0.0018119871 | BW21: =AO$2*EXP(AO$3*$BQ21) -> 0.0010198359 | BX21: =AP$2*EXP(AP$3*$BQ21) -> 0.00062208168 | BY21: =AQ$2*EXP(AQ$3*$BQ21) -> 0.00026590529 | ... CW21: =BO$2*EXP(BO$3*$BQ21) -> 0.0015024452
A22: 780 | B22: -0.031657038 | C22: -0.038098529 | D22: -0.053160149 | E22: -0.095493895 | F22: -0.086873766 | G22: -0.031214862 | H22: -0.008389829 | I22: 0.003127474 | J22: -0.004672787 | K22: -0.005672289 | L22: -0.041348062 | M22: -0.0051294719 | N22: -0.009329453 | O22: 0.014981015 | P22: -0.033985371 | Q22: -0.032329514 | R22: -0.040502861 | S22: -0.041106247 | T22: -0.020139735 | U22: -0.03991099 | V22: -0.022357524 | W22: -0.032651934 | X22: -0.005315324 | Y22: -0.026509833 | Z22: -0.0338541 | AA22: -0.031042137 | AB22: 0.021599837 | AC22: -0.004495456 | AD22: -0.058698864 | AE22: -0.097195812 | AF22: -0.071293971 | AG22: -0.065628591 | BQ22: =+A22 -> 780 | BR22: =AJ$2*EXP(AJ$3*$BQ22) -> 0.0011334394 | BS22: =AK$2*EXP(AK$3*$BQ22) -> 0.0010808283 | BT22: =AL$2*EXP(AL$3*$BQ22) -> 0.0015343935 | BU22: =AM$2*EXP(AM$3*$BQ22) -> 0.0017831164 | BV22: =AN$2*EXP(AN$3*$BQ22) -> 0.001845138 | BW22: =AO$2*EXP(AO$3*$BQ22) -> 0.0010381204 | BX22: =AP$2*EXP(AP$3*$BQ22) -> 0.00063321588 | BY22: =AQ$2*EXP(AQ$3*$BQ22) -> 0.00027091095 | ... CW22: =BO$2*EXP(BO$3*$BQ22) -> 0.0015300553
A23: 779 | B23: -0.035254324 | C23: -0.038038651 | D23: -0.051444414 | E23: -0.096276915 | F23: -0.085162637 | G23: -0.036164009 | H23: -0.008260861 | I23: 0.003330138 | J23: -0.005149508 | K23: -0.006727063 | L23: -0.041605998 | M23: -0.0033446469 | N23: -0.003288684 | O23: 0.017753827 | P23: -0.034254822 | Q23: -0.031903459 | R23: -0.04345761 | S23: -0.037730049 | T23: -0.019326776 | U23: -0.04117764 | V23: -0.021615958 | W23: -0.034266337 | X23: -0.012917527 | Y23: -0.021300447 | Z23: -0.034160399 | AA23: -0.029116829 | AB23: 0.016369724 | AC23: -0.001660463 | AD23: -0.053500993 | AE23: -0.098570703 | AF23: -0.068986365 | AG23: -0.070801129 | BQ23: =+A23 -> 779 | BR23: =AJ$2*EXP(AJ$3*$BQ23) -> 0.0011537722 | BS23: =AK$2*EXP(AK$3*$BQ23) -> 0.0011003933 | BT23: =AL$2*EXP(AL$3*$BQ23) -> 0.0015619815 | BU23: =AM$2*EXP(AM$3*$BQ23) -> 0.0018167744 | BV23: =AN$2*EXP(AN$3*$BQ23) -> 0.0018788955 | BW23: =AO$2*EXP(AO$3*$BQ23) -> 0.0010567327 | BX23: =AP$2*EXP(AP$3*$BQ23) -> 0.00064454936 | BY23: =AQ$2*EXP(AQ$3*$BQ23) -> 0.00027601085 | ... CW23: =BO$2*EXP(BO$3*$BQ23) -> 0.0015581729
... A452: 350 | B452: 1.8478144 | C452: 1.8972413 | D452: 2.5408124 | E452: 4.2292776 | F452: 3.4545069 | G452: 1.7047865 | H452: 1.04427 | I452: 0.64407771 | J452: 0.62734181 | K452: 0.75691319 | L452: 1.7090908 | M452: 0.42004947 | N452: 0.52190125 | O452: 0.2058145 | P452: 0.35779178 | Q452: 1.5828911 | R452: 1.8081682 | S452: 1.8634517 | T452: 1.7238922 | U452: 1.9620408 | V452: 1.6575152 | W452: 1.7856449 | X452: 0.45161139 | Y452: 1.4320699 | Z452: 1.5808299 | AA452: 1.7675456 | AB452: 0.28123085 | AC452: 0.50514463 | AD452: 1.740057 | AE452: 3.8533497 | AF452: 2.9480196 | AG452: 2.9904156 | BQ452: =+A452 -> 350 | BR452: =AJ$2*EXP(AJ$3*$BQ452) -> 2.3700273 | BS452: =AK$2*EXP(AK$3*$BQ452) -> 2.4209799 | BT452: =AL$2*EXP(AL$3*$BQ452) -> 3.2640865 | BU452: =AM$2*EXP(AM$3*$BQ452) -> 5.5378556 | BV452: =AN$2*EXP(AN$3*$BQ452) -> 4.484822 | BW452: =AO$2*EXP(AO$3*$BQ452) -> 2.1614007 | BX452: =AP$2*EXP(AP$3*$BQ452) -> 1.3014784 | BY452: =AQ$2*EXP(AQ$3*$BQ452) -> 0.82347641 | ... CW452: =BO$2*EXP(BO$3*$BQ452) -> 3.8491356
A453: 349 | B453: 1.8084699 | C453: 1.8513564 | D453: 2.4647811 | E453: 4.1093627 | F453: 3.3279801 | G453: 1.6634845 | H453: 1.0162126 | I453: 0.63523419 | J453: 0.62290392 | K453: 0.73001645 | L453: 1.6768719 | M453: 0.42734813 | N453: 0.5270761 | O453: 0.22668659 | P453: 0.36767395 | Q453: 1.5554577 | R453: 1.7558302 | S453: 1.8123965 | T453: 1.6790689 | U453: 1.9225674 | V453: 1.6279976 | W453: 1.7423899 | X453: 0.45271683 | Y453: 1.3975732 | Z453: 1.5526089 | AA453: 1.738408 | AB453: 0.28238465 | AC453: 0.48112664 | AD453: 1.6903237 | AE453: 3.7147874 | AF453: 2.8535275 | AG453: 2.908286
A454: 348 | B454: 2.4059925 | C454: 2.4740139 | D454: 3.3163154 | E454: 5.6826272 | F454: 4.5717866 | G454: 2.2038559 | H454: 1.3375133 | I454: 0.84395738 | J454: 0.80434578 | K454: 0.96179498 | L454: 2.2203799 | M454: 0.52433092 | N454: 0.68566989 | O454: 0.27079825 | P454: 0.446478 | Q454: 2.0332197 | R454: 2.3178336 | S454: 2.3924831 | T454: 2.2140213 | U454: 2.5395181 | V454: 2.1303948 | W454: 2.2771672 | X454: 0.58298142 | Y454: 1.8131611 | Z454: 2.0241435 | AA454: 2.2861305 | AB454: 0.35875673 | AC454: 0.64372995 | AD454: 2.2207645 | AE454: 5.0842963 | AF454: 3.8323647 | AG454: 3.9068737
A455: 347 | B455: 2.4388816 | C455: 2.500298 | D455: 3.3572766 | E455: 5.7567699 | F455: 4.6332882 | G455: 2.2374589 | H455: 1.3553017 | I455: 0.86289265 | J455: 0.81443753 | K455: 0.97120274 | L455: 2.2510766 | M455: 0.53457098 | N455: 0.68431112 | O455: 0.28301106 | P455: 0.45908232 | Q455: 2.0639578 | R455: 2.3496473 | S455: 2.4214364 | T455: 2.2490108 | U455: 2.570125 | V455: 2.1631296 | W455: 2.3009803 | X455: 0.58382432 | Y455: 1.8469553 | Z455: 2.0529518 | AA455: 2.3268061 | AB455: 0.36423327 | AC455: 0.63434983 | AD455: 2.2381337 | AE455: 5.152624 | AF455: 3.8945641 | AG455: 3.9529475
A456: 346 | B456: 2.4723949 | C456: 2.5457569 | D456: 3.4234417 | E456: 5.8559855 | F456: 4.7069428 | G456: 2.2738509 | H456: 1.3770581 | I456: 0.87674519 | J456: 0.82930569 | K456: 0.98669962 | L456: 2.2814232 | M456: 0.5405726 | N456: 0.69744282 | O456: 0.28620533 | P456: 0.46434007 | Q456: 2.0824233 | R456: 2.3743907 | S456: 2.4541252 | T456: 2.283314 | U456: 2.6028506 | V456: 2.1906551 | W456: 2.3356404 | X456: 0.59981635 | Y456: 1.8811595 | Z456: 2.0830819 | AA456: 2.352959 | AB456: 0.36669518 | AC456: 0.65115943 | AD456: 2.2776601 | AE456: 5.2280748 | AF456: 3.9507804 | AG456: 4.0242622
