Workbook

Sheet ap
A1: Wavelength (nm) | B1: E1 | C1: E2 | D1: E3 | E1: E4 | F1: E5 | G1: E6 | H1: E7 | I1: E8 | J1: E9 | K1: E10 | L1: E14 | M1: E13 | N1: E12 | O1: E24 | P1: E25 | Q1: E27 | R1: E28 | S1: E29 | T1: E30 | U1: E31 | V1: E18 | W1: E21 | X1: E22
A2: 800 | B2: 0.00042783647 | C2: 0.0023707569 | D2: 0.0030419258 | E2: 0.11329719 | F2: 0.021157481 | G2: 0.0060824975 | H2: 0.0065511157 | I2: 0.0070927733 | J2: 0.0065046006 | K2: 0.0020902092 | L2: 0.0051057526 | M2: 0.0025040365 | N2: 0.00097558761 | O2: 0.00084797284 | P2: 0.0022129462 | Q2: 0.0015241184 | R2: 0.0014209609 | S2: 0.0016445104 | T2: 0.0025560746 | U2: 0.0010098118 | V2: 0.0024605117 | W2: 0.003876712 | X2: 0.0053671127
A3: 799 | B3: 0.002707317 | C3: 0.003399409 | D3: 0.0058435515 | E3: 0.15756786 | F3: 0.023539709 | G3: 0.010463472 | H3: 0.0075455254 | I3: 0.0083809591 | J3: 0.0085686771 | K3: 0.0038832267 | L3: 0.0056508484 | M3: 0.0036688496 | N3: 0.0016967779 | O3: 0.0014772214 | P3: 0.0030812675 | Q3: 0.0029880184 | R3: 0.0020119573 | S3: 0.0019156077 | T3: 0.0038412396 | U3: 0.0015568286 | V3: 0.0035131522 | W3: 0.0043163982 | X3: 0.0072096723
A4: 798 | B4: 0.0016889824 | C4: 0.0043382045 | D4: 0.0046093866 | E4: 0.14477362 | F4: 0.021470077 | G4: 0.0089632463 | H4: 0.0088214855 | I4: 0.0084347415 | J4: 0.0069619547 | K4: 0.0036003345 | L4: 0.0050433955 | M4: 0.0032075757 | N4: 0.0020282955 | O4: 0.00170141 | P4: 0.0029273248 | Q4: 0.0036790843 | R4: 0.0021512437 | S4: 0.0020530463 | T4: 0.0044128991 | U4: 0.0018819709 | V4: 0.0036291098 | W4: 0.0061183942 | X4: 0.0077766905
A5: 797 | B5: 0.00039730959 | C5: 0.0022984697 | D5: 0.0029838383 | E5: 0.13986602 | F5: 0.026016915 | G5: 0.0058086721 | H5: 0.0058273041 | I5: 0.0066647436 | J5: 0.0073334871 | K5: 0.0027712111 | L5: 0.0040354881 | M5: 0.0025434547 | N5: 0.00089342206 | O5: 0.00059789957 | P5: 0.0018734634 | Q5: 0.0017608016 | R5: 0.0015292562 | S5: 0.0014495371 | T5: 0.0025794299 | U5: 0.00099317167 | V5: 0.0023818853 | W5: 0.0038289597 | X5: 0.0068882318
A6: 796 | B6: 0.0021589173 | C6: 0.0042305848 | D6: 0.0061489168 | E6: 0.20444712 | F6: 0.039190386 | G6: 0.0096604869 | H6: 0.0097851661 | I6: 0.010054665 | J6: 0.0091889732 | K6: 0.0048755709 | L6: 0.0080496354 | M6: 0.005184045 | N6: 0.002166938 | O6: 0.0015769193 | P6: 0.0034542484 | Q6: 0.0029336578 | R6: 0.0029067785 | S6: 0.0025384886 | T6: 0.005008095 | U6: 0.0023127142 | V6: 0.0041163494 | W6: 0.0064153223 | X6: 0.0083807054
A7: 795 | B7: 0.0035834368 | C7: 0.0037694093 | D7: 0.0073610487 | E7: 0.26140017 | F7: 0.04240061 | G7: 0.0090526114 | H7: 0.0096858188 | I7: 0.011116059 | J7: 0.01044431 | K7: 0.0047836913 | L7: 0.007148928 | M7: 0.0055448394 | N7: 0.0026857954 | O7: 0.0017392683 | P7: 0.0033377679 | Q7: 0.003756076 | R7: 0.0020430373 | S7: 0.0030133221 | T7: 0.0041945427 | U7: 0.0023874108 | V7: 0.0039672466 | W7: 0.0064230408 | X7: 0.0091887691
A8: 794 | B8: 0.003076634 | C8: 0.0048597376 | D8: 0.0054151537 | E8: 0.21521748 | F8: 0.043416703 | G8: 0.007861498 | H8: 0.010860731 | I8: 0.010612309 | J8: 0.0098463026 | K8: 0.004455259 | L8: 0.0061187105 | M8: 0.003907573 | N8: 0.0026561985 | O8: 0.0015255614 | P8: 0.0034772973 | Q8: 0.0038516249 | R8: 0.0026589613 | S8: 0.0023960496 | T8: 0.0039481625 | U8: 0.0023025193 | V8: 0.0049614896 | W8: 0.0067515485 | X8: 0.010144645
A9: 793 | B9: 0.0022807467 | C9: 0.0020773822 | D9: 0.005567458 | E9: 0.18489176 | F9: 0.013375294 | G9: 0.0080904839 | H9: 0.0084033897 | I9: 0.0089690729 | J9: 0.0089482107 | K9: 0.0038992577 | L9: 0.0055982968 | M9: 0.0033703635 | N9: 0.0018234158 | O9: 0.0010068015 | P9: 0.0031715464 | Q9: 0.0019273255 | R9: 0.0012266891 | S9: 0.0013698336 | T9: 0.003860746 | U9: 0.0013148791 | V9: 0.0038596656 | W9: 0.0053565278 | X9: 0.0089242623
A10: 792 | B10: 0.00060411069 | C10: 0.0011266932 | D10: 0.0046660175 | E10: 0.12861858 | F10: 0.032755919 | G10: 0.0057880717 | H10: 0.0066043468 | I10: 0.0075008827 | J10: 0.0088728822 | K10: 0.0036304817 | L10: 0.0050431469 | M10: 0.0023448112 | N10: 0.0016751059 | O10: 0.0015225056 | P10: 0.003065825 | Q10: 0.0018083575 | R10: 0.00067913607 | S10: 0.0018396305 | T10: 0.0030091223 | U10: 0.0010139525 | V10: 0.003253491 | W10: 0.0045224561 | X10: 0.0069476809
A11: 791 | B11: 0.0014640526 | C11: 0.0014295963 | D11: 0.0056072253 | E11: 0.19444203 | F11: 0.032572072 | G11: 0.0090251995 | H11: 0.010827244 | I11: 0.0096645291 | J11: 0.012395799 | K11: 0.0046604861 | L11: 0.0071591467 | M11: 0.0037847017 | N11: 0.0028215133 | O11: 0.0015771184 | P11: 0.0032874742 | Q11: 0.0023025162 | R11: 0.0011093642 | S11: 0.002241507 | T11: 0.0034486696 | U11: 0.0019098175 | V11: 0.0038191895 | W11: 0.005353721 | X11: 0.0083408699
A12: 790 | B12: 0.0031109665 | C12: 0.0023771129 | D12: 0.0062092215 | E12: 0.18703176 | F12: 0.029437521 | G12: 0.0088909005 | H12: 0.011846672 | I12: 0.0097903888 | J12: 0.012434284 | K12: 0.0053188526 | L12: 0.0063847529 | M12: 0.0037661249 | N12: 0.0033182795 | O12: 0.0018281345 | P12: 0.0045990456 | Q12: 0.0035836993 | R12: 0.0013265547 | S12: 0.0029007024 | T12: 0.0047976361 | U12: 0.0028122561 | V12: 0.0033551588 | W12: 0.0064443284 | X12: 0.0089586999
A13: 789 | B13: 0.0025887418 | C13: 0.0025103443 | D13: 0.0056825103 | E13: 0.20819032 | F13: 0.031257301 | G13: 0.010348109 | H13: 0.012131818 | I13: 0.011103989 | J13: 0.012380598 | K13: 0.0048692093 | L13: 0.0076956753 | M13: 0.0049716606 | N13: 0.0036112078 | O13: 0.0015861614 | P13: 0.0044516607 | Q13: 0.0033125348 | R13: 0.0018322097 | S13: 0.002662616 | T13: 0.0039433632 | U13: 0.0021032822 | V13: 0.0045396055 | W13: 0.0069754985 | X13: 0.0088704182
... A402: 400 | B402: 1.7037937 | C402: 1.2166301 | D402: 1.6598346 | E402: 26.07808 | F402: 6.5790476 | G402: 2.4179769 | H402: 2.5815115 | I402: 2.6004772 | J402: 2.9767431 | K402: 1.1321594 | L402: 1.9339177 | M402: 1.5355278 | N402: 0.70944321 | O402: 0.50202693 | P402: 1.035092 | Q402: 0.91542349 | R402: 0.62451924 | S402: 0.72112772 | T402: 1.2444576 | U402: 0.50601356 | V402: 0.90129278 | W402: 1.6429119 | X402: 2.0857119

Sheet ad
A1: Wavelength (nm) | B1: E1 | C1: E2 | D1: E3 | E1: E4 | F1: E5 | G1: E6 | H1: E7 | I1: E8 | J1: E9 | K1: E10 | L1: E14 | M1: E13 | N1: E12 | O1: E24 | P1: E25 | Q1: E27 | R1: E28 | S1: E29 | T1: E30 | U1: E31 | V1: E18 | W1: E21 | X1: E22
A2: 800 | B2: 0.0003576045 | C2: 0.000769606 | D2: 0.0021272754 | E2: 0.039121857 | F2: 0.011591026 | G2: 0.0048983727 | H2: 0.0037674447 | I2: 0.004431659 | J2: 0.0040115697 | K2: 0.0013372943 | L2: 0.0022527392 | M2: 0.0016070566 | N2: 0.00082772128 | O2: 0.00040908197 | P2: 0.00089435092 | Q2: 0.0015142376 | R2: 0.00038811616 | S2: 0.00096683689 | T2: 0.0010431433 | U2: 0.00026926206 | V2: 0.00071121243 | W2: 0.0010302788 | X2: 0.0039141363
A3: 799 | B3: #NUM! | C3: 0.00030198033 | D3: 0.0022691944 | E3: 0.032635133 | F3: 0.012093437 | G3: 0.0034885642 | H3: 0.0036926741 | I3: 0.0036688587 | J3: 0.0030462999 | K3: 0.0010290125 | L3: 0.00071603638 | M3: #NUM! | N3: 0.00059486038 | O3: 0.00022967379 | P3: 0.0011828599 | Q3: 0.00070421344 | R3: #NUM! | S3: 0.0003619882 | T3: 0.00085823729 | U3: 5.7443891e-05 | V3: 0.00073787076 | W3: 0.0020121656 | X3: 0.0033653919
A4: 798 | B4: 0.00072568705 | C4: 0.0012052786 | D4: 0.0021169089 | E4: 0.07487846 | F4: 0.015934784 | G4: 0.0059239091 | H4: 0.0056197493 | I4: 0.0060932555 | J4: 0.0048981438 | K4: 0.0021306172 | L4: 0.0031089364 | M4: 0.00099227578 | N4: 0.0012895826 | O4: 0.00074746437 | P4: 0.0018925658 | Q4: 0.0021907107 | R4: 0.00060126463 | S4: 0.0010643242 | T4: 0.0022519652 | U4: 0.0008353086 | V4: 0.00035656286 | W4: 0.0033545543 | X4: 0.0045923634
A5: 797 | B5: 0.00029274111 | C5: 0.00050885947 | D5: 0.0017240091 | E5: 0.055548115 | F5: 0.015162815 | G5: 0.0045469969 | H5: 0.0051021394 | I5: 0.0061325438 | J5: 0.0034614974 | K5: 0.0016389045 | L5: 0.0021251438 | M5: 0.00077008383 | N5: 0.00091746701 | O5: 0.00030404916 | P5: 0.0021310112 | Q5: 0.0018491945 | R5: 0.00043634769 | S5: 0.00068301491 | T5: 0.0017139245 | U5: 0.0012578068 | V5: 0.00067545701 | W5: 0.002646156 | X5: 0.0055419725
A6: 796 | B6: 0.00019205418 | C6: 0.00081176687 | D6: 0.0023288533 | E6: 0.047396559 | F6: 0.014416983 | G6: 0.0055459858 | H6: 0.0044817146 | I6: 0.0056442425 | J6: 0.0049115666 | K6: 0.0017157887 | L6: 0.0024033051 | M6: 0.00068863119 | N6: 0.0008360892 | O6: 0.00042429381 | P6: 0.0019194824 | Q6: 0.0020954302 | R6: 0.00028276743 | S6: 0.00045528675 | T6: 0.0014598843 | U6: 0.0011988852 | V6: 0.00068973458 | W6: 0.0027670096 | X6: 0.0044335968
A7: 795 | B7: 0.0021707419 | C7: 0.0016739321 | D7: 0.0035353127 | E7: 0.07823335 | F7: 0.022720685 | G7: 0.006493827 | H7: 0.0082579641 | I7: 0.0075422541 | J7: 0.0053635763 | K7: 0.0021717606 | L7: 0.005563001 | M7: 0.0024305442 | N7: 0.0016784373 | O7: 0.0011178079 | P7: 0.0026178092 | Q7: 0.0020661482 | R7: 0.00064446448 | S7: 0.0016776298 | T7: 0.0026980283 | U7: 0.0023164643 | V7: 0.0017080177 | W7: 0.0039069673 | X7: 0.0063577956
A8: 794 | B8: 0.0012962528 | C8: 0.0015316948 | D8: 0.0038518894 | E8: 0.094752682 | F8: 0.024629572 | G8: 0.0074308456 | H8: 0.0077017783 | I8: 0.0090485106 | J8: 0.0060124994 | K8: 0.0031502031 | L8: 0.0039953013 | M8: 0.0027346775 | N8: 0.0013597466 | O8: 0.00094785471 | P8: 0.0026180848 | Q8: 0.0027524726 | R8: 0.0011440818 | S8: 0.0015354722 | T8: 0.0028358379 | U8: 0.0026233659 | V8: 0.0012820871 | W8: 0.0046553798 | X8: 0.0069927718
A9: 793 | B9: 0.0024273661 | C9: 0.0022255077 | D9: 0.0052390891 | E9: 0.11202215 | F9: 0.027644126 | G9: 0.0077155794 | H9: 0.0095575815 | I9: 0.0098620778 | J9: 0.0075395136 | K9: 0.0042861429 | L9: 0.005395338 | M9: 0.0029639492 | N9: 0.0015397644 | O9: 0.0017232405 | P9: 0.0049009955 | Q9: 0.0037739662 | R9: 0.0014878444 | S9: 0.0024318717 | T9: 0.0034051566 | U9: 0.003080871 | V9: 0.0023583923 | W9: 0.0054803085 | X9: 0.0076782766
A10: 792 | B10: 0.0022780649 | C10: 0.0025500161 | D10: 0.0050570245 | E10: 0.10495355 | F10: 0.029735887 | G10: 0.0081823521 | H10: 0.0092831213 | I10: 0.0091573544 | J10: 0.007009207 | K10: 0.0042895999 | L10: 0.0052393561 | M10: 0.0038599298 | N10: 0.002173582 | O10: 0.0012633727 | P10: 0.0034537679 | Q10: 0.0030491682 | R10: 0.0014983077 | S10: 0.0026088415 | T10: 0.0033619904 | U10: 0.0016040285 | V10: 0.0025153953 | W10: 0.0059153771 | X10: 0.0079136591
A11: 791 | B11: 0.0018265138 | C11: 0.0024616969 | D11: 0.0051886039 | E11: 0.12028498 | F11: 0.032788448 | G11: 0.0096555791 | H11: 0.0098894714 | I11: 0.011430482 | J11: 0.0082894528 | K11: 0.0044368076 | L11: 0.0053819436 | M11: 0.0048076541 | N11: 0.0022989222 | O11: 0.0013422338 | P11: 0.0039262255 | Q11: 0.0036959261 | R11: 0.0018531018 | S11: 0.0026116962 | T11: 0.0039468853 | U11: 0.0022891969 | V11: 0.0030729614 | W11: 0.0052119734 | X11: 0.0096704187
A12: 790 | B12: 0.0039480554 | C12: 0.0032990048 | D12: 0.0056700301 | E12: 0.12719887 | F12: 0.032331689 | G12: 0.010788354 | H12: 0.011810062 | I12: 0.011409395 | J12: 0.0091862676 | K12: 0.0051730745 | L12: 0.0078565476 | M12: 0.005147546 | N12: 0.00288806 | O12: 0.0019042719 | P12: 0.0044221758 | Q12: 0.0044948658 | R12: 0.0022141129 | S12: 0.002862861 | T12: 0.0053865218 | U12: 0.0018672524 | V12: 0.0063645333 | W12: 0.0067924592 | X12: 0.010231133
A13: 789 | B13: 0.00082996195 | C13: 0.0025832905 | D13: 0.0049974424 | E13: 0.10628199 | F13: 0.031898984 | G13: 0.00917675 | H13: 0.010367809 | I13: 0.0098323846 | J13: 0.0083133245 | K13: 0.0036544264 | L13: 0.0057151327 | M13: 0.004145449 | N13: 0.0017722113 | O13: 0.0017534746 | P13: 0.0039707873 | Q13: 0.0030756222 | R13: 0.0015967331 | S13: 0.0023509089 | T13: 0.0036557702 | U13: 0.00088503457 | V13: 0.0030618113 | W13: 0.0054599659 | X13: 0.0088509482
A14: 788 | B14: 0.0018621279 | C14: 0.0025653015 | D14: 0.0052438819 | E14: 0.13110776 | F14: 0.033151819 | G14: 0.010120648 | H14: 0.0091864398 | I14: 0.010478514 | J14: 0.0079937559 | K14: 0.0043723851 | L14: 0.0057161571 | M14: 0.0046407206 | N14: 0.00248987 | O14: 0.0012038935 | P14: 0.0039543098 | Q14: 0.0039751148 | R14: 0.0023352258 | S14: 0.002517123 | T14: 0.0048285514 | U14: 0.0015678586 | V14: 0.00390238 | W14: 0.0071678622 | X14: 0.0098263124
A15: 787 | B15: 0.0032692038 | C15: 0.002513696 | D15: 0.0066348383 | E15: 0.12116266 | F15: 0.033452468 | G15: 0.011573561 | H15: 0.0095443686 | I15: 0.010902393 | J15: 0.0090476147 | K15: 0.0034968893 | L15: 0.0056369119 | M15: 0.0046635613 | N15: 0.0029273841 | O15: 0.0017847413 | P15: 0.0047152111 | Q15: 0.0037495303 | R15: 0.0024055948 | S15: 0.0027439849 | T15: 0.0041101342 | U15: 0.0015636821 | V15: 0.0049730441 | W15: 0.006362153 | X15: 0.0099316491
... A402: 400 | B402: 0.50888341 | C402: 0.50848492 | D402: 0.92964141 | E402: 19.733818 | F402: 5.0599901 | G402: 1.7900628 | H402: 1.737313 | I402: 1.7297025 | J402: 1.4406854 | K402: 0.74988385 | L402: 1.0678979 | M402: 0.81914687 | N402: 0.43870466 | O402: 0.31013616 | P402: 0.72575863 | Q402: 0.67794488 | R402: 0.37486371 | S402: 0.41708902 | T402: 0.71597117 | U402: 0.33282841 | V402: 0.62945993 | W402: 1.2084864 | X402: 1.6845474

Sheet aphy
A1: Wavelength (nm) | B1: E1 | C1: E2 | D1: E3 | E1: E4 | F1: E5 | G1: E6 | H1: E7 | I1: E8 | J1: E9 | K1: E10 | L1: E14 | M1: E13 | N1: E12 | O1: E24 | P1: E25 | Q1: E27 | R1: E28 | S1: E29 | T1: E30 | U1: E31 | V1: E18 | W1: E21 | X1: E22 | Z1: B/R | AB1: Si la razón B/R es >3.0 domina el picofitoplancton (< 2 um) | AH1: =+B1 -> E1 | AI1: =+C1 -> E2 | AJ1: =+D1 -> E3 | AK1: =+E1 -> E4 | AL1: =+F1 -> E5 | AM1: =+G1 -> E6 | AN1: =+H1 -> E7 | AO1: =+I1 -> E8 | ... BD1: =+X1 -> E22
A2: 800 | B2: 7.0231972e-05 | C2: 0.0016011509 | D2: 0.00091465043 | E2: 0.074175329 | F2: 0.0095664556 | G2: 0.0011841248 | H2: 0.002783671 | I2: 0.0026611143 | J2: 0.002493031 | K2: 0.00075291483 | L2: 0.0028530134 | M2: 0.00089697984 | N2: 0.00014786633 | O2: 0.00043889086 | P2: 0.0013185953 | Q2: 9.8807696e-06 | R2: 0.0010328448 | S2: 0.00067767346 | T2: 0.0015129313 | U2: 0.00074054975 | V2: 0.0017492992 | W2: 0.0028464332 | X2: 0.0014529764 | Z2: B= | AA2: afito(443) | AB2: Si la razón B/R es <2.5 domina el microfitoplancton (> 20 um) | AG2: B/R = | AH2: =B$359/B$127 -> 1.8120123 | AI2: =C$359/C$127 -> 2.6569637 | AJ2: =D$359/D$127 -> 2.6700438 | AK2: =E$359/E$127 -> 6.8435724 | AL2: =F$359/F$127 -> 7.5618238 | AM2: =G$359/G$127 -> 6.2445381 | AN2: =H$359/H$127 -> 3.8678601 | AO2: =I$359/I$127 -> 3.5390358 | ... BD2: =X$359/X$127 -> 2.6204204
A3: 799 | B3: #NUM! | C3: 0.0030974287 | D3: 0.0035743571 | E3: 0.12493273 | F3: 0.011446273 | G3: 0.0069749082 | H3: 0.0038528514 | I3: 0.0047121005 | J3: 0.0055223771 | K3: 0.0028542142 | L3: 0.0049348121 | M3: #NUM! | N3: 0.0011019175 | O3: 0.0012475476 | P3: 0.0018984076 | Q3: 0.0022838049 | R3: #NUM! | S3: 0.0015536195 | T3: 0.0029830024 | U3: 0.0014993847 | V3: 0.0027752814 | W3: 0.0023042325 | X3: 0.0038442804 | Z3: R= | AA3: afito(675) | AB3: Valores entre 2.5 y 3 domina el nanoplancton | AG3: [ ] Clorofila a =
A4: 798 | B4: 0.00096329539 | C4: 0.0031329259 | D4: 0.0024924778 | E4: 0.069895158 | F4: 0.0055352929 | G4: 0.0030393371 | H4: 0.0032017363 | I4: 0.002341486 | J4: 0.0020638109 | K4: 0.0014697174 | L4: 0.0019344591 | M4: 0.0022152999 | N4: 0.00073871282 | O4: 0.00095394562 | P4: 0.001034759 | Q4: 0.0014883736 | R4: 0.0015499791 | S4: 0.00098872202 | T4: 0.0021609339 | U4: 0.0010466623 | V4: 0.003272547 | W4: 0.0027638399 | X4: 0.0031843271
A5: 797 | B5: 0.00010456848 | C5: 0.0017896102 | D5: 0.0012598291 | E5: 0.084317904 | F5: 0.010854099 | G5: 0.0012616752 | H5: 0.00072516473 | I5: 0.00053219984 | J5: 0.0038719897 | K5: 0.0011323066 | L5: 0.0019103443 | M5: 0.0017733709 | N5: -2.4044956e-05 | O5: 0.00029385041 | P5: -0.00025754784 | Q5: -8.8392937e-05 | R5: 0.0010929085 | S5: 0.00076652218 | T5: 0.00086550544 | U5: -0.00026463508 | V5: 0.0017064283 | W5: 0.0011828037 | X5: 0.0013462593
A6: 796 | B6: 0.0019668631 | C6: 0.003418818 | D6: 0.0038200636 | E6: 0.15705057 | F6: 0.024773403 | G6: 0.004114501 | H6: 0.0053034516 | I6: 0.0044104227 | J6: 0.0042774066 | K6: 0.0031597822 | L6: 0.0056463302 | M6: 0.0044954138 | N6: 0.0013308488 | O6: 0.0011526255 | P6: 0.001534766 | Q6: 0.00083822753 | R6: 0.0026240111 | S6: 0.0020832018 | T6: 0.0035482107 | U6: 0.0011138289 | V6: 0.0034266148 | W6: 0.0036483127 | X6: 0.0039471086
A7: 795 | B7: 0.0014126949 | C7: 0.0020954771 | D7: 0.003825736 | E7: 0.18316682 | F7: 0.019679924 | G7: 0.0025587844 | H7: 0.0014278547 | I7: 0.003573805 | J7: 0.0050807333 | K7: 0.0026119307 | L7: 0.001585927 | M7: 0.0031142952 | N7: 0.0010073581 | O7: 0.00062146038 | P7: 0.00071995869 | Q7: 0.0016899277 | R7: 0.0013985728 | S7: 0.0013356922 | T7: 0.0014965144 | U7: 7.0946547e-05 | V7: 0.0022592289 | W7: 0.0025160735 | X7: 0.0028309735
A8: 794 | B8: 0.0017803812 | C8: 0.0033280428 | D8: 0.0015632643 | E8: 0.1204648 | F8: 0.01878713 | G8: 0.00043065234 | H8: 0.0031589526 | I8: 0.0015637981 | J8: 0.0038338032 | K8: 0.0013050559 | L8: 0.0021234091 | M8: 0.0011728955 | N8: 0.0012964519 | O8: 0.0005777067 | P8: 0.00085921249 | Q8: 0.0010991522 | R8: 0.0015148796 | S8: 0.00086057741 | T8: 0.0011123246 | U8: -0.00032084662 | V8: 0.0036794025 | W8: 0.0020961687 | X8: 0.0031518728
A9: 793 | B9: -0.00014661936 | C9: -0.00014812555 | D9: 0.00032836887 | E9: 0.07286961 | F9: -0.014268832 | G9: 0.00037490449 | H9: -0.0011541918 | I9: -0.00089300496 | J9: 0.0014086972 | K9: -0.0003868852 | L9: 0.00020295876 | M9: 0.00040641429 | N9: 0.00028365139 | O9: -0.00071643901 | P9: -0.0017294491 | Q9: -0.0018466407 | R9: -0.00026115537 | S9: -0.0010620381 | T9: 0.00045558933 | U9: -0.0017659919 | V9: 0.0015012733 | W9: -0.0001237807 | X9: 0.0012459857
A10: 792 | B10: -0.0016739542 | C10: -0.0014233229 | D10: -0.00039100708 | E10: 0.023665026 | F10: 0.0030200323 | G10: -0.0023942804 | H10: -0.0026787746 | I10: -0.0016564717 | J10: 0.0018636752 | K10: -0.00065911818 | L10: -0.0001962092 | M10: -0.0015151186 | N10: -0.00049847615 | O10: 0.0002591329 | P10: -0.00038794295 | Q10: -0.0012408107 | R10: -0.00081917167 | S10: -0.00076921096 | T10: -0.00035286803 | U10: -0.00059007607 | V10: 0.00073809575 | W10: -0.001392921 | X10: -0.00096597827
A11: 791 | B11: -0.00036246124 | C11: -0.0010321005 | D11: 0.00041862144 | E11: 0.074157047 | F11: -0.00021637652 | G11: -0.00063037962 | H11: 0.0009377724 | I11: -0.001765953 | J11: 0.0041063463 | K11: 0.00022367854 | L11: 0.0017772031 | M11: -0.0010229523 | N11: 0.0005225911 | O11: 0.00023488458 | P11: -0.0006387513 | Q11: -0.0013934099 | R11: -0.00074373752 | S11: -0.00037018916 | T11: -0.00049821571 | U11: -0.00037937941 | V11: 0.00074622816 | W11: 0.00014174759 | X11: -0.0013295488
A12: 790 | B12: -0.00083708897 | C12: -0.00092189193 | D12: 0.00053919136 | E12: 0.059832888 | F12: -0.0028941683 | G12: -0.0018974531 | H12: 3.6610097e-05 | I12: -0.0016190065 | J12: 0.0032480162 | K12: 0.00014577808 | L12: -0.0014717947 | M12: -0.0013814211 | N12: 0.00043021951 | O12: -7.6137397e-05 | P12: 0.00017686986 | Q12: -0.00091116648 | R12: -0.00088755822 | S12: 3.7841357e-05 | T12: -0.00058888571 | U12: 0.00094500369 | V12: -0.0030093745 | W12: -0.00034813083 | X12: -0.0012724335
A13: 789 | B13: 0.0017587799 | C13: -7.2946254e-05 | D13: 0.0006850679 | E13: 0.10190833 | F13: -0.00064168268 | G13: 0.0011713592 | H13: 0.0017640092 | I13: 0.0012716047 | J13: 0.0040672735 | K13: 0.0012147829 | L13: 0.0019805426 | M13: 0.00082621155 | N13: 0.0018389965 | O13: -0.00016731318 | P13: 0.00048087338 | Q13: 0.00023691261 | R13: 0.00023547669 | S13: 0.00031170711 | T13: 0.00028759301 | U13: 0.0012182477 | V13: 0.0014777942 | W13: 0.0015155326 | X13: 1.9469957e-05
A14: 788 | B14: 0.0012599635 | C14: 0.00018650505 | D14: 0.0028922107 | E14: 0.10129604 | F14: 0.00031714233 | G14: 0.0021153303 | H14: 0.0027876054 | I14: 0.002378944 | J14: 0.0036678952 | K14: 0.0014635129 | L14: 0.0025318619 | M14: -0.00050623431 | N14: 0.001551059 | O14: 0.0011062671 | P14: 0.0013016946 | Q14: -0.00045948381 | R14: 8.2945723e-05 | S14: 0.00097178164 | T14: 0.00088755568 | U14: 0.00081816434 | V14: 0.00047137326 | W14: -0.00022315105 | X14: -0.00096635598
A15: 787 | B15: -0.00023084267 | C15: 0.00036540151 | D15: 0.00022779264 | E15: 0.0680402 | F15: 0.0037585904 | G15: 0.00049786222 | H15: 0.0023686938 | I15: -0.00014176938 | J15: 0.0026287327 | K15: 0.0021066506 | L15: 0.0010571189 | M15: 0.00074404212 | N15: 0.00049842741 | O15: 0.00035600364 | P15: -0.00012709614 | Q15: -0.00058124544 | R15: -0.0010464389 | S15: 0.00047900886 | T15: 0.00041230591 | U15: 0.00071998745 | V15: -0.0011113099 | W15: 0.00067628623 | X15: -0.00064737712
... A402: 400 | B402: 1.1949102 | C402: 0.70814521 | D402: 0.73019314 | E402: 6.3442624 | F402: 1.5190576 | G402: 0.62791407 | H402: 0.84419851 | I402: 0.87077471 | J402: 1.5360576 | K402: 0.38227558 | L402: 0.8660198 | M402: 0.71638097 | N402: 0.27073856 | O402: 0.19189077 | P402: 0.30933333 | Q402: 0.23747861 | R402: 0.24965553 | S402: 0.3040387 | T402: 0.52848643 | U402: 0.17318515 | V402: 0.27183285 | W402: 0.43442551 | X402: 0.40116454

Sheet aCDOM
A1: Wavelength (nm) | B1: E1 | C1: E2 | D1: E3 | E1: E4 | F1: E5 | G1: E6 | H1: E7 | I1: E8 | J1: E9 | K1: E10 | L1: E14 | M1: E13 | N1: E12 | O1: E24 | P1: E25 | Q1: E27 | R1: E28 | S1: E29 | T1: E30 | U1: E31 | V1: E18 | W1: E21 | X1: E22 | Y1: MODELADO | Z1: Wavelength (nm) | AA1: E1 | AB1: E2 | AC1: E3 | AD1: E4 | AE1: E5 | AF1: E6 | AG1: E7 | AH1: E8 | AI1: E9 | AJ1: E10 | AK1: E14 | AL1: E13 | AM1: E12 | AN1: E24 | AO1: E25 | AP1: E27 | AQ1: E28 | AR1: E29 | AS1: E30 | AT1: E31 | AU1: E18 | AV1: E21 | AW1: E22
A2: 800 | B2: 0.060432553 | C2: 0.016816543 | D2: 0.044997283 | E2: 0.035785815 | F2: 0.041340768 | G2: 0.031568552 | H2: 0.12771485 | I2: 0.041333903 | J2: 0.023010828 | K2: 0.028014989 | L2: 0.024172815 | M2: 0.011386504 | N2: 0.0078470096 | O2: 0.0054863171 | P2: 0.034838999 | Q2: 0.019091442 | R2: 0.016891697 | S2: 0.028005035 | T2: 0.11995844 | U2: 0.016644956 | V2: 0.020936686 | W2: 0.028529062 | X2: 0.026676609 | Z2: 800 | AA2: 0.0029397836 | AB2: 0.0014239833 | AC2: 0.0021958752 | AD2: 0.0040146645 | AE2: 0.0028539762 | AF2: 0.0026066533 | AG2: 0.0054790421 | AH2: 0.0020068975 | AI2: 0.001334951 | AJ2: 0.00091884196 | AK2: 0.0016950444 | AL2: 0.00077441883 | AM2: 0.00064316205 | AN2: 0.00024293155 | AO2: 0.0014337782 | AP2: 0.0013855378 | AQ2: 0.00073342128 | AR2: 0.0017378415 | AS2: 0.0054129939 | AT2: 0.001143562 | AU2: 0.0017730696 | AV2: 0.0023453667 | AW2: 0.0020153651
A3: 799 | B3: 0.059289098 | C3: 0.0085302705 | D3: 0.045193922 | E3: 0.040349682 | F3: 0.03725357 | G3: 0.035240167 | H3: 0.1246184 | I3: 0.039683926 | J3: 0.023523874 | K3: 0.034136521 | L3: 0.026645726 | M3: 0.011890626 | N3: 0.01344692 | O3: 0.0050916682 | P3: 0.037270727 | Q3: 0.019882458 | R3: 0.0075443309 | S3: 0.032651609 | T3: 0.11209461 | U3: 0.022242464 | V3: 0.026868445 | W3: 0.026756913 | X3: 0.023704383 | Z3: 799 | AA3: 0.0029827508 | AB3: 0.0014470516 | AC3: 0.0022303548 | AD3: 0.0040773358 | AE3: 0.0028991952 | AF3: 0.002649225 | AG3: 0.0055570105 | AH3: 0.0020393681 | AI3: 0.0013572283 | AJ3: 0.00093350296 | AK3: 0.0017222799 | AL3: 0.00078756259 | AM3: 0.00065404536 | AN3: 0.00024726478 | AO3: 0.0014568157 | AP3: 0.0014078565 | AQ3: 0.00074551128 | AR3: 0.0017632767 | AS3: 0.0054831093 | AT3: 0.001161553 | AU3: 0.0018014327 | AV3: 0.0023827655 | AW3: 0.0020480751
A4: 798 | B4: 0.057676182 | C4: 0.015678923 | D4: 0.040047346 | E4: 0.044126652 | F4: 0.04122203 | G4: 0.033106314 | H4: 0.12384591 | I4: 0.036193849 | J4: 0.027060623 | K4: 0.035769685 | L4: 0.02821403 | M4: 0.007209051 | N4: 0.012620214 | O4: 0.0054485687 | P4: 0.031533549 | Q4: 0.021636761 | R4: 0.013560168 | S4: 0.033717164 | T4: 0.11410321 | U4: 0.021511503 | V4: 0.027087048 | W4: 0.031945014 | X4: 0.027805996 | Z4: 798 | AA4: 0.003026346 | AB4: 0.0014704935 | AC4: 0.0022653758 | AD4: 0.0041409854 | AE4: 0.0029451307 | AF4: 0.002692492 | AG4: 0.0056360884 | AH4: 0.002072364 | AI4: 0.0013798773 | AJ4: 0.00094839789 | AK4: 0.001749953 | AL4: 0.00080092944 | AM4: 0.00066511284 | AN4: 0.00025167529 | AO4: 0.0014802234 | AP4: 0.0014305348 | AQ4: 0.00075780058 | AR4: 0.0017890841 | AS4: 0.005554133 | AT4: 0.0011798271 | AU4: 0.0018302495 | AV4: 0.0024207606 | AW4: 0.002081316
A5: 797 | B5: 0.068067139 | C5: 0.023815572 | D5: 0.049891971 | E5: 0.041528484 | F5: 0.039157497 | G5: 0.036819454 | H5: 0.13244756 | I5: 0.038039779 | J5: 0.030191395 | K5: 0.038025022 | L5: 0.027773392 | M5: 0.012450686 | N5: 0.017262668 | O5: 0.0091884772 | P5: 0.037664004 | Q5: 0.026619642 | R5: 0.019586296 | S5: 0.037863731 | T5: 0.11962487 | U5: 0.026472764 | V5: 0.033064104 | W5: 0.039461891 | X5: 0.035416902 | Z5: 797 | AA5: 0.0030705784 | AB5: 0.0014943153 | AC5: 0.0023009468 | AD5: 0.0042056286 | AE5: 0.0029917939 | AF5: 0.0027364656 | AG5: 0.0057162916 | AH5: 0.0021058938 | AI5: 0.0014029043 | AJ5: 0.00096353049 | AK5: 0.0017780708 | AL5: 0.00081452315 | AM5: 0.0006763676 | AN5: 0.00025616448 | AO5: 0.0015040072 | AP5: 0.0014535784 | AQ5: 0.00077029247 | AR5: 0.0018152693 | AS5: 0.0056260767 | AT5: 0.0011983887 | AU5: 0.0018595272 | AV5: 0.0024593615 | AW5: 0.0021150964
A6: 796 | B6: 0.056655583 | C6: 0.01506121 | D6: 0.043461926 | E6: 0.039443704 | F6: 0.040849002 | G6: 0.033191764 | H6: 0.12257857 | I6: 0.039519547 | J6: 0.023326207 | K6: 0.036466672 | L6: 0.03265607 | M6: 0.013512125 | N6: 0.010171326 | O6: 0.0013932851 | P6: 0.036643406 | Q6: 0.018761995 | R6: 0.012804844 | S6: 0.031230184 | T6: 0.12125735 | U6: 0.028108331 | V6: 0.026577435 | W6: 0.038460169 | X6: 0.030798814 | Z6: 796 | AA6: 0.0031154574 | AB6: 0.0015185229 | AC6: 0.0023370762 | AD6: 0.004271281 | AE6: 0.0030391965 | AF6: 0.0027811573 | AG6: 0.0057976362 | AH6: 0.0021399661 | AI6: 0.0014263156 | AJ6: 0.00097890454 | AK6: 0.0018066403 | AL6: 0.00082834758 | AM6: 0.0006878128 | AN6: 0.00026073374 | AO6: 0.0015281732 | AP6: 0.0014769931 | AQ6: 0.00078299027 | AR6: 0.0018418377 | AS6: 0.0056989522 | AT6: 0.0012172424 | AU6: 0.0018892733 | AV6: 0.002498578 | AW6: 0.002149425
A7: 795 | B7: 0.062207445 | C7: 0.026683472 | D7: 0.047333267 | E7: 0.038154057 | F7: 0.04174331 | G7: 0.039378843 | H7: 0.1320361 | I7: 0.041206243 | J7: 0.02653179 | K7: 0.03630229 | L7: 0.020591452 | M7: 0.012324399 | N7: 0.021802513 | O7: 0.0051150045 | P7: 0.042484908 | Q7: 0.026288823 | R7: 0.019376274 | S7: 0.044585817 | T7: 0.11598517 | U7: 0.025133358 | V7: 0.027708533 | W7: 0.042130753 | X7: 0.030866075 | Z7: 795 | AA7: 0.0031609922 | AB7: 0.0015431227 | AC7: 0.002373773 | AD7: 0.0043379582 | AE7: 0.0030873502 | AF7: 0.002826579 | AG7: 0.0058801383 | AH7: 0.0021745897 | AI7: 0.0014501175 | AJ7: 0.0009945239 | AK7: 0.0018356689 | AL7: 0.00084240665 | AM7: 0.00069945168 | AN7: 0.0002653845 | AO7: 0.0015527275 | AP7: 0.0015007851 | AQ7: 0.00079589739 | AR7: 0.001868795 | AS7: 0.0057727718 | AT7: 0.0012363926 | AU7: 0.0019194953 | AV7: 0.0025384198 | AW7: 0.0021843108
A8: 794 | B8: 0.060247238 | C8: 0.022801835 | D8: 0.048702874 | E8: 0.037617676 | F8: 0.05044654 | G8: 0.034251828 | H8: 0.1338103 | I8: 0.036552808 | J8: 0.020678619 | K8: 0.048149335 | L8: 0.03587607 | M8: 0.015023116 | N8: 0.019851913 | O8: 0.005159959 | P8: 0.038818783 | Q8: 0.02595972 | R8: 0.019618214 | S8: 0.041204528 | T8: 0.11968459 | U8: 0.027125482 | V8: 0.024426763 | W8: 0.045336683 | X8: 0.026049975 | Z8: 794 | AA8: 0.0032071926 | AB8: 0.001568121 | AC8: 0.002411046 | AD8: 0.0044056763 | AE8: 0.0031362668 | AF8: 0.0028727425 | AG8: 0.0059638144 | AH8: 0.0022097734 | AI8: 0.0014743166 | AJ8: 0.0010103925 | AK8: 0.0018651639 | AL8: 0.00085670433 | AM8: 0.0007112875 | AN8: 0.00027011822 | AO8: 0.0015776763 | AP8: 0.0015249603 | AQ8: 0.00080901727 | AR8: 0.0018961468 | AS8: 0.0058475475 | AT8: 0.0012558441 | AU8: 0.0019502007 | AV8: 0.002578897 | AW8: 0.0022197629
A9: 793 | B9: 0.070050339 | C9: 0.024551677 | D9: 0.045621859 | E9: 0.040268349 | F9: 0.05199391 | G9: 0.036457061 | H9: 0.13003162 | I9: 0.031345488 | J9: 0.029845821 | K9: 0.040086467 | L9: 0.031115904 | M9: 0.011649032 | N9: 0.017871457 | O9: 0.014196411 | P9: 0.043710383 | Q9: 0.024968976 | R9: 0.012286648 | S9: 0.045582395 | T9: 0.12476219 | U9: 0.027911349 | V9: 0.029277523 | W9: 0.041601235 | X9: 0.025064724 | Z9: 793 | AA9: 0.0032540682 | AB9: 0.0015935243 | AC9: 0.0024489042 | AD9: 0.0044744515 | AE9: 0.0031859585 | AF9: 0.0029196599 | AG9: 0.0060486813 | AH9: 0.0022455264 | AI9: 0.0014989196 | AJ9: 0.0010265143 | AK9: 0.0018951329 | AL9: 0.00087124467 | AM9: 0.00072332361 | AN9: 0.00027493638 | AO9: 0.0016030259 | AP9: 0.0015495249 | AQ9: 0.00082235343 | AR9: 0.001923899 | AS9: 0.0059232918 | AT9: 0.0012756016 | AU9: 0.0019813972 | AV9: 0.0026200195 | AW9: 0.0022557903
A10: 792 | B10: 0.064738696 | C10: 0.020242103 | D10: 0.047426266 | E10: 0.038540813 | F10: 0.043330832 | G10: 0.030686252 | H10: 0.12500035 | I10: 0.027946352 | J10: 0.031679398 | K10: 0.040504452 | L10: 0.029011563 | M10: 0.011219721 | N10: 0.013604779 | O10: 0.0080034984 | P10: 0.038968407 | Q10: 0.032442957 | R10: 0.021636761 | S10: 0.038366138 | T10: 0.12549418 | U10: 0.029615207 | V10: 0.033187646 | W10: 0.038053505 | X10: 0.023685507 | Z10: 792 | AA10: 0.0033016289 | AB10: 0.0016193391 | AC10: 0.0024873569 | AD10: 0.0045443003 | AE10: 0.0032364375 | AF10: 0.0029673436 | AG10: 0.0061347558 | AH10: 0.0022818579 | AI10: 0.0015239331 | AJ10: 0.0010428933 | AK10: 0.0019255833 | AL10: 0.00088603181 | AM10: 0.00073556338 | AN10: 0.00027984048 | AO10: 0.0016287829 | AP10: 0.0015744852 | AQ10: 0.00083590943 | AR10: 0.0019520573 | AS10: 0.0060000172 | AT10: 0.00129567 | AU10: 0.0020130929 | AV10: 0.0026617978 | AW10: 0.0022924024
A11: 791 | B11: 0.069602841 | C11: 0.028903808 | D11: 0.052838805 | E11: 0.040670549 | F11: 0.054853234 | G11: 0.038850355 | H11: 0.13929182 | I11: 0.035139618 | J11: 0.031424762 | K11: 0.038816724 | L11: 0.038743972 | M11: 0.017266786 | N11: 0.019686505 | O11: 0.012627764 | P11: 0.039970474 | Q11: 0.026716762 | R11: 0.021358446 | S11: 0.047890581 | T11: 0.13061844 | U11: 0.03552912 | V11: 0.034662948 | W11: 0.044158224 | X11: 0.023438423 | Z11: 791 | AA11: 0.0033498848 | AB11: 0.0016455721 | AC11: 0.0025264134 | AD11: 0.0046152396 | AE11: 0.0032877163 | AF11: 0.0030158061 | AG11: 0.0062220553 | AH11: 0.0023187772 | AI11: 0.0015493641 | AJ11: 0.0010595336 | AK11: 0.0019565231 | AL11: 0.00090106991 | AM11: 0.00074801027 | AN11: 0.00028483206 | AO11: 0.0016549537 | AP11: 0.0015998476 | AQ11: 0.00084968889 | AR11: 0.0019806277 | AS11: 0.0060777365 | AT11: 0.0013160541 | AU11: 0.0020452955 | AV11: 0.0027042423 | AW11: 0.0023296088
A12: 790 | B12: 0.065222572 | C12: 0.021035178 | D12: 0.04524986 | E12: 0.034826645 | F12: 0.050914973 | G12: 0.03436885 | H12: 0.12766029 | I12: 0.037650278 | J12: 0.034678738 | K12: 0.037467023 | L12: 0.032955661 | M12: 0.013137378 | N12: 0.012132222 | O12: 0.0078573063 | P12: 0.03093677 | Q12: 0.025296366 | R12: 0.015087978 | S12: 0.039878506 | T12: 0.12643928 | U12: 0.028345464 | V12: 0.024901717 | W12: 0.030780627 | X12: 0.025127869 | Z12: 790 | AA12: 0.003398846 | AB12: 0.00167223 | AC12: 0.0025660832 | AD12: 0.0046872862 | AE12: 0.0033398075 | AF12: 0.00306506 | AG12: 0.006310597 | AH12: 0.0023562939 | AI12: 0.0015752194 | AJ12: 0.0010764395 | AK12: 0.0019879599 | AL12: 0.00091636325 | AM12: 0.00076066779 | AN12: 0.00028991267 | AO12: 0.001681545 | AP12: 0.0016256185 | AQ12: 0.00086369549 | AR12: 0.0020096164 | AS12: 0.0061564625 | AT12: 0.0013367589 | AU12: 0.0020780133 | AV12: 0.0027473636 | AW12: 0.0023674191
A13: 789 | B13: 0.067606599 | C13: 0.026245241 | D13: 0.058410915 | E13: 0.042453679 | F13: 0.055299016 | G13: 0.034124852 | H13: 0.13665865 | I13: 0.032034583 | J13: 0.036108053 | K13: 0.029605254 | L13: 0.033097049 | M13: 0.013484325 | N13: 0.022486803 | O13: 0.011101669 | P13: 0.040655105 | Q13: 0.025297052 | R13: 0.016386545 | S13: 0.046431407 | T13: 0.12636481 | U13: 0.034594657 | V13: 0.029750417 | W13: 0.041179475 | X13: 0.028576764 | Z13: 789 | AA13: 0.0034485228 | AB13: 0.0016993199 | AC13: 0.0026063758 | AD13: 0.0047604575 | AE13: 0.0033927241 | AF13: 0.0031151184 | AG13: 0.0064003987 | AH13: 0.0023944175 | AI13: 0.0016015062 | AJ13: 0.0010936151 | AK13: 0.0020199019 | AL13: 0.00093191616 | AM13: 0.00077353948 | AN13: 0.0002950839 | AO13: 0.0017085636 | AP13: 0.0016518045 | AQ13: 0.00087793299 | AR13: 0.0020390292 | AS13: 0.0062362082 | AT13: 0.0013577894 | AU13: 0.0021112544 | AV13: 0.0027911725 | AW13: 0.002405843
... A452: 350 | B452: 1.7452451 | C452: 1.6316806 | D452: 2.0268493 | E452: 3.514164 | F452: 2.7728027 | G452: 3.1531606 | H452: 2.700694 | I452: 2.2810134 | J452: 1.8926605 | K452: 0.95989282 | L452: 1.844308 | M452: 1.2828809 | N452: 1.0390227 | O452: 0.60509784 | P452: 1.5808422 | Q452: 1.5445097 | R452: 0.96874876 | S452: 1.0280806 | T452: 1.5167456 | U452: 1.0839568 | V452: 1.8728885 | W452: 2.3977995 | X452: 2.3379199 | Z452: 350 | AA452: 2.0139152 | AB452: 1.9683641 | AC452: 2.4347045 | AD452: 4.274634 | AE452: 3.3701522 | AF452: 3.8202347 | AG452: 3.1634873 | AH452: 2.749268 | AI452: 2.2902004 | AJ452: 1.1400859 | AK452: 2.2099142 | AL452: 1.5069719 | AM452: 1.2237087 | AN452: 0.69299615 | AO452: 1.8692883 | AP452: 1.8392044 | AQ452: 1.1499399 | AR452: 1.2012811 | AS452: 1.7727767 | AT452: 1.2851721 | AU452: 2.2399577 | AV452: 2.8970312 | AW452: 2.8236916
A453: 349 | B453: 1.6915037 | C453: 1.5991138 | D453: 1.9809337 | E453: 3.3693011 | F453: 2.6705503 | G453: 3.005027 | H453: 2.6026376 | I453: 2.2235246 | J453: 1.8625494 | K453: 0.93786467 | L453: 1.7724189 | M453: 1.2369735 | N453: 1.0089454 | O453: 0.57273124 | P453: 1.5101031 | Q453: 1.4766025 | R453: 0.94669933 | S453: 1.0021566 | T453: 1.4652771 | U453: 1.0500284 | V453: 1.7965839 | W453: 2.3053712 | X453: 2.2468632
A454: 348 | B454: 2.3177412 | C454: 2.1893682 | D454: 2.7244484 | E454: 4.7781542 | F454: 3.7442561 | G454: 4.2570758 | H454: 3.5613631 | I454: 3.0780382 | J454: 2.5477263 | K454: 1.3154055 | L454: 2.4877907 | M454: 1.6979598 | N454: 1.3921323 | O454: 0.79741824 | P454: 2.0885176 | Q454: 2.0642673 | R454: 1.3087651 | S454: 1.3717368 | T454: 1.989254 | U454: 1.4498524 | V454: 2.5202213 | W454: 3.2393251 | X454: 3.1477471
A455: 347 | B455: 2.3580422 | C455: 2.1934008 | D455: 2.7039963 | E455: 4.801757 | F455: 3.7740364 | G455: 4.2697499 | H455: 3.6076459 | I455: 3.0955174 | J455: 2.5800732 | K455: 1.3013049 | L455: 2.4726663 | M455: 1.6992437 | N455: 1.4299357 | O455: 0.82417635 | P455: 2.1029066 | Q455: 2.0632882 | R455: 1.3040437 | S455: 1.3802132 | T455: 2.0347293 | U455: 1.4155007 | V455: 2.5329777 | W455: 3.2463467 | X455: 3.1326152
A456: 346 | B456: 2.417065 | C456: 2.282312 | D456: 2.8070789 | E456: 4.8863346 | F456: 3.8653443 | G456: 4.3674861 | H456: 3.6656707 | I456: 3.1894815 | J456: 2.6271364 | K456: 1.3088194 | L456: 2.5236029 | M456: 1.731596 | N456: 1.4367377 | O456: 0.82403685 | P456: 2.1424364 | Q456: 2.1078157 | R456: 1.3215717 | S456: 1.4044979 | T456: 2.0659056 | U456: 1.5043944 | V456: 2.5835396 | W456: 3.2901666 | X456: 3.247263
A457: 345 | B457: 2.4357027 | C457: 2.3068678 | D457: 2.8380976 | E457: 4.9809898 | F457: 3.899953 | G457: 4.4342982 | H457: 3.7274986 | I457: 3.2161704 | J457: 2.6946363 | K457: 1.3462095 | L457: 2.5866796 | M457: 1.743535 | N457: 1.4730211 | O457: 0.85298425 | P457: 2.167727 | Q457: 2.1121156 | R457: 1.3650226 | S457: 1.3969182 | T457: 2.0688322 | U457: 1.5292368 | V457: 2.6170725 | W457: 3.3997773 | X457: 3.2710463
A458: 344 | B458: 2.4471438 | C458: 2.3212632 | D458: 2.8492662 | E458: 5.0370709 | F458: 3.9767392 | G458: 4.4752639 | H458: 3.7290292 | I458: 3.2648671 | J458: 2.7144933 | K458: 1.3445794 | L458: 2.5992038 | M458: 1.7644559 | N458: 1.4782737 | O458: 0.85278229 | P458: 2.2262141 | Q458: 2.1604894 | R458: 1.3869535 | S458: 1.4108058 | T458: 2.1006852 | U458: 1.5058972 | V458: 2.6270719 | W458: 3.4086532 | X458: 3.3134145
A459: 343 | B459: 2.5477552 | C459: 2.3746504 | D459: 2.9582596 | E459: 5.1481367 | F459: 4.0073359 | G459: 4.5764216 | H459: 3.8553971 | I459: 3.307641 | J459: 2.7801373 | K459: 1.3816899 | L459: 2.6694953 | M459: 1.8198421 | N459: 1.5317117 | O459: 0.89777854 | P459: 2.1934633 | Q459: 2.2053268 | R459: 1.4175876 | S459: 1.4999479 | T459: 2.123577 | U459: 1.5733833 | V459: 2.7017338 | W459: 3.4856088 | X459: 3.3768478
A460: 342 | B460: 2.555887 | C460: 2.3915315 | D460: 3.0166008 | E460: 5.2277063 | F460: 4.0705519 | G460: 4.6275352 | H460: 3.860985 | I460: 3.3737026 | J460: 2.80526 | K460: 1.4119094 | L460: 2.7088073 | M460: 1.8511958 | N460: 1.5519851 | O460: 0.89759992 | P460: 2.2729879 | Q460: 2.2380789 | R460: 1.4516939 | S460: 1.4663114 | T460: 2.170484 | U460: 1.5408858 | V460: 2.7182353 | W460: 3.5362568 | X460: 3.4543515
A461: 341 | B461: 2.620937 | C461: 2.4673811 | D461: 3.0452246 | E461: 5.3364649 | F461: 4.1913964 | G461: 4.7270728 | H461: 3.9466645 | I461: 3.480559 | J461: 2.874019 | K461: 1.4484856 | L461: 2.7788013 | M461: 1.8725399 | N461: 1.5890499 | O461: 0.96940834 | P461: 2.2958893 | Q461: 2.3048901 | R461: 1.489175 | S461: 1.5303359 | T461: 2.1968343 | U461: 1.607001 | V461: 2.7866995 | W461: 3.6266594 | X461: 3.509642
A462: 340 | B462: 2.6658146 | C462: 2.5166168 | D462: 3.1160466 | E462: 5.3878465 | F462: 4.2504108 | G462: 4.8497439 | H462: 3.9987179 | I462: 3.5173313 | J462: 2.9520902 | K462: 1.4734935 | L462: 2.8046844 | M462: 1.9508804 | N462: 1.6084246 | O462: 0.95679859 | P462: 2.3636982 | Q462: 2.3344028 | R462: 1.4972037 | S462: 1.5456314 | T462: 2.2366831 | U462: 1.6791287 | V462: 2.8491305 | W462: 3.6520325 | X462: 3.5684436
A463: 339 | B463: 2.7113202 | C463: 2.546733 | D463: 3.1682924 | E463: 5.5511244 | F463: 4.3014462 | G463: 4.9144657 | H463: 4.0749337 | I463: 3.5623121 | J463: 2.9992412 | K463: 1.490053 | L463: 2.8614659 | M463: 1.9944196 | N463: 1.6733936 | O463: 0.98132591 | P463: 2.4095191 | Q463: 2.3792793 | R463: 1.5069876 | S463: 1.5750366 | T463: 2.2607629 | U463: 1.6874802 | V463: 2.8755868 | W463: 3.7438558 | X463: 3.6329143
A464: 338 | B464: 2.7555218 | C464: 2.5606945 | D464: 3.226931 | E464: 5.5714206 | F464: 4.4073086 | G464: 4.9936821 | H464: 4.1708077 | I464: 3.5940991 | J464: 3.043204 | K464: 1.4923456 | L464: 2.8603229 | M464: 1.9631079 | N464: 1.6623501 | O464: 0.97588231 | P464: 2.4343119 | Q464: 2.4494654 | R464: 1.5308895 | S464: 1.5696455 | T464: 2.2995949 | U464: 1.7209751 | V464: 2.9270661 | W464: 3.8094214 | X464: 3.6964455
... A552: 250 | B552: 2.50474 | C552: 3.4658022 | D552: 6.7822003 | E552: 11.300415 | F552: 7.0882289 | G552: 9.5019977 | H552: 5.6500235 | I552: 7.4646493 | J552: 6.2691803 | K552: 4.8862121 | L552: 7.5678541 | M552: 2.5337423 | N552: 1.9767082 | O552: 1.4360421 | P552: 2.4759189 | Q552: 2.4948402 | R552: 1.4318801 | S552: 2.067059 | T552: 2.9324004 | U552: 1.791647 | V552: 2.8264119 | W552: 3.1469417 | X552: 3.7605747

Sheet ax(443)
B1: =+ap!B1 -> E1 | C1: =+ap!C1 -> E2 | D1: =+ap!D1 -> E3 | E1: =+ap!E1 -> E4 | F1: =+ap!F1 -> E5 | G1: =+ap!G1 -> E6 | H1: =+ap!H1 -> E7 | I1: =+ap!I1 -> E8 | ... X1: =+ap!X1 -> E22
A2: ap (443) | B2: =+ap!B359 -> 1.5301191 | C2: =+ap!C359 -> 0.78163196 | D2: =+ap!D359 -> 1.102331 | E2: =+ap!E359 -> 14.816519 | F2: =+ap!F359 -> 3.6807497 | G2: =+ap!G359 -> 1.3933413 | H2: =+ap!H359 -> 1.5832498 | I2: =+ap!I359 -> 1.6177305 | ... X2: =+ap!X359 -> 1.340264
A3: ad (443) | B3: =+ad!B359 -> 0.29546317 | C3: =+ad!C359 -> 0.30022203 | D3: =+ad!D359 -> 0.5504879 | E3: =+ad!E359 -> 11.393713 | F3: =+ad!F359 -> 2.9099836 | G3: =+ad!G359 -> 1.0204334 | H3: =+ad!H359 -> 0.9985709 | I3: =+ad!I359 -> 1.0209402 | ... X3: =+ad!X359 -> 0.95867111
A4: aphy (443) | B4: =+aphy!B359 -> 1.2346559 | C4: =+aphy!C359 -> 0.48140993 | D4: =+aphy!D359 -> 0.55184314 | E4: =+aphy!E359 -> 3.422806 | F4: =+aphy!F359 -> 0.77076605 | G4: =+aphy!G359 -> 0.37290797 | H4: =+aphy!H359 -> 0.58467891 | I4: =+aphy!I359 -> 0.59679025 | ... X4: =+aphy!X359 -> 0.38159293
A5: aCDOM (443) | B5: =+aCDOM!B359 -> 0.49769038 | C5: =+aCDOM!C359 -> 0.40616354 | D5: =+aCDOM!D359 -> 0.53318209 | E5: =+aCDOM!E359 -> 0.95306529 | F5: =+aCDOM!F359 -> 0.72729335 | G5: =+aCDOM!G359 -> 0.79527812 | H5: =+aCDOM!H359 -> 0.80303333 | I5: =+aCDOM!I359 -> 0.57355185 | ... L5: =+aCDOM!L359 -> 0.46737372 | N5: =+aCDOM!M359 -> 0.28971868 | O5: =+aCDOM!N359 -> 0.23813933 | P5: =+aCDOM!O359 -> 0.12327564 | Q5: =+aCDOM!P359 -> 0.39641826 | R5: =+aCDOM!Q359 -> 0.38379033 | S5: =+aCDOM!R359 -> 0.2433252 | T5: =+aCDOM!S359 -> 0.28794465 | U5: =+aCDOM!T359 -> 0.49724854 | ... X5: =+aCDOM!W359 -> 0.62468954
A6: aCDOM-Mod (443) | B6: =+aCDOM!AA359 -> 0.52238557 | C6: =+aCDOM!AB359 -> 0.44161925 | D6: =+aCDOM!AC359 -> 0.57171503 | E6: =+aCDOM!AD359 -> 1.0122023 | F6: =+aCDOM!AE359 -> 0.78113906 | G6: =+aCDOM!AF359 -> 0.84680221 | H6: =+aCDOM!AG359 -> 0.85008835 | I6: =+aCDOM!AH359 -> 0.61797005 | ... X6: =+aCDOM!AW359 -> 0.63175418
A7: TOTAL | B7: =SUM(B3:B5) -> 2.0278094 | C7: =SUM(C3:C5) -> 1.1877955 | D7: =SUM(D3:D5) -> 1.6355131 | E7: =SUM(E3:E5) -> 15.769585 | F7: =SUM(F3:F5) -> 4.408043 | G7: =SUM(G3:G5) -> 2.1886195 | H7: =SUM(H3:H5) -> 2.3862831 | I7: =SUM(I3:I5) -> 2.1912823 | ... X7: =SUM(X3:X5) -> 1.9649536
A8: TOTAL-Mod | B8: =SUM(B3:B4,B6) -> 2.0525046 | C8: =SUM(C3:C4,C6) -> 1.2232512 | D8: =SUM(D3:D4,D6) -> 1.6740461 | E8: =SUM(E3:E4,E6) -> 15.828722 | F8: =SUM(F3:F4,F6) -> 4.4618887 | G8: =SUM(G3:G4,G6) -> 2.2401435 | H8: =SUM(H3:H4,H6) -> 2.4333382 | I8: =SUM(I3:I4,I6) -> 2.2357005 | ... X8: =SUM(X3:X4,X6) -> 1.9720182
B9: =+B1 -> E1 | C9: =+C1 -> E2 | D9: =+D1 -> E3 | E9: =+E1 -> E4 | F9: =+F1 -> E5 | G9: =+G1 -> E6 | H9: =+H1 -> E7 | I9: =+I1 -> E8 | ... X9: =+X1 -> E22
A10: ad (443) | B10: =(B3*100)/B$7 -> 14.570559 | C10: =(C3*100)/C$7 -> 25.275566 | D10: =(D3*100)/D$7 -> 33.658421 | E10: =(E3*100)/E$7 -> 72.251195 | F10: =(F3*100)/F$7 -> 66.015318 | G10: =(G3*100)/G$7 -> 46.624522 | H10: =(H3*100)/H$7 -> 41.846287 | I10: =(I3*100)/I$7 -> 46.590994 | ... X10: =(X3*100)/X$7 -> 48.788486
A11: aphy (443) | B11: =(B4*100)/B$7 -> 60.886189 | C11: =(C4*100)/C$7 -> 40.529698 | D11: =(D4*100)/D$7 -> 33.741284 | E11: =(E4*100)/E$7 -> 21.705112 | F11: =(F4*100)/F$7 -> 17.485447 | G11: =(G4*100)/G$7 -> 17.038502 | H11: =(H4*100)/H$7 -> 24.501657 | I11: =(I4*100)/I$7 -> 27.234749 | ... X11: =(X4*100)/X$7 -> 19.419946
A12: aCDOM (443) | B12: =(B5*100)/B$7 -> 24.543252 | C12: =(C5*100)/C$7 -> 34.194736 | D12: =(D5*100)/D$7 -> 32.600294 | E12: =(E5*100)/E$7 -> 6.0436931 | F12: =(F5*100)/F$7 -> 16.499234 | G12: =(G5*100)/G$7 -> 36.336976 | H12: =(H5*100)/H$7 -> 33.652056 | I12: =(I5*100)/I$7 -> 26.174256 | ... L12: =(L5*100)/L$7 -> 27.97982 | N12: =(N5*100)/N$7 -> 37.152761 | O12: =(O5*100)/O$7 -> 39.458843 | P12: =(P5*100)/P$7 -> 15.637714 | Q12: =(Q5*100)/Q$7 -> 39.474154 | R12: =(R5*100)/R$7 -> 44.377296 | S12: =(S5*100)/S$7 -> 28.736147 | T12: =(T5*100)/T$7 -> 21.174843 | U12: =(U5*100)/U$7 -> 57.038529 | ... X12: =(X5*100)/X$7 -> 31.791567
B14: =+B1 -> E1 | C14: =+C1 -> E2 | D14: =+D1 -> E3 | E14: =+E1 -> E4 | F14: =+F1 -> E5 | G14: =+G1 -> E6 | H14: =+H1 -> E7 | I14: =+I1 -> E8 | ... X14: =+X1 -> E22
A15: ad (443) | B15: =(B3*100)/B$8 -> 14.39525 | C15: =(C3*100)/C$8 -> 24.542958 | D15: =(D3*100)/D$8 -> 32.883677 | E15: =(E3*100)/E$8 -> 71.98126 | F15: =(F3*100)/F$8 -> 65.218651 | G15: =(G3*100)/G$8 -> 45.552142 | H15: =(H3*100)/H$8 -> 41.037079 | I15: =(I3*100)/I$8 -> 45.665339 | ... X15: =(X3*100)/X$8 -> 48.613704
A16: aphy (443) | B16: =(B4*100)/B$8 -> 60.153623 | C16: =(C4*100)/C$8 -> 39.354952 | D16: =(D4*100)/D$8 -> 32.964633 | E16: =(E4*100)/E$8 -> 21.624021 | F16: =(F4*100)/F$8 -> 17.274435 | G16: =(G4*100)/G$8 -> 16.646611 | H16: =(H4*100)/H$8 -> 24.027853 | I16: =(I4*100)/I$8 -> 26.693658 | ... X16: =(X4*100)/X$8 -> 19.350375
A17: aCDOM-Mod (443) | B17: =(B6*100)/B$8 -> 25.451128 | C17: =(C6*100)/C$8 -> 36.10209 | D17: =(D6*100)/D$8 -> 34.151691 | E17: =(E6*100)/E$8 -> 6.3947195 | F17: =(F6*100)/F$8 -> 17.506915 | G17: =(G6*100)/G$8 -> 37.801248 | H17: =(H6*100)/H$8 -> 34.935068 | I17: =(I6*100)/I$8 -> 27.641003 | ... X17: =(X6*100)/X$8 -> 32.03592
B18: =SUM(B15:B17) -> 100 | C18: =SUM(C15:C17) -> 100 | D18: =SUM(D15:D17) -> 100 | E18: =SUM(E15:E17) -> 100 | F18: =SUM(F15:F17) -> 100 | G18: =SUM(G15:G17) -> 100 | H18: =SUM(H15:H17) -> 100 | I18: =SUM(I15:I17) -> 100 | ... X18: =SUM(X15:X17) -> 100

Sheet aphy-Especifico
A1: Wavelength (nm) | B1: =+'ax(443)'!B1 -> E1 | C1: =+'ax(443)'!C1 -> E2 | D1: =+'ax(443)'!D1 -> E3 | E1: =+'ax(443)'!E1 -> E4 | F1: =+'ax(443)'!F1 -> E5 | G1: =+'ax(443)'!G1 -> E6 | H1: =+'ax(443)'!H1 -> E7 | I1: =+'ax(443)'!I1 -> E8 | ... X1: =+'ax(443)'!X1 -> E22 | Z1: B/R | AB1: Si la razón B/R es >3.0 domina el picofitoplancton (< 2 um) | AH1: =+B1 -> E1 | AI1: =+C1 -> E2 | AJ1: =+D1 -> E3 | AK1: =+E1 -> E4 | AL1: =+F1 -> E5 | AM1: =+G1 -> E6 | AN1: =+H1 -> E7 | AO1: =+I1 -> E8 | ... BD1: =+X1 -> E22
A2: 800 | B2: 4.7395157e-05 | C2: #NUM! | D2: 0.00022208099 | E2: -0.00056984866 | F2: -0.00033792219 | G2: 3.9035309e-05 | H2: -0.00015637642 | I2: 0.0003397468 | J2: 3.1525056e-05 | K2: 0.00028366487 | L2: -0.00080300261 | M2: 0.00032888039 | N2: -0.00022204598 | O2: -0.00047152893 | P2: 0.00048854474 | Q2: 3.0818796e-05 | R2: 0.0011803537 | S2: 6.4164951e-05 | T2: 0.00051709288 | U2: -0.00029669319 | V2: 0.99970331 | W2: 1.9997033 | X2: 2.9997033 | Z2: B= | AA2: afito(443) | AB2: Si la razón B/R es <2.5 domina el microfitoplancton (> 20 um) | AG2: B/R = | AH2: =B$359/B$127 -> 3.4181706 | AI2: =C$359/C$127 -> 2.5549729 | AJ2: =D$359/D$127 -> 1.9271342 | AK2: =E$359/E$127 -> 2.2513843 | AL2: =F$359/F$127 -> 2.1822755 | AM2: =G$359/G$127 -> 2.4951902 | AN2: =H$359/H$127 -> 2.2879726 | AO2: =I$359/I$127 -> 2.3518542 | ... BD2: =X$359/X$127 -> 1.0013476
A3: 799 | B3: -3.3515579e-06 | C3: -8.0355931e-06 | D3: 0.00011100373 | E3: -0.00072680899 | F3: -0.00028904224 | G3: -0.00010777451 | H3: -0.00028772543 | I3: -0.00029131302 | J3: -2.7766645e-05 | K3: -0.00090207184 | L3: -0.00063717805 | M3: 0.00013581979 | N3: 0.00060919273 | O3: -0.0016069306 | P3: 0.0002950431 | Q3: 3.7938272e-05 | R3: 0.00021219462 | S3: -0.00029482502 | T3: -0.00073914769 | U3: -0.00062483153 | V3: 0.99937517 | W3: 1.9993752 | X3: 2.9993752 | Z3: R= | AA3: afito(675) | AB3: Valores entre 2.5 y 3 domina el nanoplancton
A4: 798 | B4: 0.00028119129 | C4: 0.00010404444 | D4: 0.00028929359 | E4: -0.00028924083 | F4: 0.00042019407 | G4: 0.0003386854 | H4: 2.439702e-07 | I4: 0.00043062724 | J4: 0.00042874077 | K4: 0.00035367864 | L4: 0.00023456185 | M4: -0.00017944888 | N4: 0.00070714187 | O4: -2.5054543e-05 | P4: 0.0005520527 | Q4: -0.00059905666 | R4: 0.0010159875 | S4: 4.096851e-06 | T4: -0.00025980402 | U4: 0.00028902697 | V4: 1.000289 | W4: 2.000289 | X4: 3.000289
A5: 797 | B5: -6.1272973e-05 | C5: #NUM! | D5: -0.00021336832 | E5: -0.00052071812 | F5: 8.8185227e-06 | G5: 5.3317221e-05 | H5: -0.00044772776 | I5: -0.00058112285 | J5: -0.00024429229 | K5: -0.00059373452 | L5: -0.00054797724 | M5: -0.00089799268 | N5: -0.00069105582 | O5: -0.0016113975 | P5: -9.2734024e-05 | Q5: -0.0018430581 | R5: -9.6582137e-05 | S5: -0.00032084647 | T5: -0.00089384812 | U5: -0.00066881727 | V5: 0.99933118 | W5: 1.9993312 | X5: 2.9993312
A6: 796 | B6: #NUM! | C6: 8.2080216e-05 | D6: 0.00014662978 | E6: -0.00072496884 | F6: 0.00044666796 | G6: -8.2897505e-05 | H6: 0.00027971141 | I6: -0.00032848322 | J6: 0.0002939426 | K6: 0.00038138445 | L6: -0.00070861355 | M6: -0.00021446336 | N6: 8.4265468e-05 | O6: -0.001478836 | P6: -7.550042e-05 | Q6: -0.00072567116 | R6: 0.00075411101 | S6: 0.0001495672 | T6: -4.6261592e-05 | U6: 8.7212958e-06 | V6: 1.0000087 | W6: 2.0000087 | X6: 3.0000087
A7: 795 | B7: 5.9202568e-05 | C7: #NUM! | D7: -3.6769349e-05 | E7: -0.00012163424 | F7: -0.0010488255 | G7: -0.00012403819 | H7: -0.00064350476 | I7: -0.00011422799 | J7: -0.00056478489 | K7: #NUM! | L7: -0.0011404814 | M7: -0.00054319279 | N7: -0.00019589065 | O7: -0.0020388145 | P7: -0.00071035603 | Q7: -0.0012244832 | R7: -0.00033515353 | S7: 6.7438064e-05 | T7: 0.00052082365 | U7: -0.00047392402 | V7: 0.99952608 | W7: 1.9995261 | X7: 2.9995261
A8: 794 | B8: 0.00038143817 | C8: #NUM! | D8: -0.00044737639 | E8: -0.0002477496 | F8: -0.000223821 | G8: -0.00016644632 | H8: -0.00069649198 | I8: -0.0003113472 | J8: -0.00030209931 | K8: -0.0005305643 | L8: -0.00079789696 | M8: -0.00058104621 | N8: -0.00073062598 | O8: -0.0017450913 | P8: -0.000267852 | Q8: -0.00092064116 | R8: -0.00086566777 | S8: 4.9077026e-05 | T8: -0.00089013418 | U8: -0.00030816154 | V8: 0.99969184 | W8: 1.9996918 | X8: 2.9996918
A9: 793 | B9: #NUM! | C9: #NUM! | D9: -0.00017193763 | E9: 0.00045993651 | F9: 0.00059940514 | G9: -4.5894431e-05 | H9: 0.00029201093 | I9: 0.00061573359 | J9: 0.00028524198 | K9: 0.0010596726 | L9: 0.00077693597 | M9: -0.00022030116 | N9: 0.00077388802 | O9: 0.0005537724 | P9: 0.00017437934 | Q9: 0.00076239583 | R9: 0.0012855435 | S9: 0.00018959597 | T9: 0.00082095871 | U9: 6.0495382e-06 | V9: 1.000006 | W9: 2.000006 | X9: 3.000006
A10: 792 | B10: #NUM! | C10: #NUM! | D10: -0.00057959308 | E10: -0.00044625398 | F10: -0.00017735662 | G10: 0.00013044941 | H10: -0.00020694055 | I10: -0.00017269769 | J10: -0.00030908636 | K10: -3.9834944e-05 | L10: -0.00044782599 | M10: -0.00058980066 | N10: 7.3827414e-05 | O10: 0.00067763519 | P10: 0.00036195992 | Q10: -0.00018650396 | R10: 0.00045645595 | S10: -4.049495e-05 | T10: -0.00058030488 | U10: -0.00082581377 | V10: 0.99917419 | W10: 1.9991742 | X10: 2.9991742
A11: 791 | B11: 0.0001493231 | C11: -0.00011082406 | D11: -0.00059127583 | E11: 1.1138694e-05 | F11: -0.00037378885 | G11: 6.0409924e-05 | H11: -0.00041305415 | I11: -0.00027506677 | J11: -0.00073172508 | K11: -0.0004578148 | L11: -0.00059736675 | M11: -0.00070025119 | N11: -0.00029093399 | O11: -0.00031166574 | P11: -0.00058639685 | Q11: -0.00036528949 | R11: -0.00082455817 | S11: -0.00016215614 | T11: -0.00029650738 | U11: -0.00099418444 | V11: 0.99900582 | W11: 1.9990058 | X11: 2.9990058
A12: 790 | B12: #NUM! | C12: -0.00012516542 | D12: -2.6960153e-05 | E12: -0.0012699633 | F12: -9.7804594e-05 | G12: 0.00025006175 | H12: 0.00054582087 | I12: 0.00053482544 | J12: 0.00015434526 | K12: -0.0007502212 | L12: 0.00020060947 | M12: -0.00037764925 | N12: 7.6659136e-05 | O12: 0.00041093616 | P12: -5.4455909e-05 | Q12: -3.4485346e-05 | R12: -9.4568557e-05 | S12: 3.5895574e-05 | T12: -0.00027738023 | U12: 0.00014788361 | V12: 1.0001479 | W12: 2.0001479 | X12: 3.0001479
A13: 789 | B13: #NUM! | C13: -0.00033913262 | D13: -0.0009701927 | E13: -0.0034820639 | F13: -0.0009026232 | G13: -0.00038791109 | H13: -0.00080011384 | I13: 0.00032663221 | J13: -0.00056916179 | K13: -0.00096978289 | L13: -0.0014339323 | M13: -0.00081314681 | N13: -0.00039999303 | O13: -0.00044414677 | P13: -0.00033226564 | Q13: -0.00077760302 | R13: -0.00053440071 | S13: -0.00055737801 | T13: -0.00033842799 | U13: -0.00077003121 | V13: 0.99922997 | W13: 1.99923 | X13: 2.99923
A14: 788 | B14: -6.308044e-05 | C14: -0.00040732485 | D14: -0.00042604839 | E14: -0.0018814173 | F14: -0.00073414885 | G14: -0.00011805085 | H14: -0.0011119142 | I14: -0.00099127474 | J14: -0.00067545109 | K14: -0.00095540111 | L14: -0.001262453 | M14: -0.00070791318 | N14: -0.00051116867 | O14: -0.00062476067 | P14: 0.00015287034 | Q14: -0.00011378425 | R14: -0.0012958535 | S14: -0.00019475186 | T14: -0.0014912196 | U14: -0.0009092733 | V14: 0.99909073 | W14: 1.9990907 | X14: 2.9990907
A15: 787 | B15: -3.2932673e-05 | C15: -0.00039449806 | D15: 1.8465751e-05 | E15: 0.0002367243 | F15: -0.0003406215 | G15: -0.00012365749 | H15: -0.00057400619 | I15: 0.0001605788 | J15: -0.00048519668 | K15: -0.0010042173 | L15: -0.0013341035 | M15: -0.0006565706 | N15: -0.00036172063 | O15: -0.00026430755 | P15: 0.00044094268 | Q15: -0.00053050897 | R15: -0.0010411229 | S15: -9.9965054e-05 | T15: -0.00098902481 | U15: -0.00049364098 | V15: 0.99950636 | W15: 1.9995064 | X15: 2.9995064
A16: 786 | B16: -8.9103209e-05 | C16: -0.00021564117 | D16: -8.8926186e-05 | E16: -0.0010545026 | F16: -1.2444801e-05 | G16: -0.0003156328 | H16: 0.00010540718 | I16: -0.00024393492 | J16: -0.00029154733 | K16: -0.0014069886 | L16: -0.00058529608 | M16: -0.00046046768 | N16: -0.00025578236 | O16: -0.0004118101 | P16: 0.00027918604 | Q16: -0.00050828566 | R16: -0.0004043664 | S16: -0.00016652745 | T16: -0.00077264446 | U16: -0.00062938404 | V16: 0.99937062 | W16: 1.9993706 | X16: 2.9993706
A17: 785 | B17: 5.8685138e-05 | C17: 9.6163099e-05 | D17: 0.00031128193 | E17: 0.00073108576 | F17: -0.00048097136 | G17: 0.00024247041 | H17: -0.00049059603 | I17: 0.00044036387 | J17: 0.00071477993 | K17: -0.00085570139 | L17: 0.00021755576 | M17: -0.00048513664 | N17: -2.0850513e-05 | O17: -0.0010439912 | P17: 0.00069180068 | Q17: -3.2940947e-05 | R17: -0.00038439421 | S17: 0.00060691393 | T17: -0.00046077696 | U17: -0.00034942987 | V17: 0.99965057 | W17: 1.9996506 | X17: 2.9996506
A18: 784 | B18: 0.00052114673 | C18: 0.00045348304 | D18: -0.00038373351 | E18: -0.00062237474 | F18: 0.00017534715 | G18: 0.00023518241 | H18: -0.00036256067 | I18: 0.00022693853 | J18: 0.00032427417 | K18: -0.00091884684 | L18: 3.2989717e-05 | M18: -0.00044401617 | N18: -0.00067754503 | O18: 5.4549236e-05 | P18: 0.00093550946 | Q18: 0.00026606452 | R18: -0.00025525329 | S18: 0.0008054913 | T18: 0.00023148893 | U18: -0.00026874032 | V18: 0.99973126 | W18: 1.9997313 | X18: 2.9997313
A19: 783 | B19: 4.2883163e-05 | C19: 0.00027506999 | D19: -0.00086338817 | E19: -0.00019583087 | F19: -0.0015967673 | G19: -2.6020107e-05 | H19: -6.7535781e-05 | I19: 0.00020298644 | J19: -8.2912481e-05 | K19: -0.0012484728 | L19: -0.00052255892 | M19: -0.00053261445 | N19: -0.0012385461 | O19: -0.00049957491 | P19: 8.3733272e-05 | Q19: -0.00058090235 | R19: -0.00022859226 | S19: 0.00012203395 | T19: -0.00059480031 | U19: -0.00013382092 | V19: 0.99986618 | W19: 1.9998662 | X19: 2.9998662
A20: 782 | B20: -3.9581077e-05 | C20: 0.00015975673 | D20: -0.00036370304 | E20: -0.00040788386 | F20: -0.0011593187 | G20: -4.4528258e-05 | H20: -0.00070186124 | I20: -0.00050894436 | J20: 0.00027371384 | K20: -0.00045364207 | L20: -0.0001884299 | M20: -0.00073582159 | N20: -0.0011345023 | O20: -0.00077406414 | P20: 0.00084828085 | Q20: -0.00084873696 | R20: -0.0013922377 | S20: 0.00066598696 | T20: -0.00029420775 | U20: -0.00027937667 | V20: 0.99972062 | W20: 1.9997206 | X20: 2.9997206
A21: 781 | B21: -0.00012623785 | C21: 0.00022346753 | D21: -0.00031633673 | E21: -0.0002532646 | F21: -0.0016451392 | G21: 7.1086311e-05 | H21: -0.00093712026 | I21: -0.00031037649 | J21: 0.00012675486 | K21: -0.0017545421 | L21: -0.00041231867 | M21: -0.00037776345 | N21: -0.0015697983 | O21: 0.00011645692 | P21: 0.0010289786 | Q21: 0.00026273816 | R21: 0.00012603588 | S21: 0.00040524215 | T21: -0.00064739967 | U21: -0.00012988663 | V21: 0.99987011 | W21: 1.9998701 | X21: 2.9998701
A22: 780 | B22: -0.00020860611 | C22: -0.00023494552 | D22: -0.00058383272 | E22: -0.0007412419 | F22: -0.0020625877 | G22: -6.0467057e-06 | H22: -0.00031972302 | I22: -0.00011141877 | J22: 8.6771485e-05 | K22: -0.0023119808 | L22: -0.0013742721 | M22: -0.00069696798 | N22: -0.0016243433 | O22: -0.00064141453 | P22: 0.00064216558 | Q22: -0.00034983691 | R22: -0.000713572 | S22: -0.00027623425 | T22: -0.00040591756 | U22: -0.00074283549 | V22: 0.99925716 | W22: 1.9992572 | X22: 2.9992572
A23: 779 | B23: -1.0655358e-05 | C23: -3.8742964e-05 | D23: -0.00034056581 | E23: -0.00042735623 | F23: -0.002098115 | G23: -9.5747917e-05 | H23: -0.00060028968 | I23: -0.00035232906 | J23: 0.00039554875 | K23: -0.0016905245 | L23: -0.0007564014 | M23: -0.0001977489 | N23: -0.0012068985 | O23: -0.00030900051 | P23: 0.0007312725 | Q23: -8.2811379e-05 | R23: 0.00063415325 | S23: -4.2214766e-05 | T23: -0.00013428607 | U23: -0.00031322228 | V23: 0.99968678 | W23: 1.9996868 | X23: 2.9996868
A24: 778 | B24: -0.00011550987 | C24: 2.6257179e-05 | D24: -6.1188598e-05 | E24: -0.00064865384 | F24: -0.00079688808 | G24: -9.8244895e-05 | H24: 0.00022748612 | I24: 0.00066981527 | J24: 0.00023171322 | K24: -0.0009770293 | L24: -0.0009488461 | M24: 0.00039025239 | N24: -0.0010413126 | O24: 0.00039814395 | P24: 0.0010151293 | Q24: 0.00050805734 | R24: 0.0008129221 | S24: 0.00017763681 | T24: 0.00015368475 | U24: -0.00059987876 | V24: 0.99940012 | W24: 1.9994001 | X24: 2.9994001
A25: 777 | B25: -0.00056854906 | C25: -5.8229223e-05 | D25: -0.0006351651 | E25: -0.0010744003 | F25: -0.0016668241 | G25: -0.00033975145 | H25: -0.00078808877 | I25: 0.00011081874 | J25: 1.5626526e-05 | K25: -0.0016084672 | L25: -0.0010767558 | M25: 0.00011549824 | N25: -0.0020819134 | O25: -0.00094292746 | P25: 0.00063004973 | Q25: -0.00048014611 | R25: 0.00012529569 | S25: -0.00032194604 | T25: -0.00060400846 | U25: -0.0014308792 | V25: 0.99856912 | W25: 1.9985691 | X25: 2.9985691
... A402: 400 | B402: 0.031897798 | C402: 0.012038562 | D402: 0.021098038 | E402: 0.075054155 | F402: 0.067143464 | G402: 0.012071315 | H402: 0.015850392 | I402: 0.082504483 | J402: 0.021022367 | K402: 0.12193867 | L402: 0.049115501 | M402: 0.044594755 | N402: -0.006632204 | O402: 0.086592216 | P402: 0.046378643 | Q402: 0.14413741 | R402: 0.08801797 | S402: 0.020737705 | T402: 0.088785688 | U402: 0.0052294711 | V402: 1.0052295 | W402: 2.0052295 | X402: 3.0052295

Sheet Varias longitudes de onda
C1: SC-22-0108 | D1: SC-22-0112 | E1: SC-22-0116 | F1: SC-22-0121 | G1: SC-22-0122 | H1: SC-22-0127 | I1: SC-22-0129 | J1: SC-22-0131 | K1: SC-22-0135 | L1: SC-22-0139 | M1: SC-22-0141 | N1: SC-22-0144 | O1: SC-22-0156 | P1: SC-22-0161 | Q1: SC-22-0163 | R1: SC-22-0164 | S1: SC-22-0167 | T1: SC-22-0168 | U1: SC-22-0170 | V1: SC-22-0172 | W1: SC-22-0175 | X1: SC-22-0176 | Y1: SC-22-0178
A2: aCDOM | B2: Wavelength (nm) | C2: =+aCDOM!B1 -> E1 | D2: =+aCDOM!C1 -> E2 | E2: =+aCDOM!D1 -> E3 | F2: =+aCDOM!E1 -> E4 | G2: =+aCDOM!F1 -> E5 | H2: =+aCDOM!G1 -> E6 | I2: =+aCDOM!H1 -> E7 | J2: =+aCDOM!I1 -> E8 | ... Y2: =+aCDOM!X1 -> E22
B3: 715 | C3: =+aCDOM!B87 -> 0.037959992 | D3: =+aCDOM!C87 -> -0.0072090507 | E3: =+aCDOM!D87 -> 0.025409785 | F3: =+aCDOM!E87 -> 0.031607503 | G3: =+aCDOM!F87 -> 0.038071867 | H3: =+aCDOM!G87 -> 0.018588349 | I3: =+aCDOM!H87 -> 0.12920783 | J3: =+aCDOM!I87 -> 0.011976077 | ... Y3: =+aCDOM!X87 -> 0.0058157654
B4: 676 | C4: =+aCDOM!B126 -> 0.071250076 | D4: =+aCDOM!C126 -> 0.015312927 | E4: =+aCDOM!D126 -> 0.038131236 | F4: =+aCDOM!E126 -> 0.049665305 | G4: =+aCDOM!F126 -> 0.049392825 | H4: =+aCDOM!G126 -> 0.033862841 | I4: =+aCDOM!H126 -> 0.15606409 | J4: =+aCDOM!I126 -> 0.034987764 | ... Y4: =+aCDOM!X126 -> 0.029821284
B5: 650 | C5: =+aCDOM!B152 -> 0.072280626 | D5: =+aCDOM!C152 -> 0.026408421 | E5: =+aCDOM!D152 -> 0.055214939 | F5: =+aCDOM!E152 -> 0.063161127 | G5: =+aCDOM!F152 -> 0.063537074 | H5: =+aCDOM!G152 -> 0.045444097 | I5: =+aCDOM!H152 -> 0.17338647 | J5: =+aCDOM!I152 -> 0.048416667 | ... Y5: =+aCDOM!X152 -> 0.037367159
B6: 630 | C6: =+aCDOM!B172 -> 0.084628189 | D6: =+aCDOM!C172 -> 0.028027 | E6: =+aCDOM!D172 -> 0.06167467 | F6: =+aCDOM!E172 -> 0.076858736 | G6: =+aCDOM!F172 -> 0.073534926 | H6: =+aCDOM!G172 -> 0.058859101 | I6: =+aCDOM!H172 -> 0.18645625 | J6: =+aCDOM!I172 -> 0.052536811 | ... Y6: =+aCDOM!X172 -> 0.047465905
B7: 555 | C7: =+aCDOM!B247 -> 0.14823724 | D7: =+aCDOM!C247 -> 0.088163308 | E7: =+aCDOM!D247 -> 0.13468772 | F7: =+aCDOM!E247 -> 0.20384151 | G7: =+aCDOM!F247 -> 0.17550034 | H7: =+aCDOM!G247 -> 0.16288424 | I7: =+aCDOM!H247 -> 0.28330477 | J7: =+aCDOM!I247 -> 0.12788121 | ... Y7: =+aCDOM!X247 -> 0.12278422
B8: 510 | C8: =+aCDOM!B292 -> 0.21991766 | D8: =+aCDOM!C292 -> 0.1585026 | E8: =+aCDOM!D292 -> 0.21569233 | F8: =+aCDOM!E292 -> 0.34989643 | G8: =+aCDOM!F292 -> 0.28136155 | H8: =+aCDOM!G292 -> 0.29559776 | I8: =+aCDOM!H292 -> 0.38869857 | J8: =+aCDOM!I292 -> 0.22116715 | ... Y8: =+aCDOM!X292 -> 0.21215129
